Workbook

Sheet OG
A1: asset.agent_name | B1: asset.display_fqdn | C1: asset.display_mac_address | D1: asset.fqdns | E1: asset.host_name | F1: asset.id | G1: asset.ip_addresses | H1: asset.name | I1: asset.netbios_name | J1: asset.operating_systems | K1: asset.system_type | L1: asset.tags | M1: compliance.audit_description | N1: compliance.audit_file | O1: compliance.audit_name | P1: compliance.audit_see_also | Q1: compliance.audit_solution | R1: compliance.benchmark | S1: compliance.benchmark_name | T1: compliance.benchmark_version | U1: compliance.control_id | V1: compliance.db_type | W1: compliance.full_id | X1: compliance.functional_id | Y1: compliance.info | Z1: compliance.informational_id | AA1: compliance.policy_expectation | AB1: compliance.profile_name | AC1: compliance.references | AD1: compliance_check_id | AE1: compliance_result | AF1: definition.id | AG1: definition.name | AH1: definition.output | AI1: definition.references | AJ1: definition.synopsis | AK1: error_value | AL1: first_seen | AM1: id | AN1: last_fixed | AO1: last_observed | AP1: metadata_id | AQ1: original_compliance_result | AR1: result_modification | AS1: result_modification_rule.comment | AT1: result_modification_rule.expires_at | AU1: uname_output
C2: 2c:f8:9b:c8:7e:09 | E2: wc-harwd-sa-3202-image | F2: ed63f2e6-8ee8-4077-bff4-4307d8534492 | G2: 10.132.172.254, 10.1.175.254 | H2: wc-harwd-sa-3202-image | J2: Cisco IOS XE 16.12.8 | K2: switch | L2: [{"category":"target","value":"Auth_Network_Device"},{"category":"rem","value":"NetworkEng"},{"category":"os","value":"CiscoIOS"},{"category":"type","value":"NetworkDevice"},{"category":"target","value":"Infoblox_Auto_All_Subnet"},{"category":"test","value":"Baseline_NetIOS"},{"category":"target","value":"Remote_Check"},{"category":"status","value":"Assessed"},{"category":"exp","value":"Internal"},{"category":"static","value":"BaselineNetIOS"},{"category":"lob","value":"HTS"}] | N2: Baseline_NetIOS_AuditFile.audit | O2: AC - NetIOS - Set 'exec-timeout' to less than or equal to 10 minutes 'line vty'as CONFIG_CHECK_NOT | P2: See cooresponding HTH Standards and Policies | R2: Custom | S2: Custom | U2: 655bb3e628c11c5704fcc0d636f20dbd572dda2094b8f76523e010a013a9167e | W2: b7288d5757ff67bf596c56cee7dfb898f01b40d6a4aa80a9435cd1c33bc6caec | X2: f47d241ba8 | Y2: If no input is detected during the interval, the EXEC facility resumes the current connection. | Z2: 88e00c381570279a5eb7d4802d9b1b1754c846e96e6d73978f046aa2759e752d | AA2: CONFIG_CHECK_NOT item: exec-timeout (10|[1-9])$ context: line vty .+ | AC2: [{framework=NIST 800-53r5, control=AC-11}] | AE2: PASSED | AF2: 46689 | AG2: Cisco IOS Compliance Checks | AH2: line vty 0 4 transport input ssh Expected configuration: exec-timeout (10|[1-9])$ line vty 5 31 transport input ssh Expected configuration: exec-timeout (10|[1-9])$ | AJ2: Compliance checks for Cisco IOS devices. | AL2: 2025-10-28T02:17:28.235Z | AM2: 08e45a81-fe0c-5793-8d9a-3f3f80af7c90 | AO2: 2026-05-04T00:17:20.723Z | AP2: a0988a85ef105ba14a7da626f5d41efc5f9a03ac6e07745b4cd9bdffea70e1ae | AQ2: PASSED | AR2: NONE
C3: 2c:f8:9b:c8:7e:09 | E3: wc-harwd-sa-3202-image | F3: ed63f2e6-8ee8-4077-bff4-4307d8534492 | G3: 10.132.172.254, 10.1.175.254 | H3: wc-harwd-sa-3202-image | J3: Cisco IOS XE 16.12.8 | K3: switch | L3: [{"category":"target","value":"Auth_Network_Device"},{"category":"rem","value":"NetworkEng"},{"category":"os","value":"CiscoIOS"},{"category":"type","value":"NetworkDevice"},{"category":"target","value":"Infoblox_Auto_All_Subnet"},{"category":"test","value":"Baseline_NetIOS"},{"category":"target","value":"Remote_Check"},{"category":"status","value":"Assessed"},{"category":"exp","value":"Internal"},{"category":"static","value":"BaselineNetIOS"},{"category":"lob","value":"HTS"}] | N3: Baseline_NetIOS_AuditFile.audit | O3: IA - NetIOS - Set 'transport input ssh' for 'line vty' connections | P3: See cooresponding HTH Standards and Policies | R3: Custom | S3: Custom | U3: fc7d129759d9f57ea2d27562bc370f1841da9be8948a844c64ad25b5b3b94cf8 | W3: 2aa136725f5510f5f62486fb633ee02d4e66c932eeed7c11f2e079e42d146f2d | X3: 0dbae36c60 | Y3: Selects the Secure Shell (SSH) protocol. | Z3: 700e00becf5a1f67c1be1611a52776fb801aa3277e660e5466b718f295c762e7 | AA3: CONFIG_CHECK item: transport input ssh *$ context: line vty .+ | AC3: [{framework=NIST 800-53r5, control=IA-2(1)}] | AE3: PASSED | AF3: 46689 | AG3: Cisco IOS Compliance Checks | AH3: line vty 0 4 transport input ssh <---- line vty 5 31 transport input ssh <---- | AJ3: Compliance checks for Cisco IOS devices. | AL3: 2025-10-28T02:17:28.235Z | AM3: 09719d68-82cf-5c03-a402-0c28cb0069dc | AO3: 2026-05-04T00:17:20.723Z | AP3: 0a0fab99baa5dda49f77758672f816ab2b75f3e73c5cb11b61ad071a67a86571 | AQ3: PASSED | AR3: NONE
C4: 2c:f8:9b:c8:7e:09 | E4: wc-harwd-sa-3202-image | F4: ed63f2e6-8ee8-4077-bff4-4307d8534492 | G4: 10.132.172.254, 10.1.175.254 | H4: wc-harwd-sa-3202-image | J4: Cisco IOS XE 16.12.8 | K4: switch | L4: [{"category":"target","value":"Auth_Network_Device"},{"category":"rem","value":"NetworkEng"},{"category":"os","value":"CiscoIOS"},{"category":"type","value":"NetworkDevice"},{"category":"target","value":"Infoblox_Auto_All_Subnet"},{"category":"test","value":"Baseline_NetIOS"},{"category":"target","value":"Remote_Check"},{"category":"status","value":"Assessed"},{"category":"exp","value":"Internal"},{"category":"static","value":"BaselineNetIOS"},{"category":"lob","value":"HTS"}] | N4: Baseline_NetIOS_AuditFile.audit | O4: PASSED - TARGET OS MATCHES BASELINE - IOS | P4: HTH | R4: Custom | S4: Custom | U4: b5fc18ab7596192497c063a9f6420cb8d133326edc70bff4844278a0735061f7 | W4: 37306217dd5708f03a3db8fba30edb12b2863b4e3b922553b8580f9c37f194cf | X4: 82aebc6eba | Z4: e3b0c44298fc1c149afbf4c8996fb92427ae41e4649b934ca495991b7852b855 | AA4: PASSED | AE4: PASSED | AF4: 46689 | AG4: Cisco IOS Compliance Checks | AH4: PASSED | AJ4: Compliance checks for Cisco IOS devices. | AL4: 2025-10-28T02:17:28.235Z | AM4: 19486276-370d-5599-81ad-1e68dc133677 | AO4: 2026-05-04T00:17:20.723Z | AP4: 9a9e57b683d0821c91e506670cbfafd30ee156eef15df71571aaa4bc8ce24417 | AQ4: PASSED | AR4: NONE
C5: 2c:f8:9b:c8:7e:09 | E5: wc-harwd-sa-3202-image | F5: ed63f2e6-8ee8-4077-bff4-4307d8534492 | G5: 10.132.172.254, 10.1.175.254 | H5: wc-harwd-sa-3202-image | J5: Cisco IOS XE 16.12.8 | K5: switch | L5: [{"category":"target","value":"Auth_Network_Device"},{"category":"rem","value":"NetworkEng"},{"category":"os","value":"CiscoIOS"},{"category":"type","value":"NetworkDevice"},{"category":"target","value":"Infoblox_Auto_All_Subnet"},{"category":"test","value":"Baseline_NetIOS"},{"category":"target","value":"Remote_Check"},{"category":"status","value":"Assessed"},{"category":"exp","value":"Internal"},{"category":"static","value":"BaselineNetIOS"},{"category":"lob","value":"HTS"}] | N5: Baseline_NetIOS_AuditFile.audit | O5: CM - NetIOS - Enable 'service password-encryption | P5: See cooresponding HTH Standards and Policies | R5: Custom | S5: Custom | U5: 96781bf1705fac9545e6d3d52b5e99399faa465e36e2903200d9ef231fc56975 | W5: 442644a29cce06eaf23d0511f2a8bb685845011e2286c0a4437f28be9b51620b | X5: 7a2f3f64d2 | Y5: When password encryption is enabled, the encrypted form of the passwords is displayed when a more system:running-config command is entered. | Z5: f50a9ea29d8cc1f9f336f79d55ca73567e25a8251b18bfd961a0d4bfab21c75b | AA5: CONFIG_CHECK item: service password-encryption | AC5: [{framework=NIST 800-53r5, control=CM-6 CM-7 SC-23}] | AE5: PASSED | AF5: 46689 | AG5: Cisco IOS Compliance Checks | AH5: service password-encryption <---- | AJ5: Compliance checks for Cisco IOS devices. | AL5: 2025-10-28T02:17:28.235Z | AM5: 26c6e776-0dcc-570d-a50a-d15b1cf31338 | AO5: 2026-05-04T00:17:20.723Z | AP5: 6b007dfcba9e2f4107229b9a0745abd9eb72c7b8211a1530a6456cfa91dbcbd3 | AQ5: PASSED | AR5: NONE
C6: 2c:f8:9b:c8:7e:09 | E6: wc-harwd-sa-3202-image | F6: ed63f2e6-8ee8-4077-bff4-4307d8534492 | G6: 10.132.172.254, 10.1.175.254 | H6: wc-harwd-sa-3202-image | J6: Cisco IOS XE 16.12.8 | K6: switch | L6: [{"category":"target","value":"Auth_Network_Device"},{"category":"rem","value":"NetworkEng"},{"category":"os","value":"CiscoIOS"},{"category":"type","value":"NetworkDevice"},{"category":"target","value":"Infoblox_Auto_All_Subnet"},{"category":"test","value":"Baseline_NetIOS"},{"category":"target","value":"Remote_Check"},{"category":"status","value":"Assessed"},{"category":"exp","value":"Internal"},{"category":"static","value":"BaselineNetIOS"},{"category":"lob","value":"HTS"}] | N6: Baseline_NetIOS_AuditFile.audit | O6: AC - NetIOS - Set 'exec-timeout' to less than or equal to 10 minutes for 'line aux 0'as CONFIG_CHECK_NOT | P6: See cooresponding HTH Standards and Policies | R6: Custom | S6: Custom | U6: 03851f55d96fa8c6c6fcd0ee3f1d1faaf5e73325a105f29be7013e8501dc9d8d | W6: 2fd08cf0e5821903e4d299f34f33aed6392f15f50868f51adf14914c90b7313b | X6: 38932179b6 | Y6: If no input is detected during the interval, the EXEC facility resumes the current connection. | Z6: 88e00c381570279a5eb7d4802d9b1b1754c846e96e6d73978f046aa2759e752d | AA6: CONFIG_CHECK_NOT item: exec-timeout (10|[1-9])$ context: line aux 0 | AC6: [{framework=NIST 800-53r5, control=AC-11}] | AE6: PASSED | AF6: 46689 | AG6: Cisco IOS Compliance Checks | AH6: line aux 0 stopbits 1 Expected configuration: exec-timeout (10|[1-9])$ | AJ6: Compliance checks for Cisco IOS devices. | AL6: 2025-10-28T02:17:28.235Z | AM6: 2fee92e7-0174-5cc9-8a9a-a282f0d218ba | AO6: 2026-05-04T00:17:20.723Z | AP6: fe23ede88fdaacfa0265d6bf112421798edb3eccc6dd419a0bb0200d9bc31e2a | AQ6: PASSED | AR6: NONE
C7: 2c:f8:9b:c8:7e:09 | E7: wc-harwd-sa-3202-image | F7: ed63f2e6-8ee8-4077-bff4-4307d8534492 | G7: 10.132.172.254, 10.1.175.254 | H7: wc-harwd-sa-3202-image | J7: Cisco IOS XE 16.12.8 | K7: switch | L7: [{"category":"target","value":"Auth_Network_Device"},{"category":"rem","value":"NetworkEng"},{"category":"os","value":"CiscoIOS"},{"category":"type","value":"NetworkDevice"},{"category":"target","value":"Infoblox_Auto_All_Subnet"},{"category":"test","value":"Baseline_NetIOS"},{"category":"target","value":"Remote_Check"},{"category":"status","value":"Assessed"},{"category":"exp","value":"Internal"},{"category":"static","value":"BaselineNetIOS"},{"category":"lob","value":"HTS"}] | N7: Baseline_NetIOS_AuditFile.audit | O7: AC - NetIOS - Authentication - Enable 'aaa authentication login' | P7: See cooresponding HTH Standards and Policies | R7: Custom | S7: Custom | U7: a82bdd409430b9149737a2dab882b6d6c526090b2f9c82ddb8d2b9152d3607b4 | W7: 667b2d0666cacdae5e10bf663c8bb6ecaf7e7bad649df23a31340afdfc4f6a12 | X7: d0830cb8ac | Y7: Sets authentication, authorization and accounting (AAA) authentication at login.' | Z7: 0660036b883faa8e5d2a363c446220b1c4ab1365e0efc818adb3d5589b9f124a | AA7: CONFIG_CHECK item: aaa authentication login | AC7: [{framework=NIST 800-53r5, control=AC-2(1)}] | AE7: PASSED | AF7: 46689 | AG7: Cisco IOS Compliance Checks | AH7: aaa authentication login default group HTH-ISE local-case <---- aaa authentication login HTH-ISE local-case <---- | AJ7: Compliance checks for Cisco IOS devices. | AL7: 2025-10-28T02:17:28.235Z | AM7: 316fdd4e-f432-5765-bf40-b9460b18a415 | AO7: 2026-05-04T00:17:20.723Z | AP7: dfaedd4a2a45ac182df242f885c29a422de178a93761a4610cc2cab7361dd3a1 | AQ7: PASSED | AR7: NONE
C8: 2c:f8:9b:c8:7e:09 | E8: wc-harwd-sa-3202-image | F8: ed63f2e6-8ee8-4077-bff4-4307d8534492 | G8: 10.132.172.254, 10.1.175.254 | H8: wc-harwd-sa-3202-image | J8: Cisco IOS XE 16.12.8 | K8: switch | L8: [{"category":"target","value":"Auth_Network_Device"},{"category":"rem","value":"NetworkEng"},{"category":"os","value":"CiscoIOS"},{"category":"type","value":"NetworkDevice"},{"category":"target","value":"Infoblox_Auto_All_Subnet"},{"category":"test","value":"Baseline_NetIOS"},{"category":"target","value":"Remote_Check"},{"category":"status","value":"Assessed"},{"category":"exp","value":"Internal"},{"category":"static","value":"BaselineNetIOS"},{"category":"lob","value":"HTS"}] | N8: Baseline_NetIOS_AuditFile.audit | O8: AC - NetIOS - Authentication - line con 0 | P8: See cooresponding HTH Standards and Policies | R8: Custom | S8: Custom | U8: bdd4238f073aefccab3f9677f72fd2405841f6deb04406e0f79a3585249e4038 | W8: c4bc41d14ce2445b8d740699c7b48583e905b839a9afc3b56425404b290586f0 | X8: b54c76b38c | Y8: Authenticates users who access the router or switch using the serial console port. | Z8: 0a9942010ba2277da7a1b9dc5bd35feb23f679b64ae35b059dc301d4b6c0990b | AA8: PASSED | AC8: [{framework=NIST 800-53r5, control=AC-2(1)}] | AE8: PASSED | AF8: 46689 | AG8: Cisco IOS Compliance Checks | AH8: PASSED | AJ8: Compliance checks for Cisco IOS devices. | AL8: 2025-10-28T02:17:28.235Z | AM8: 3363f210-c81d-510e-8f0c-da8f5c1f6521 | AO8: 2026-05-04T00:17:20.723Z | AP8: b9d52d56e814004af1adeb184501f876283624e367d43cab5b90c2766f0f941c | AQ8: PASSED | AR8: NONE
C9: 2c:f8:9b:c8:7e:09 | E9: wc-harwd-sa-3202-image | F9: ed63f2e6-8ee8-4077-bff4-4307d8534492 | G9: 10.132.172.254, 10.1.175.254 | H9: wc-harwd-sa-3202-image | J9: Cisco IOS XE 16.12.8 | K9: switch | L9: [{"category":"target","value":"Auth_Network_Device"},{"category":"rem","value":"NetworkEng"},{"category":"os","value":"CiscoIOS"},{"category":"type","value":"NetworkDevice"},{"category":"target","value":"Infoblox_Auto_All_Subnet"},{"category":"test","value":"Baseline_NetIOS"},{"category":"target","value":"Remote_Check"},{"category":"status","value":"Assessed"},{"category":"exp","value":"Internal"},{"category":"static","value":"BaselineNetIOS"},{"category":"lob","value":"HTS"}] | N9: Baseline_NetIOS_AuditFile.audit | O9: CM - NetIOS - Set 'username secret' for all local users | P9: See cooresponding HTH Standards and Policies | R9: Custom | S9: Custom | U9: 94a9a4f5e94e2a64e01e9489ac522ccab78025054dd41d49a11cea0c32a905c1 | W9: 564f760d9e14639616e90cc48b88b6dd1e4010c1d460afdf4e3ffa24a129b9f1 | X9: cac121a4ea | Y9: Use the username secret command to configure a username and MD5-encrypted user password. | Z9: 4ad2dc9047359b2a3e07616f94077e7a8b7075dcd94b2c42909230bf05465978 | AA9: CONFIG_CHECK item: username [^ ]+ regex: username .+ secret [^ ]+ | AC9: [{framework=NIST 800-53r5, control=CM-6 CM-7 SC-23}] | AE9: PASSED | AF9: 46689 | AG9: Cisco IOS Compliance Checks | AH9: username netadmin privilege 15 secret 9 $14$B0ho$7D3BRJupYDdF7.$lJeus8bA4cujy6yUAvyfwL.JoJ.DcNgIioCnBo.C3Lw <---- | AJ9: Compliance checks for Cisco IOS devices. | AL9: 2025-10-28T02:17:28.235Z | AM9: 3c5f98d9-8b59-5ff9-90a6-df046c6053e0 | AO9: 2026-05-04T00:17:20.723Z | AP9: 5df302254cb6db68076ba8f3cc11de258abbb55432d20acdec8be38421eeddab | AQ9: PASSED | AR9: NONE
C10: 2c:f8:9b:c8:7e:09 | E10: wc-harwd-sa-3202-image | F10: ed63f2e6-8ee8-4077-bff4-4307d8534492 | G10: 10.132.172.254, 10.1.175.254 | H10: wc-harwd-sa-3202-image | J10: Cisco IOS XE 16.12.8 | K10: switch | L10: [{"category":"target","value":"Auth_Network_Device"},{"category":"rem","value":"NetworkEng"},{"category":"os","value":"CiscoIOS"},{"category":"type","value":"NetworkDevice"},{"category":"target","value":"Infoblox_Auto_All_Subnet"},{"category":"test","value":"Baseline_NetIOS"},{"category":"target","value":"Remote_Check"},{"category":"status","value":"Assessed"},{"category":"exp","value":"Internal"},{"category":"static","value":"BaselineNetIOS"},{"category":"lob","value":"HTS"}] | N10: Baseline_NetIOS_AuditFile.audit | O10: AC - NetIOS - Authentication - Enable 'aaa authentication enable default' | P10: See cooresponding HTH Standards and Policies | R10: Custom | S10: Custom | U10: e5a1c123b1da61a9f1e164a9450ae05aa02e6ef0c43ba2ac646ca68259b9f695 | W10: 52c10fe244b56ff29876c5849d12981fe4b66392a08ada9eb61356a88403a0e4 | X10: 8a631af8d5 | Y10: Authenticates users who access privileged EXEC mode when they use the enable command. | Z10: 21112c0e2908c9fce2ccfd51a7e01e2250299f02c7e9e44877e84154769d63e4 | AA10: CONFIG_CHECK item: aaa authentication enable | AC10: [{framework=NIST 800-53r5, control=AC-2(1)}] | AE10: PASSED | AF10: 46689 | AG10: Cisco IOS Compliance Checks | AH10: aaa authentication enable default group HTH-ISE enable <---- | AJ10: Compliance checks for Cisco IOS devices. | AL10: 2025-10-28T02:17:28.235Z | AM10: 476a3da5-78fc-517d-afe8-268c1ef39b18 | AO10: 2026-05-04T00:17:20.723Z | AP10: 3e360c8c338c41391daf9aa3957dffa4a70f9b57609899268dc862e7e3251fc0 | AQ10: PASSED | AR10: NONE
C11: 2c:f8:9b:c8:7e:09 | E11: wc-harwd-sa-3202-image | F11: ed63f2e6-8ee8-4077-bff4-4307d8534492 | G11: 10.132.172.254, 10.1.175.254 | H11: wc-harwd-sa-3202-image | J11: Cisco IOS XE 16.12.8 | K11: switch | L11: [{"category":"target","value":"Auth_Network_Device"},{"category":"rem","value":"NetworkEng"},{"category":"os","value":"CiscoIOS"},{"category":"type","value":"NetworkDevice"},{"category":"target","value":"Infoblox_Auto_All_Subnet"},{"category":"test","value":"Baseline_NetIOS"},{"category":"target","value":"Remote_Check"},{"category":"status","value":"Assessed"},{"category":"exp","value":"Internal"},{"category":"static","value":"BaselineNetIOS"},{"category":"lob","value":"HTS"}] | N11: Baseline_NetIOS_AuditFile.audit | O11: AC - NetIOS - Authentication - line tty | P11: See cooresponding HTH Standards and Policies | R11: Custom | S11: Custom | U11: aefa03d73468bce61daf2ccfd2326b4481da1f733df55761c5dd39d618958ab7 | W11: aad801fd0767ca2149683d8b87f508d7f3862b17de2b0a266d165c5bc77c3845 | X11: b54c76b38c | Y11: Authenticates users who access the router or switch using the TTY port. | Z11: b5188d1680cd1f872a7caab802db50bd5b581a41ca67f94d35af3421523d568f | AA11: PASSED | AC11: [{framework=NIST 800-53r5, control=AC-2(1)}] | AE11: PASSED | AF11: 46689 | AG11: Cisco IOS Compliance Checks | AH11: PASSED | AJ11: Compliance checks for Cisco IOS devices. | AL11: 2025-10-28T02:17:28.235Z | AM11: 5c6441d5-36f7-57ec-9f1f-9809ba56039b | AO11: 2026-05-04T00:17:20.723Z | AP11: 947c0125bf7b59550f627028a65acaf9b8865866fb25972a05db89754d35f839 | AQ11: PASSED | AR11: NONE
C12: 2c:f8:9b:c8:7e:09 | E12: wc-harwd-sa-3202-image | F12: ed63f2e6-8ee8-4077-bff4-4307d8534492 | G12: 10.132.172.254, 10.1.175.254 | H12: wc-harwd-sa-3202-image | J12: Cisco IOS XE 16.12.8 | K12: switch | L12: [{"category":"target","value":"Auth_Network_Device"},{"category":"rem","value":"NetworkEng"},{"category":"os","value":"CiscoIOS"},{"category":"type","value":"NetworkDevice"},{"category":"target","value":"Infoblox_Auto_All_Subnet"},{"category":"test","value":"Baseline_NetIOS"},{"category":"target","value":"Remote_Check"},{"category":"status","value":"Assessed"},{"category":"exp","value":"Internal"},{"category":"static","value":"BaselineNetIOS"},{"category":"lob","value":"HTS"}] | N12: Baseline_NetIOS_AuditFile.audit | O12: AC - NetIOS - Authentication - Enable 'aaa new-model' | P12: See cooresponding HTH Standards and Policies | R12: Custom | S12: Custom | U12: 5648965a69fdae3f7c83dc8c9e238ba169925cef0bb1aa011df3cd4527afc0e6 | W12: 3bf2e801ae793b9bb20ef93b8790251e1d1cfffbeeeb259d435d99f73e7dd76b | X12: 5b2cc3b739 | Y12: This command enables the AAA access control system. | Z12: db7b1af768ef8d4f2c0414181dfba7bf43d90cf3e76c2662abf5c7672bfc01d0 | AA12: CONFIG_CHECK item: aaa new-model | AC12: [{framework=NIST 800-53r5, control=AC-2(1)}] | AE12: PASSED | AF12: 46689 | AG12: Cisco IOS Compliance Checks | AH12: aaa new-model <---- | AJ12: Compliance checks for Cisco IOS devices. | AL12: 2025-10-28T02:17:28.235Z | AM12: 7e579e07-5da8-55f7-9462-936fd0ee980e | AO12: 2026-05-04T00:17:20.723Z | AP12: 1bf6923969825c753219c6e47b51c20b5061a2404c67bfa3a330d5696c21cbd6 | AQ12: PASSED | AR12: NONE
C13: 2c:f8:9b:c8:7e:09 | E13: wc-harwd-sa-3202-image | F13: ed63f2e6-8ee8-4077-bff4-4307d8534492 | G13: 10.132.172.254, 10.1.175.254 | H13: wc-harwd-sa-3202-image | J13: Cisco IOS XE 16.12.8 | K13: switch | L13: [{"category":"target","value":"Auth_Network_Device"},{"category":"rem","value":"NetworkEng"},{"category":"os","value":"CiscoIOS"},{"category":"type","value":"NetworkDevice"},{"category":"target","value":"Infoblox_Auto_All_Subnet"},{"category":"test","value":"Baseline_NetIOS"},{"category":"target","value":"Remote_Check"},{"category":"status","value":"Assessed"},{"category":"exp","value":"Internal"},{"category":"static","value":"BaselineNetIOS"},{"category":"lob","value":"HTS"}] | N13: Baseline_NetIOS_AuditFile.audit | O13: AU - NetIOS - NTP Server Configured | P13: HTH | R13: Custom | S13: Custom | U13: fb2e745af836b6c5d454253619c65cc180003d58ef21ad853939c3a0b15f5c10 | W13: f3735f3a03452bb8ec5e7c4ea2f7039a2d873ca07c42adad67f57af78aec4043 | X13: 2cd0f04a57 | Y13: 10.248.232.10 was configured. | Z13: d430366dace3242ad734f5ef230df00f88317e995d9522fb810936ccd11e4664 | AA13: PASSED | AC13: [{framework=NIST 800-53, control=AU-7 AU-8}] | AE13: PASSED | AF13: 46689 | AG13: Cisco IOS Compliance Checks | AH13: PASSED | AJ13: Compliance checks for Cisco IOS devices. | AL13: 2025-10-28T02:17:28.235Z | AM13: 8d1f9715-69dd-5019-a047-96ddf4822471 | AO13: 2026-05-04T00:17:20.723Z | AP13: 1c70dc74fd319e65ff6e3960cda7d3cd09a84518da368754e926eaffe13c78b9 | AQ13: PASSED | AR13: NONE
C14: 2c:f8:9b:c8:7e:09 | E14: wc-harwd-sa-3202-image | F14: ed63f2e6-8ee8-4077-bff4-4307d8534492 | G14: 10.132.172.254, 10.1.175.254 | H14: wc-harwd-sa-3202-image | J14: Cisco IOS XE 16.12.8 | K14: switch | L14: [{"category":"target","value":"Auth_Network_Device"},{"category":"rem","value":"NetworkEng"},{"category":"os","value":"CiscoIOS"},{"category":"type","value":"NetworkDevice"},{"category":"target","value":"Infoblox_Auto_All_Subnet"},{"category":"test","value":"Baseline_NetIOS"},{"category":"target","value":"Remote_Check"},{"category":"status","value":"Assessed"},{"category":"exp","value":"Internal"},{"category":"static","value":"BaselineNetIOS"},{"category":"lob","value":"HTS"}] | N14: Baseline_NetIOS_AuditFile.audit | O14: AC - NetIOS - Set 'exec-timeout' less than or equal to 10 minutes 'line tty'as CONFIG_CHECK_NOT | P14: See cooresponding HTH Standards and Policies | R14: Custom | S14: Custom | U14: ada5a8bf6cfeaf75ec962e9cfb51ce006a44c9b3a23c6a2fdd20dadb29d56881 | W14: 723bf2c17b45b096e59191f7c694b8034412481e510dce43b68e0014e03709d2 | X14: 16b050ed5d | Y14: If no input is detected during the interval, the EXEC facility resumes the current connection. | Z14: 88e00c381570279a5eb7d4802d9b1b1754c846e96e6d73978f046aa2759e752d | AA14: CONFIG_CHECK_NOT item: exec-timeout (10|[1-9])$ context: line tty .+ | AC14: [{framework=NIST 800-53r5, control=AC-11}] | AE14: PASSED | AF14: 46689 | AG14: Cisco IOS Compliance Checks | AH14: line tty .+ not found in the configuration file | AJ14: Compliance checks for Cisco IOS devices. | AL14: 2025-10-28T02:17:28.235Z | AM14: 901e9e5b-7885-5189-a5e1-9a4c9e830b65 | AO14: 2026-05-04T00:17:20.723Z | AP14: 5cf57d6a29515b67ee9cee1945904781769b982036a1b2f3cf45ae9f12163133 | AQ14: PASSED | AR14: NONE
C15: 2c:f8:9b:c8:7e:09 | E15: wc-harwd-sa-3202-image | F15: ed63f2e6-8ee8-4077-bff4-4307d8534492 | G15: 10.132.172.254, 10.1.175.254 | H15: wc-harwd-sa-3202-image | J15: Cisco IOS XE 16.12.8 | K15: switch | L15: [{"category":"target","value":"Auth_Network_Device"},{"category":"rem","value":"NetworkEng"},{"category":"os","value":"CiscoIOS"},{"category":"type","value":"NetworkDevice"},{"category":"target","value":"Infoblox_Auto_All_Subnet"},{"category":"test","value":"Baseline_NetIOS"},{"category":"target","value":"Remote_Check"},{"category":"status","value":"Assessed"},{"category":"exp","value":"Internal"},{"category":"static","value":"BaselineNetIOS"},{"category":"lob","value":"HTS"}] | N15: Baseline_NetIOS_AuditFile.audit | O15: AC - NetIOS - Set 'privilege 1' for local users - 'All users have encrypted passwords' | P15: See cooresponding HTH Standards and Policies | R15: Custom | S15: Custom | U15: bf0f7bb158b066f3bb2818ab8b7fe33dcd4f18ea49f2cd1745921a3211a34c39 | W15: 0cfef084bc9e9716b178bdac06bb8cc8f3f015fc646e4d0a22624b8ac5c0e00e | X15: 1a25ad5f76 | Y15: Sets the privilege level for the user. | Z15: 04c5515417b1a166b23a6f60730064fe57faf4e53dd90113d731ca73a3aea18e | AA15: CONFIG_CHECK item: username .+ secret [5|8|9] .+ | AC15: [{framework=NIST 800-53r5, control=AC-6 AC-6(5)}] | AE15: PASSED | AF15: 46689 | AG15: Cisco IOS Compliance Checks | AH15: username netadmin privilege 15 secret 9 $14$B0ho$7D3BRJupYDdF7.$lJeus8bA4cujy6yUAvyfwL.JoJ.DcNgIioCnBo.C3Lw <---- | AJ15: Compliance checks for Cisco IOS devices. | AL15: 2025-10-28T02:17:28.235Z | AM15: 97258393-1983-51d2-9703-17f2b8d1e7ae | AO15: 2026-05-04T00:17:20.723Z | AP15: 4108a2698c9323d7b8e2af922b2fdfa8ae0414c68bae61ecb20c026deb06cba5 | AQ15: PASSED | AR15: NONE
C16: 2c:f8:9b:c8:7e:09 | E16: wc-harwd-sa-3202-image | F16: ed63f2e6-8ee8-4077-bff4-4307d8534492 | G16: 10.132.172.254, 10.1.175.254 | H16: wc-harwd-sa-3202-image | J16: Cisco IOS XE 16.12.8 | K16: switch | L16: [{"category":"target","value":"Auth_Network_Device"},{"category":"rem","value":"NetworkEng"},{"category":"os","value":"CiscoIOS"},{"category":"type","value":"NetworkDevice"},{"category":"target","value":"Infoblox_Auto_All_Subnet"},{"category":"test","value":"Baseline_NetIOS"},{"category":"target","value":"Remote_Check"},{"category":"status","value":"Assessed"},{"category":"exp","value":"Internal"},{"category":"static","value":"BaselineNetIOS"},{"category":"lob","value":"HTS"}] | N16: Baseline_NetIOS_AuditFile.audit | O16: CM - NetIOS - Set 'password' for 'enable secret' | P16: See cooresponding HTH Standards and Policies | R16: Custom | S16: Custom | U16: 14d939f3cd9a600d2649c8fb77fb92c81827b7d04727aa43fddbe5b638ae45a7 | W16: 094421ec0277d7f92a6eac717b5625e52825cf34191646b01771bba594844049 | X16: b036c44021 | Y16: Use the enable secret command to provide an additional layer of security over the enable password. | Z16: 88c95adbda137c219bc7d8d74f0b5de2d05a113515771c20de37aaaac18b680e | AA16: CONFIG_CHECK item: enable secret [^ ]+ | AC16: [{framework=NIST 800-53r5, control=CM-6 CM-7 SC-23}] | AE16: PASSED | AF16: 46689 | AG16: Cisco IOS Compliance Checks | AH16: enable secret 9 $14$Z1NL$53wlqErEEDCDlk$td5Z8TPaISnbZwCbf7oi51kS9Y0cQas2ClrSu4JqoiY <---- | AJ16: Compliance checks for Cisco IOS devices. | AL16: 2025-10-28T02:17:28.235Z | AM16: a6b76cfc-0bec-5572-943f-d1baa10c7d53 | AO16: 2026-05-04T00:17:20.723Z | AP16: de3b9808512c93595b47cab05f4c1c0e88cc6f423764bd4a43724871a34532bb | AQ16: PASSED | AR16: NONE
... C20: 2c:f8:9b:c8:7e:09 | E20: wc-harwd-sa-3202-image | F20: ed63f2e6-8ee8-4077-bff4-4307d8534492 | G20: 10.132.172.254, 10.1.175.254 | H20: wc-harwd-sa-3202-image | J20: Cisco IOS XE 16.12.8 | K20: switch | L20: [{"category":"target","value":"Auth_Network_Device"},{"category":"rem","value":"NetworkEng"},{"category":"os","value":"CiscoIOS"},{"category":"type","value":"NetworkDevice"},{"category":"target","value":"Infoblox_Auto_All_Subnet"},{"category":"test","value":"Baseline_NetIOS"},{"category":"target","value":"Remote_Check"},{"category":"status","value":"Assessed"},{"category":"exp","value":"Internal"},{"category":"static","value":"BaselineNetIOS"},{"category":"lob","value":"HTS"}] | N20: Baseline_NetIOS_AuditFile.audit | O20: AU - NetIOS - NTP Server Configured (2) | P20: HTH | R20: Custom | S20: Custom | U20: 08ccbded2cb12ecbf558c1de7144c5bd0b61eebf9939a00aa6f1326e7f74fdbe | W20: 2cd4b11493b69b239d9a33f558cedef95680ede88f67c0494956da689e8fa202 | X20: b83ec6cd1d | Y20: Check to confirm 10.248.232.210 was configured. | Z20: 0c43137cd3f65587623c2f692daacec5cce0bd83297ef87547cf8ee580497829 | AA20: CONFIG_CHECK item: ^(sntp|ntp) server.*10.248.232.210 regex: ^(sntp|ntp)[\s]+server([\s]+vrf[\s]+[a-zA-Z0-9_\-]+)?[\s]*10.248.232.210.*$ | AC20: [{framework=NIST 800-53, control=AU-7 AU-8}] | AE20: PASSED | AF20: 46689 | AG20: Cisco IOS Compliance Checks | AH20: ntp server 10.248.232.210 <---- | AJ20: Compliance checks for Cisco IOS devices. | AL20: 2025-10-28T02:17:28.235Z | AM20: ff575b33-e9b2-5b70-9401-3270b25e8959 | AO20: 2026-05-04T00:17:20.723Z | AP20: ee7b54fb3c773d3832640144a2df74434488a63abf66a1be1164fe475bc1bb40 | AQ20: PASSED | AR20: NONE

Sheet new
A1: Plugin ID | B1: CVE | C1: CVSS | D1: Risk | E1: Host | F1: Protocol | G1: Port | H1: Name | I1: Synopsis | J1: Numb | K1: ShortDesc | L1: Description | M1: Solution | N1: See Also | O1: Plugin Output | P1: Asset UUID | Q1: Vulnerability State | R1: IP Address | S1: FQDN | T1: NetBios | U1: OS | V1: MAC Address | W1: Plugin Family | X1: CVSS Base Score | Y1: CVSS Temporal Score | Z1: CVSS Temporal Vector | AA1: CVSS Vector | AB1: CVSS3 Base Score | AC1: CVSS3 Temporal Score | AD1: CVSS3 Temporal Vector | AE1: CVSS3 Vector | AF1: System Type | AG1: Host Start | AH1: Host End | AI1: Vulnerability Priority Rating (VPR) | AJ1: First Found | AK1: Last Found | AL1: Host Scan Schedule ID | AM1: Host Scan ID | AN1: Indexed At | AO1: Last Authenticated Results Date | AP1: Last Unauthenticated Results Date | AQ1: Tracked | AR1: Risk Factor | AS1: Severity | AT1: Original Severity | AU1: Modification | AV1: Plugin Family ID | AW1: Plugin Type | AX1: Plugin Version | AY1: Service | AZ1: Plugin Modification Date | BA1: Plugin Publication Date | BB1: Checks for Malware | BC1: Exploit Available | BD1: Exploited by Malware | BE1: Exploited by Nessus | BF1: CANVAS | BG1: D2 Elliot | BH1: Metasploit | BI1: Core Exploits | BJ1: ExploitHub | BK1: Default Account | BL1: Patch Available | BM1: In The News | BN1: Unsupported By Vendor | BO1: Last Fixed
A2: 46689 | C2: 0 | D2: None | E2: hth2-ipflex-hth2-cube1.hilltop.systems | F2: tcp | G2: 0 | H2: Cisco IOS Compliance Checks | I2: Compliance checks for Cisco IOS devices. | J2: 1.0001 | K2: 1.0001 - NETIOS - Enable 'aaa authentication login | L2: "1.0001 - NETIOS - Enable 'aaa authentication login: [PASSED]" Sets authentication, authorization and accounting (AAA) authentication at login. See Also: See HTH Policies and Standards Reference: NIST 800-53r5|AC-2(1) Policy Value: CONFIG_CHECK item: ^aaa authentication enable .+ required: 1 Actual Value: aaa authentication enable default group ISE-TACACS enable <---- | M2: N/A | P2: 549e7be8-1405-4274-a37c-56853449b396 | R2: 10.2.166.4 | S2: hth2-ipflex-hth2-cube1.hilltop.systems | V2: A4:6C:2A:B4:73:81 A4:6C:2A:B4:73:82 A4:6C:2A:B4:73:80 | W2: Policy Compliance | X2: 0 | Y2: 0 | AB2: 0 | AC2: 0 | AG2: 2026-05-08T15:18:01.658Z | AH2: 2026-05-08T15:23:54.504Z | AI2: null | AL2: template-80295fee-c9f5-bb4f-0422-3f46012f5e2bba99a3058425a248 | AM2: 95d933fc-434b-40df-8f34-1685e1133e37 | AN2: 2026-05-08T15:24:26.333Z | AO2: 2026-05-08T15:23:51Z | AQ2: TRUE | AR2: None | AS2: 0 | AT2: 0 | AV2: 39 | AW2: local | AX2: $Revision: 1.899 $ | AZ2: 2026-05-05T00:00:00Z | BA2: 2010-05-17T00:00:00Z | BB2: FALSE | BC2: FALSE | BD2: FALSE | BE2: FALSE | BF2: FALSE | BG2: FALSE | BH2: FALSE | BI2: FALSE | BJ2: FALSE | BK2: FALSE | BL2: FALSE | BM2: FALSE | BN2: FALSE
A3: 46689 | C3: 0 | D3: None | E3: wc-harwd-sa-3202-image | F3: tcp | G3: 0 | H3: Cisco IOS Compliance Checks | I3: Compliance checks for Cisco IOS devices. | J3: 1.0001 | K3: 1.0001 - NETIOS - Enable 'aaa authentication login | L3: "1.0001 - NETIOS - Enable 'aaa authentication login: [PASSED]" Sets authentication, authorization and accounting (AAA) authentication at login. See Also: See HTH Policies and Standards Reference: NIST 800-53r5|AC-2(1) Policy Value: CONFIG_CHECK item: ^aaa authentication enable .+ required: 1 Actual Value: aaa authentication enable default group HTH-ISE enable <---- | M3: N/A | P3: ed63f2e6-8ee8-4077-bff4-4307d8534492 | R3: 10.132.172.254 | S3: wc-harwd-sa-3202-image | V3: 2C:F8:9B:C8:7E:09 2C:F8:9B:C8:7E:07 2C:F8:9B:C8:7E:08 2C:F8:9B:C8:7E:0E 2C:F8:9B:C8:7E:0F 2C:F8:9B:C8:7E:0C 2C:F8:9B:C8:7E:0D 2C:F8:9B:C8:7E:0A 2C:F8:9B:C8:7E:0B 2C:F8:9B:C8:7E:16 2C:F8:9B:C8:7E:17 2C:F8:9B:C8:7E:14 2C:F8:9B:C8:7E:15 2C:F8:9B:C8:7E:12 2C:F8:9B:C8:7E:13 2C:F8:9B:C8:7E:10 2C:F8:9B:C8:7E:11 2C:F8:9B:C8:7E:05 2C:F8:9B:C8:7E:06 2C:F8:9B:C8:7E:03 2C:F8:9B:C8:7E:47 2C:F8:9B:C8:7E:04 2C:F8:9B:C8:7E:01 2C:F8:9B:C8:7E:02 2C:F8:9B:C8:7E:00 2C:F8:9B:C8:7E:29 2C:F8:9B:C8:7E:2E 2C:F8:9B:C8:7E:2F 2C:F8:9B:C8:7E:2C 2C:F8:9B:C8:7E:2D 2C:F8:9B:C8:7E:2A 2C:F8:9B:C8:7E:2B 2C:F8:9B:C8:7E:30 2C:F8:9B:C8:7E:31 2C:F8:9B:C8:7E:73 2C:F8:9B:C8:7E:70 2C:F8:9B:C8:7E:34 2C:F8:9B:C8:7E:32 2C:F8:9B:C8:7E:33 2C:F8:9B:C8:7E:18 2C:F8:9B:C8:7E:19 2C:F8:9B:C8:7E:1F 2C:F8:9B:C8:7E:1D 2C:F8:9B:C8:7E:1E 2C:F8:9B:C8:7E:1B 2C:F8:9B:C8:7E:1C 2C:F8:9B:C8:7E:1A 2C:F8:9B:C8:7E:20 2C:F8:9B:C8:7E:27 2C:F8:9B:C8:7E:28 2C:F8:9B:C8:7E:25 2C:F8:9B:C8:7E:26 2C:F8:9B:C8:7E:23 2C:F8:9B:C8:7E:24 2C:F8:9B:C8:7E:21 2C:F8:9B:C8:7E:22 | W3: Policy Compliance | X3: 0 | Y3: 0 | AB3: 0 | AC3: 0 | AG3: 2026-05-08T15:18:01.658Z | AH3: 2026-05-08T15:23:54.504Z | AI3: null | AL3: template-80295fee-c9f5-bb4f-0422-3f46012f5e2bba99a3058425a248 | AM3: 95d933fc-434b-40df-8f34-1685e1133e37 | AN3: 2026-05-08T15:24:26.367Z | AO3: 2026-05-08T15:21:56Z | AQ3: TRUE | AR3: None | AS3: 0 | AT3: 0 | AV3: 39 | AW3: local | AX3: $Revision: 1.899 $ | AZ3: 2026-05-05T00:00:00Z | BA3: 2010-05-17T00:00:00Z | BB3: FALSE | BC3: FALSE | BD3: FALSE | BE3: FALSE | BF3: FALSE | BG3: FALSE | BH3: FALSE | BI3: FALSE | BJ3: FALSE | BK3: FALSE | BL3: FALSE | BM3: FALSE | BN3: FALSE
A4: 46689 | C4: 0 | D4: None | E4: hth2-ipflex-hth2-cube1.hilltop.systems | F4: tcp | G4: 0 | H4: Cisco IOS Compliance Checks | I4: Compliance checks for Cisco IOS devices. | J4: 1.0002 | K4: 1.0002 - NETIOS - Set 'login authentication for 'line vty | L4: "1.0002 - NETIOS - Set 'login authentication for 'line vty: [PASSED]" Authenticates users who access the router or switch remotely through the VTY port. See Also: See HTH Policies and Standards Reference: NIST 800-53r5|AC-2(1) Policy Value: CONFIG_CHECK item: login( authentication [A-Za-z0-9_-]+)?|no login context: line vty .+ Actual Value: line vty 0 4 exec-timeout 15 0 privilege level 15 password 7 04681B07012A551F logging synchronous login authentication VTY-Access <---- length 0 transport input ssh transport output ssh | M4: N/A | P4: 549e7be8-1405-4274-a37c-56853449b396 | R4: 10.2.166.4 | S4: hth2-ipflex-hth2-cube1.hilltop.systems | V4: A4:6C:2A:B4:73:81 A4:6C:2A:B4:73:82 A4:6C:2A:B4:73:80 | W4: Policy Compliance | X4: 0 | Y4: 0 | AB4: 0 | AC4: 0 | AG4: 2026-05-08T15:18:01.658Z | AH4: 2026-05-08T15:23:54.504Z | AI4: null | AL4: template-80295fee-c9f5-bb4f-0422-3f46012f5e2bba99a3058425a248 | AM4: 95d933fc-434b-40df-8f34-1685e1133e37 | AN4: 2026-05-08T15:24:26.333Z | AO4: 2026-05-08T15:23:51Z | AQ4: TRUE | AR4: None | AS4: 0 | AT4: 0 | AV4: 39 | AW4: local | AX4: $Revision: 1.899 $ | AZ4: 2026-05-05T00:00:00Z | BA4: 2010-05-17T00:00:00Z | BB4: FALSE | BC4: FALSE | BD4: FALSE | BE4: FALSE | BF4: FALSE | BG4: FALSE | BH4: FALSE | BI4: FALSE | BJ4: FALSE | BK4: FALSE | BL4: FALSE | BM4: FALSE | BN4: FALSE
A5: 46689 | C5: 0 | D5: High | E5: wc-harwd-sa-3202-image | F5: tcp | G5: 0 | H5: Cisco IOS Compliance Checks | I5: Compliance checks for Cisco IOS devices. | J5: 1.0002 | K5: 1.0002 - NETIOS - Set 'login authentication for 'line vty | L5: "1.0002 - NETIOS - Set 'login authentication for 'line vty: [FAILED]" Authenticates users who access the router or switch remotely through the VTY port. See Also: See HTH Policies and Standards Reference: NIST 800-53r5|AC-2(1) Policy Value: CONFIG_CHECK item: login( authentication [A-Za-z0-9_-]+)?|no login context: line vty .+ Actual Value: line vty 0 4 transport input ssh Expected configuration: login( authentication [A-Za-z0-9_-]+)?|no login line vty 5 31 transport input ssh Expected configuration: login( authentication [A-Za-z0-9_-]+)?|no login | M5: N/A | P5: ed63f2e6-8ee8-4077-bff4-4307d8534492 | R5: 10.132.172.254 | S5: wc-harwd-sa-3202-image | V5: 2C:F8:9B:C8:7E:09 2C:F8:9B:C8:7E:07 2C:F8:9B:C8:7E:08 2C:F8:9B:C8:7E:0E 2C:F8:9B:C8:7E:0F 2C:F8:9B:C8:7E:0C 2C:F8:9B:C8:7E:0D 2C:F8:9B:C8:7E:0A 2C:F8:9B:C8:7E:0B 2C:F8:9B:C8:7E:16 2C:F8:9B:C8:7E:17 2C:F8:9B:C8:7E:14 2C:F8:9B:C8:7E:15 2C:F8:9B:C8:7E:12 2C:F8:9B:C8:7E:13 2C:F8:9B:C8:7E:10 2C:F8:9B:C8:7E:11 2C:F8:9B:C8:7E:05 2C:F8:9B:C8:7E:06 2C:F8:9B:C8:7E:03 2C:F8:9B:C8:7E:47 2C:F8:9B:C8:7E:04 2C:F8:9B:C8:7E:01 2C:F8:9B:C8:7E:02 2C:F8:9B:C8:7E:00 2C:F8:9B:C8:7E:29 2C:F8:9B:C8:7E:2E 2C:F8:9B:C8:7E:2F 2C:F8:9B:C8:7E:2C 2C:F8:9B:C8:7E:2D 2C:F8:9B:C8:7E:2A 2C:F8:9B:C8:7E:2B 2C:F8:9B:C8:7E:30 2C:F8:9B:C8:7E:31 2C:F8:9B:C8:7E:73 2C:F8:9B:C8:7E:70 2C:F8:9B:C8:7E:34 2C:F8:9B:C8:7E:32 2C:F8:9B:C8:7E:33 2C:F8:9B:C8:7E:18 2C:F8:9B:C8:7E:19 2C:F8:9B:C8:7E:1F 2C:F8:9B:C8:7E:1D 2C:F8:9B:C8:7E:1E 2C:F8:9B:C8:7E:1B 2C:F8:9B:C8:7E:1C 2C:F8:9B:C8:7E:1A 2C:F8:9B:C8:7E:20 2C:F8:9B:C8:7E:27 2C:F8:9B:C8:7E:28 2C:F8:9B:C8:7E:25 2C:F8:9B:C8:7E:26 2C:F8:9B:C8:7E:23 2C:F8:9B:C8:7E:24 2C:F8:9B:C8:7E:21 2C:F8:9B:C8:7E:22 | W5: Policy Compliance | X5: 0 | Y5: 0 | AB5: 0 | AC5: 0 | AG5: 2026-05-08T15:18:01.658Z | AH5: 2026-05-08T15:23:54.504Z | AI5: null | AL5: template-80295fee-c9f5-bb4f-0422-3f46012f5e2bba99a3058425a248 | AM5: 95d933fc-434b-40df-8f34-1685e1133e37 | AN5: 2026-05-08T15:24:26.353Z | AO5: 2026-05-08T15:21:56Z | AQ5: TRUE | AR5: None | AS5: 0 | AT5: 0 | AV5: 39 | AW5: local | AX5: $Revision: 1.899 $ | AZ5: 2026-05-05T00:00:00Z | BA5: 2010-05-17T00:00:00Z | BB5: FALSE | BC5: FALSE | BD5: FALSE | BE5: FALSE | BF5: FALSE | BG5: FALSE | BH5: FALSE | BI5: FALSE | BJ5: FALSE | BK5: FALSE | BL5: FALSE | BM5: FALSE | BN5: FALSE
A6: 46689 | C6: 0 | D6: None | E6: hth2-ipflex-hth2-cube1.hilltop.systems | F6: tcp | G6: 0 | H6: Cisco IOS Compliance Checks | I6: Compliance checks for Cisco IOS devices. | J6: 1.0003 | K6: 1.0003 - NETIOS - Set 'login authentication for 'line tty | L6: "1.0003 - NETIOS - Set 'login authentication for 'line tty: [PASSED]" Authenticates users who access the router or switch remotely through the VTY port. See Also: See HTH Policies and Standards Reference: NIST 800-53r5|AC-2(1) Policy Value: CONFIG_CHECK item: ^login authentication .+ context: line tty .+ required: 0 Actual Value: line tty .+ not found in the configuration file | M6: N/A | P6: 549e7be8-1405-4274-a37c-56853449b396 | R6: 10.2.166.4 | S6: hth2-ipflex-hth2-cube1.hilltop.systems | V6: A4:6C:2A:B4:73:81 A4:6C:2A:B4:73:82 A4:6C:2A:B4:73:80 | W6: Policy Compliance | X6: 0 | Y6: 0 | AB6: 0 | AC6: 0 | AG6: 2026-05-08T15:18:01.658Z | AH6: 2026-05-08T15:23:54.504Z | AI6: null | AL6: template-80295fee-c9f5-bb4f-0422-3f46012f5e2bba99a3058425a248 | AM6: 95d933fc-434b-40df-8f34-1685e1133e37 | AN6: 2026-05-08T15:24:26.333Z | AO6: 2026-05-08T15:23:51Z | AQ6: TRUE | AR6: None | AS6: 0 | AT6: 0 | AV6: 39 | AW6: local | AX6: $Revision: 1.899 $ | AZ6: 2026-05-05T00:00:00Z | BA6: 2010-05-17T00:00:00Z | BB6: FALSE | BC6: FALSE | BD6: FALSE | BE6: FALSE | BF6: FALSE | BG6: FALSE | BH6: FALSE | BI6: FALSE | BJ6: FALSE | BK6: FALSE | BL6: FALSE | BM6: FALSE | BN6: FALSE
A7: 46689 | C7: 0 | D7: None | E7: wc-harwd-sa-3202-image | F7: tcp | G7: 0 | H7: Cisco IOS Compliance Checks | I7: Compliance checks for Cisco IOS devices. | J7: 1.0003 | K7: 1.0003 - NETIOS - Set 'login authentication for 'line tty | L7: "1.0003 - NETIOS - Set 'login authentication for 'line tty: [PASSED]" Authenticates users who access the router or switch remotely through the VTY port. See Also: See HTH Policies and Standards Reference: NIST 800-53r5|AC-2(1) Policy Value: CONFIG_CHECK item: ^login authentication .+ context: line tty .+ required: 0 Actual Value: line tty .+ not found in the configuration file | M7: N/A | P7: ed63f2e6-8ee8-4077-bff4-4307d8534492 | R7: 10.132.172.254 | S7: wc-harwd-sa-3202-image | V7: 2C:F8:9B:C8:7E:09 2C:F8:9B:C8:7E:07 2C:F8:9B:C8:7E:08 2C:F8:9B:C8:7E:0E 2C:F8:9B:C8:7E:0F 2C:F8:9B:C8:7E:0C 2C:F8:9B:C8:7E:0D 2C:F8:9B:C8:7E:0A 2C:F8:9B:C8:7E:0B 2C:F8:9B:C8:7E:16 2C:F8:9B:C8:7E:17 2C:F8:9B:C8:7E:14 2C:F8:9B:C8:7E:15 2C:F8:9B:C8:7E:12 2C:F8:9B:C8:7E:13 2C:F8:9B:C8:7E:10 2C:F8:9B:C8:7E:11 2C:F8:9B:C8:7E:05 2C:F8:9B:C8:7E:06 2C:F8:9B:C8:7E:03 2C:F8:9B:C8:7E:47 2C:F8:9B:C8:7E:04 2C:F8:9B:C8:7E:01 2C:F8:9B:C8:7E:02 2C:F8:9B:C8:7E:00 2C:F8:9B:C8:7E:29 2C:F8:9B:C8:7E:2E 2C:F8:9B:C8:7E:2F 2C:F8:9B:C8:7E:2C 2C:F8:9B:C8:7E:2D 2C:F8:9B:C8:7E:2A 2C:F8:9B:C8:7E:2B 2C:F8:9B:C8:7E:30 2C:F8:9B:C8:7E:31 2C:F8:9B:C8:7E:73 2C:F8:9B:C8:7E:70 2C:F8:9B:C8:7E:34 2C:F8:9B:C8:7E:32 2C:F8:9B:C8:7E:33 2C:F8:9B:C8:7E:18 2C:F8:9B:C8:7E:19 2C:F8:9B:C8:7E:1F 2C:F8:9B:C8:7E:1D 2C:F8:9B:C8:7E:1E 2C:F8:9B:C8:7E:1B 2C:F8:9B:C8:7E:1C 2C:F8:9B:C8:7E:1A 2C:F8:9B:C8:7E:20 2C:F8:9B:C8:7E:27 2C:F8:9B:C8:7E:28 2C:F8:9B:C8:7E:25 2C:F8:9B:C8:7E:26 2C:F8:9B:C8:7E:23 2C:F8:9B:C8:7E:24 2C:F8:9B:C8:7E:21 2C:F8:9B:C8:7E:22 | W7: Policy Compliance | X7: 0 | Y7: 0 | AB7: 0 | AC7: 0 | AG7: 2026-05-08T15:18:01.658Z | AH7: 2026-05-08T15:23:54.504Z | AI7: null | AL7: template-80295fee-c9f5-bb4f-0422-3f46012f5e2bba99a3058425a248 | AM7: 95d933fc-434b-40df-8f34-1685e1133e37 | AN7: 2026-05-08T15:24:26.349Z | AO7: 2026-05-08T15:21:56Z | AQ7: TRUE | AR7: None | AS7: 0 | AT7: 0 | AV7: 39 | AW7: local | AX7: $Revision: 1.899 $ | AZ7: 2026-05-05T00:00:00Z | BA7: 2010-05-17T00:00:00Z | BB7: FALSE | BC7: FALSE | BD7: FALSE | BE7: FALSE | BF7: FALSE | BG7: FALSE | BH7: FALSE | BI7: FALSE | BJ7: FALSE | BK7: FALSE | BL7: FALSE | BM7: FALSE | BN7: FALSE
A8: 46689 | C8: 0 | D8: None | E8: hth2-ipflex-hth2-cube1.hilltop.systems | F8: tcp | G8: 0 | H8: Cisco IOS Compliance Checks | I8: Compliance checks for Cisco IOS devices. | J8: 1.0004 | K8: 1.0004 - NETIOS - Authentication - line con 0 | L8: "1.0004 - NETIOS - Authentication - line con 0: [PASSED]" Authenticates users who access the router or switch using the serial console port. See Also: See cooresponding HTH Standards and Policies Reference: NIST 800-53r5|AC-2(1) Policy Value: CONFIG_CHECK_NOT item: ^no login$ context: line con 0 Actual Value: line con 0 Expected configuration: ^no login$ | M8: N/A | P8: 549e7be8-1405-4274-a37c-56853449b396 | R8: 10.2.166.4 | S8: hth2-ipflex-hth2-cube1.hilltop.systems | V8: A4:6C:2A:B4:73:81 A4:6C:2A:B4:73:82 A4:6C:2A:B4:73:80 | W8: Policy Compliance | X8: 0 | Y8: 0 | AB8: 0 | AC8: 0 | AG8: 2026-05-08T15:18:01.658Z | AH8: 2026-05-08T15:23:54.504Z | AI8: null | AL8: template-80295fee-c9f5-bb4f-0422-3f46012f5e2bba99a3058425a248 | AM8: 95d933fc-434b-40df-8f34-1685e1133e37 | AN8: 2026-05-08T15:24:26.318Z | AO8: 2026-05-08T15:23:51Z | AQ8: TRUE | AR8: None | AS8: 0 | AT8: 0 | AV8: 39 | AW8: local | AX8: $Revision: 1.899 $ | AZ8: 2026-05-05T00:00:00Z | BA8: 2010-05-17T00:00:00Z | BB8: FALSE | BC8: FALSE | BD8: FALSE | BE8: FALSE | BF8: FALSE | BG8: FALSE | BH8: FALSE | BI8: FALSE | BJ8: FALSE | BK8: FALSE | BL8: FALSE | BM8: FALSE | BN8: FALSE
A9: 46689 | C9: 0 | D9: None | E9: wc-harwd-sa-3202-image | F9: tcp | G9: 0 | H9: Cisco IOS Compliance Checks | I9: Compliance checks for Cisco IOS devices. | J9: 1.0004 | K9: 1.0004 - NETIOS - Authentication - line con 0 | L9: "1.0004 - NETIOS - Authentication - line con 0: [PASSED]" Authenticates users who access the router or switch using the serial console port. See Also: See cooresponding HTH Standards and Policies Reference: NIST 800-53r5|AC-2(1) Policy Value: CONFIG_CHECK_NOT item: ^no login$ context: line con 0 Actual Value: line con 0 stopbits 1 Expected configuration: ^no login$ | M9: N/A | P9: ed63f2e6-8ee8-4077-bff4-4307d8534492 | R9: 10.132.172.254 | S9: wc-harwd-sa-3202-image | V9: 2C:F8:9B:C8:7E:09 2C:F8:9B:C8:7E:07 2C:F8:9B:C8:7E:08 2C:F8:9B:C8:7E:0E 2C:F8:9B:C8:7E:0F 2C:F8:9B:C8:7E:0C 2C:F8:9B:C8:7E:0D 2C:F8:9B:C8:7E:0A 2C:F8:9B:C8:7E:0B 2C:F8:9B:C8:7E:16 2C:F8:9B:C8:7E:17 2C:F8:9B:C8:7E:14 2C:F8:9B:C8:7E:15 2C:F8:9B:C8:7E:12 2C:F8:9B:C8:7E:13 2C:F8:9B:C8:7E:10 2C:F8:9B:C8:7E:11 2C:F8:9B:C8:7E:05 2C:F8:9B:C8:7E:06 2C:F8:9B:C8:7E:03 2C:F8:9B:C8:7E:47 2C:F8:9B:C8:7E:04 2C:F8:9B:C8:7E:01 2C:F8:9B:C8:7E:02 2C:F8:9B:C8:7E:00 2C:F8:9B:C8:7E:29 2C:F8:9B:C8:7E:2E 2C:F8:9B:C8:7E:2F 2C:F8:9B:C8:7E:2C 2C:F8:9B:C8:7E:2D 2C:F8:9B:C8:7E:2A 2C:F8:9B:C8:7E:2B 2C:F8:9B:C8:7E:30 2C:F8:9B:C8:7E:31 2C:F8:9B:C8:7E:73 2C:F8:9B:C8:7E:70 2C:F8:9B:C8:7E:34 2C:F8:9B:C8:7E:32 2C:F8:9B:C8:7E:33 2C:F8:9B:C8:7E:18 2C:F8:9B:C8:7E:19 2C:F8:9B:C8:7E:1F 2C:F8:9B:C8:7E:1D 2C:F8:9B:C8:7E:1E 2C:F8:9B:C8:7E:1B 2C:F8:9B:C8:7E:1C 2C:F8:9B:C8:7E:1A 2C:F8:9B:C8:7E:20 2C:F8:9B:C8:7E:27 2C:F8:9B:C8:7E:28 2C:F8:9B:C8:7E:25 2C:F8:9B:C8:7E:26 2C:F8:9B:C8:7E:23 2C:F8:9B:C8:7E:24 2C:F8:9B:C8:7E:21 2C:F8:9B:C8:7E:22 | W9: Policy Compliance | X9: 0 | Y9: 0 | AB9: 0 | AC9: 0 | AG9: 2026-05-08T15:18:01.658Z | AH9: 2026-05-08T15:23:54.504Z | AI9: null | AL9: template-80295fee-c9f5-bb4f-0422-3f46012f5e2bba99a3058425a248 | AM9: 95d933fc-434b-40df-8f34-1685e1133e37 | AN9: 2026-05-08T15:24:26.367Z | AO9: 2026-05-08T15:21:56Z | AQ9: TRUE | AR9: None | AS9: 0 | AT9: 0 | AV9: 39 | AW9: local | AX9: $Revision: 1.899 $ | AZ9: 2026-05-05T00:00:00Z | BA9: 2010-05-17T00:00:00Z | BB9: FALSE | BC9: FALSE | BD9: FALSE | BE9: FALSE | BF9: FALSE | BG9: FALSE | BH9: FALSE | BI9: FALSE | BJ9: FALSE | BK9: FALSE | BL9: FALSE | BM9: FALSE | BN9: FALSE
A10: 46689 | C10: 0 | D10: None | E10: hth2-ipflex-hth2-cube1.hilltop.systems | F10: tcp | G10: 0 | H10: Cisco IOS Compliance Checks | I10: Compliance checks for Cisco IOS devices. | J10: 1.0005 | K10: 1.0005 - NETIOS - Set 'transport input ssh' for 'line vty' connections | L10: "1.0005 - NETIOS - Set 'transport input ssh' for 'line vty' connections: [PASSED]" Selects the Secure Shell (SSH) protocol. See Also: See HTH Policies and Standards Reference: NIST 800-53r5|IA-2(1) Policy Value: CONFIG_CHECK item: transport input ssh$ context: line vty .+ Actual Value: line vty 0 4 exec-timeout 15 0 privilege level 15 password 7 04681B07012A551F logging synchronous login authentication VTY-Access length 0 transport input ssh <---- transport output ssh | M10: N/A | P10: 549e7be8-1405-4274-a37c-56853449b396 | R10: 10.2.166.4 | S10: hth2-ipflex-hth2-cube1.hilltop.systems | V10: A4:6C:2A:B4:73:81 A4:6C:2A:B4:73:82 A4:6C:2A:B4:73:80 | W10: Policy Compliance | X10: 0 | Y10: 0 | AB10: 0 | AC10: 0 | AG10: 2026-05-08T15:18:01.658Z | AH10: 2026-05-08T15:23:54.504Z | AI10: null | AL10: template-80295fee-c9f5-bb4f-0422-3f46012f5e2bba99a3058425a248 | AM10: 95d933fc-434b-40df-8f34-1685e1133e37 | AN10: 2026-05-08T15:24:26.332Z | AO10: 2026-05-08T15:23:51Z | AQ10: TRUE | AR10: None | AS10: 0 | AT10: 0 | AV10: 39 | AW10: local | AX10: $Revision: 1.899 $ | AZ10: 2026-05-05T00:00:00Z | BA10: 2010-05-17T00:00:00Z | BB10: FALSE | BC10: FALSE | BD10: FALSE | BE10: FALSE | BF10: FALSE | BG10: FALSE | BH10: FALSE | BI10: FALSE | BJ10: FALSE | BK10: FALSE | BL10: FALSE | BM10: FALSE | BN10: FALSE
A11: 46689 | C11: 0 | D11: None | E11: wc-harwd-sa-3202-image | F11: tcp | G11: 0 | H11: Cisco IOS Compliance Checks | I11: Compliance checks for Cisco IOS devices. | J11: 1.0005 | K11: 1.0005 - NETIOS - Set 'transport input ssh' for 'line vty' connections | L11: "1.0005 - NETIOS - Set 'transport input ssh' for 'line vty' connections: [PASSED]" Selects the Secure Shell (SSH) protocol. See Also: See HTH Policies and Standards Reference: NIST 800-53r5|IA-2(1) Policy Value: CONFIG_CHECK item: transport input ssh$ context: line vty .+ Actual Value: line vty 0 4 transport input ssh <---- line vty 5 31 transport input ssh <---- | M11: N/A | P11: ed63f2e6-8ee8-4077-bff4-4307d8534492 | R11: 10.132.172.254 | S11: wc-harwd-sa-3202-image | V11: 2C:F8:9B:C8:7E:09 2C:F8:9B:C8:7E:07 2C:F8:9B:C8:7E:08 2C:F8:9B:C8:7E:0E 2C:F8:9B:C8:7E:0F 2C:F8:9B:C8:7E:0C 2C:F8:9B:C8:7E:0D 2C:F8:9B:C8:7E:0A 2C:F8:9B:C8:7E:0B 2C:F8:9B:C8:7E:16 2C:F8:9B:C8:7E:17 2C:F8:9B:C8:7E:14 2C:F8:9B:C8:7E:15 2C:F8:9B:C8:7E:12 2C:F8:9B:C8:7E:13 2C:F8:9B:C8:7E:10 2C:F8:9B:C8:7E:11 2C:F8:9B:C8:7E:05 2C:F8:9B:C8:7E:06 2C:F8:9B:C8:7E:03 2C:F8:9B:C8:7E:47 2C:F8:9B:C8:7E:04 2C:F8:9B:C8:7E:01 2C:F8:9B:C8:7E:02 2C:F8:9B:C8:7E:00 2C:F8:9B:C8:7E:29 2C:F8:9B:C8:7E:2E 2C:F8:9B:C8:7E:2F 2C:F8:9B:C8:7E:2C 2C:F8:9B:C8:7E:2D 2C:F8:9B:C8:7E:2A 2C:F8:9B:C8:7E:2B 2C:F8:9B:C8:7E:30 2C:F8:9B:C8:7E:31 2C:F8:9B:C8:7E:73 2C:F8:9B:C8:7E:70 2C:F8:9B:C8:7E:34 2C:F8:9B:C8:7E:32 2C:F8:9B:C8:7E:33 2C:F8:9B:C8:7E:18 2C:F8:9B:C8:7E:19 2C:F8:9B:C8:7E:1F 2C:F8:9B:C8:7E:1D 2C:F8:9B:C8:7E:1E 2C:F8:9B:C8:7E:1B 2C:F8:9B:C8:7E:1C 2C:F8:9B:C8:7E:1A 2C:F8:9B:C8:7E:20 2C:F8:9B:C8:7E:27 2C:F8:9B:C8:7E:28 2C:F8:9B:C8:7E:25 2C:F8:9B:C8:7E:26 2C:F8:9B:C8:7E:23 2C:F8:9B:C8:7E:24 2C:F8:9B:C8:7E:21 2C:F8:9B:C8:7E:22 | W11: Policy Compliance | X11: 0 | Y11: 0 | AB11: 0 | AC11: 0 | AG11: 2026-05-08T15:18:01.658Z | AH11: 2026-05-08T15:23:54.504Z | AI11: null | AL11: template-80295fee-c9f5-bb4f-0422-3f46012f5e2bba99a3058425a248 | AM11: 95d933fc-434b-40df-8f34-1685e1133e37 | AN11: 2026-05-08T15:24:26.352Z | AO11: 2026-05-08T15:21:56Z | AQ11: TRUE | AR11: None | AS11: 0 | AT11: 0 | AV11: 39 | AW11: local | AX11: $Revision: 1.899 $ | AZ11: 2026-05-05T00:00:00Z | BA11: 2010-05-17T00:00:00Z | BB11: FALSE | BC11: FALSE | BD11: FALSE | BE11: FALSE | BF11: FALSE | BG11: FALSE | BH11: FALSE | BI11: FALSE | BJ11: FALSE | BK11: FALSE | BL11: FALSE | BM11: FALSE | BN11: FALSE
A12: 46689 | C12: 0 | D12: None | E12: hth2-ipflex-hth2-cube1.hilltop.systems | F12: tcp | G12: 0 | H12: Cisco IOS Compliance Checks | I12: Compliance checks for Cisco IOS devices. | J12: 1.0006 | K12: 1.0006 - NETIOS - Set 'password' for 'enable secret | L12: "1.0006 - NETIOS - Set 'password' for 'enable secret: [PASSED]" Enable secret password type 5 and enable secret password type 5 must be migrated to the stronger password type 8 or 9. See Also: See HTH Policies and Standards Reference: NIST 800-53r5|AC-6(2) AC-6(5) Policy Value: CONFIG_CHECK item: enable secret [^ ]+ Actual Value: enable secret 5 $1$uhIg$.BzYCWKUy20Kl3.f78xEz/ <---- | M12: N/A | P12: 549e7be8-1405-4274-a37c-56853449b396 | R12: 10.2.166.4 | S12: hth2-ipflex-hth2-cube1.hilltop.systems | V12: A4:6C:2A:B4:73:81 A4:6C:2A:B4:73:82 A4:6C:2A:B4:73:80 | W12: Policy Compliance | X12: 0 | Y12: 0 | AB12: 0 | AC12: 0 | AG12: 2026-05-08T15:18:01.658Z | AH12: 2026-05-08T15:23:54.504Z | AI12: null | AL12: template-80295fee-c9f5-bb4f-0422-3f46012f5e2bba99a3058425a248 | AM12: 95d933fc-434b-40df-8f34-1685e1133e37 | AN12: 2026-05-08T15:24:26.309Z | AO12: 2026-05-08T15:23:51Z | AQ12: TRUE | AR12: None | AS12: 0 | AT12: 0 | AV12: 39 | AW12: local | AX12: $Revision: 1.899 $ | AZ12: 2026-05-05T00:00:00Z | BA12: 2010-05-17T00:00:00Z | BB12: FALSE | BC12: FALSE | BD12: FALSE | BE12: FALSE | BF12: FALSE | BG12: FALSE | BH12: FALSE | BI12: FALSE | BJ12: FALSE | BK12: FALSE | BL12: FALSE | BM12: FALSE | BN12: FALSE
A13: 46689 | C13: 0 | D13: None | E13: wc-harwd-sa-3202-image | F13: tcp | G13: 0 | H13: Cisco IOS Compliance Checks | I13: Compliance checks for Cisco IOS devices. | J13: 1.0006 | K13: 1.0006 - NETIOS - Set 'password' for 'enable secret | L13: "1.0006 - NETIOS - Set 'password' for 'enable secret: [PASSED]" Enable secret password type 5 and enable secret password type 5 must be migrated to the stronger password type 8 or 9. See Also: See HTH Policies and Standards Reference: NIST 800-53r5|AC-6(2) AC-6(5) Policy Value: CONFIG_CHECK item: enable secret [^ ]+ Actual Value: enable secret 9 $14$Z1NL$53wlqErEEDCDlk$td5Z8TPaISnbZwCbf7oi51kS9Y0cQas2ClrSu4JqoiY <---- | M13: N/A | P13: ed63f2e6-8ee8-4077-bff4-4307d8534492 | R13: 10.132.172.254 | S13: wc-harwd-sa-3202-image | V13: 2C:F8:9B:C8:7E:09 2C:F8:9B:C8:7E:07 2C:F8:9B:C8:7E:08 2C:F8:9B:C8:7E:0E 2C:F8:9B:C8:7E:0F 2C:F8:9B:C8:7E:0C 2C:F8:9B:C8:7E:0D 2C:F8:9B:C8:7E:0A 2C:F8:9B:C8:7E:0B 2C:F8:9B:C8:7E:16 2C:F8:9B:C8:7E:17 2C:F8:9B:C8:7E:14 2C:F8:9B:C8:7E:15 2C:F8:9B:C8:7E:12 2C:F8:9B:C8:7E:13 2C:F8:9B:C8:7E:10 2C:F8:9B:C8:7E:11 2C:F8:9B:C8:7E:05 2C:F8:9B:C8:7E:06 2C:F8:9B:C8:7E:03 2C:F8:9B:C8:7E:47 2C:F8:9B:C8:7E:04 2C:F8:9B:C8:7E:01 2C:F8:9B:C8:7E:02 2C:F8:9B:C8:7E:00 2C:F8:9B:C8:7E:29 2C:F8:9B:C8:7E:2E 2C:F8:9B:C8:7E:2F 2C:F8:9B:C8:7E:2C 2C:F8:9B:C8:7E:2D 2C:F8:9B:C8:7E:2A 2C:F8:9B:C8:7E:2B 2C:F8:9B:C8:7E:30 2C:F8:9B:C8:7E:31 2C:F8:9B:C8:7E:73 2C:F8:9B:C8:7E:70 2C:F8:9B:C8:7E:34 2C:F8:9B:C8:7E:32 2C:F8:9B:C8:7E:33 2C:F8:9B:C8:7E:18 2C:F8:9B:C8:7E:19 2C:F8:9B:C8:7E:1F 2C:F8:9B:C8:7E:1D 2C:F8:9B:C8:7E:1E 2C:F8:9B:C8:7E:1B 2C:F8:9B:C8:7E:1C 2C:F8:9B:C8:7E:1A 2C:F8:9B:C8:7E:20 2C:F8:9B:C8:7E:27 2C:F8:9B:C8:7E:28 2C:F8:9B:C8:7E:25 2C:F8:9B:C8:7E:26 2C:F8:9B:C8:7E:23 2C:F8:9B:C8:7E:24 2C:F8:9B:C8:7E:21 2C:F8:9B:C8:7E:22 | W13: Policy Compliance | X13: 0 | Y13: 0 | AB13: 0 | AC13: 0 | AG13: 2026-05-08T15:18:01.658Z | AH13: 2026-05-08T15:23:54.504Z | AI13: null | AL13: template-80295fee-c9f5-bb4f-0422-3f46012f5e2bba99a3058425a248 | AM13: 95d933fc-434b-40df-8f34-1685e1133e37 | AN13: 2026-05-08T15:24:26.351Z | AO13: 2026-05-08T15:21:56Z | AQ13: TRUE | AR13: None | AS13: 0 | AT13: 0 | AV13: 39 | AW13: local | AX13: $Revision: 1.899 $ | AZ13: 2026-05-05T00:00:00Z | BA13: 2010-05-17T00:00:00Z | BB13: FALSE | BC13: FALSE | BD13: FALSE | BE13: FALSE | BF13: FALSE | BG13: FALSE | BH13: FALSE | BI13: FALSE | BJ13: FALSE | BK13: FALSE | BL13: FALSE | BM13: FALSE | BN13: FALSE
... A39: 46689 | C39: 0 | D39: None | E39: wc-harwd-sa-3202-image | F39: tcp | G39: 0 | H39: Cisco IOS Compliance Checks | I39: Compliance checks for Cisco IOS devices. | J39: 1.0019 | K39: 1.0019 - NETIOS - Ensure NTP Server Configured (2nd) | L39: "1.0019 - NETIOS - Ensure NTP Server Configured (2nd): [PASSED]" Check to confirm 10.248.232.210 was configured. See Also: HTH Reference: NIST 800-53|AU-7 AU-8 Policy Value: CONFIG_CHECK item: ^(sntp|ntp) server.*10.248.232.210 regex: ^(sntp|ntp)[\s]+server([\s]+vrf[\s]+[a-zA-Z0-9_\-]+)?[\s]*10.248.232.210.*$ Actual Value: ntp server 10.248.232.210 <---- | M39: N/A | P39: ed63f2e6-8ee8-4077-bff4-4307d8534492 | R39: 10.132.172.254 | S39: wc-harwd-sa-3202-image | V39: 2C:F8:9B:C8:7E:09 2C:F8:9B:C8:7E:07 2C:F8:9B:C8:7E:08 2C:F8:9B:C8:7E:0E 2C:F8:9B:C8:7E:0F 2C:F8:9B:C8:7E:0C 2C:F8:9B:C8:7E:0D 2C:F8:9B:C8:7E:0A 2C:F8:9B:C8:7E:0B 2C:F8:9B:C8:7E:16 2C:F8:9B:C8:7E:17 2C:F8:9B:C8:7E:14 2C:F8:9B:C8:7E:15 2C:F8:9B:C8:7E:12 2C:F8:9B:C8:7E:13 2C:F8:9B:C8:7E:10 2C:F8:9B:C8:7E:11 2C:F8:9B:C8:7E:05 2C:F8:9B:C8:7E:06 2C:F8:9B:C8:7E:03 2C:F8:9B:C8:7E:47 2C:F8:9B:C8:7E:04 2C:F8:9B:C8:7E:01 2C:F8:9B:C8:7E:02 2C:F8:9B:C8:7E:00 2C:F8:9B:C8:7E:29 2C:F8:9B:C8:7E:2E 2C:F8:9B:C8:7E:2F 2C:F8:9B:C8:7E:2C 2C:F8:9B:C8:7E:2D 2C:F8:9B:C8:7E:2A 2C:F8:9B:C8:7E:2B 2C:F8:9B:C8:7E:30 2C:F8:9B:C8:7E:31 2C:F8:9B:C8:7E:73 2C:F8:9B:C8:7E:70 2C:F8:9B:C8:7E:34 2C:F8:9B:C8:7E:32 2C:F8:9B:C8:7E:33 2C:F8:9B:C8:7E:18 2C:F8:9B:C8:7E:19 2C:F8:9B:C8:7E:1F 2C:F8:9B:C8:7E:1D 2C:F8:9B:C8:7E:1E 2C:F8:9B:C8:7E:1B 2C:F8:9B:C8:7E:1C 2C:F8:9B:C8:7E:1A 2C:F8:9B:C8:7E:20 2C:F8:9B:C8:7E:27 2C:F8:9B:C8:7E:28 2C:F8:9B:C8:7E:25 2C:F8:9B:C8:7E:26 2C:F8:9B:C8:7E:23 2C:F8:9B:C8:7E:24 2C:F8:9B:C8:7E:21 2C:F8:9B:C8:7E:22 | W39: Policy Compliance | X39: 0 | Y39: 0 | AB39: 0 | AC39: 0 | AG39: 2026-05-08T15:18:01.658Z | AH39: 2026-05-08T15:23:54.504Z | AI39: null | AL39: template-80295fee-c9f5-bb4f-0422-3f46012f5e2bba99a3058425a248 | AM39: 95d933fc-434b-40df-8f34-1685e1133e37 | AN39: 2026-05-08T15:24:26.351Z | AO39: 2026-05-08T15:21:56Z | AQ39: TRUE | AR39: None | AS39: 0 | AT39: 0 | AV39: 39 | AW39: local | AX39: $Revision: 1.899 $ | AZ39: 2026-05-05T00:00:00Z | BA39: 2010-05-17T00:00:00Z | BB39: FALSE | BC39: FALSE | BD39: FALSE | BE39: FALSE | BF39: FALSE | BG39: FALSE | BH39: FALSE | BI39: FALSE | BJ39: FALSE | BK39: FALSE | BL39: FALSE | BM39: FALSE | BN39: FALSE
A40: 25203 | C40: 0 | D40: None | E40: hth2-ipflex-hth2-cube1.hilltop.systems | F40: TCP | G40: 0 | H40: Enumerate IPv4 Interfaces via SSH | I40: Nessus was able to enumerate the IPv4 interfaces on the remote host. | J40: essus | L40: Nessus was able to enumerate the network interfaces configured with IPv4 addresses by connecting to the remote host via SSH using the supplied credentials. | M40: Disable any unused IPv4 interfaces. | O40: The following IPv4 addresses are set on the remote host : - 3.3.5.7 (on interface GigabitEthernet0/2) - 3.3.5.1 (on interface Embedded-Service-Engine0/0) | P40: 549e7be8-1405-4274-a37c-56853449b396 | Q40: New | R40: 10.2.166.4 | S40: hth2-ipflex-hth2-cube1.hilltop.systems | V40: A4:6C:2A:B4:73:81 A4:6C:2A:B4:73:82 A4:6C:2A:B4:73:80 | W40: General | X40: 0 | Y40: 0 | AB40: 0 | AC40: 0 | AG40: 2026-05-08T15:18:01.658Z | AH40: 2026-05-08T15:23:54.504Z | AI40: null | AJ40: 2026-05-08T15:23:54.504Z | AK40: 2026-05-08T15:23:54.504Z | AL40: template-80295fee-c9f5-bb4f-0422-3f46012f5e2bba99a3058425a248 | AM40: 95d933fc-434b-40df-8f34-1685e1133e37 | AN40: 2026-05-08T15:24:26.300Z | AO40: 2026-05-08T15:23:51Z | AQ40: TRUE | AR40: None | AS40: 0 | AT40: 0 | AU40: NONE | AV40: 30 | AW40: local | AX40: 1.21 | AZ40: 2025-09-24T00:00:00Z | BA40: 2007-05-11T00:00:00Z | BB40: FALSE | BC40: FALSE | BD40: FALSE | BE40: FALSE | BF40: FALSE | BG40: FALSE | BH40: FALSE | BI40: FALSE | BJ40: FALSE | BK40: FALSE | BL40: FALSE | BM40: FALSE | BN40: FALSE
A41: 141118 | C41: 0 | D41: None | E41: hth2-ipflex-hth2-cube1.hilltop.systems | F41: TCP | G41: 22 | H41: Target Credential Status by Authentication Protocol - Valid Credentials Provided | I41: Valid credentials were provided for an available authentication protocol. | J41: essus | L41: Nessus was able to determine that valid credentials were provided for an authentication protocol available on the remote target because it was able to successfully authenticate directly to the remote target using that authentication protocol at least once. Authentication was successful because the authentication protocol service was available remotely, the service was able to be identified, the authentication protocol was able to be negotiated successfully, and a set of credentials provided in the scan policy for that authentication protocol was accepted by the remote service. See plugin output for details, including protocol, port, and account. Please note the following - This plugin reports per protocol, so it is possible for valid credentials to be provided for one protocol and not another. For example, authentication may succeed via SSH but fail via SMB, while no credentials were provided for an available SNMP service. - Providing valid credentials for all available authentication protocols may improve scan coverage, but the value of successful authentication for a given protocol may vary from target to target depending upon what data (if any) is gathered from the target via that protocol. For example, successful authentication via SSH is more valuable for Linux targets than for Windows targets, and likewise successful authentication via SMB is more valuable for Windows targets than for Linux targets. | M41: N/A | O41: Nessus was able to log in to the remote host via the following : User: 'HTH-SVC-TenablNetEng' Port: 22 Proto: SSH Method: keyboard-interactive Escalation: cisco_enable | P41: 549e7be8-1405-4274-a37c-56853449b396 | Q41: New | R41: 10.2.166.4 | S41: hth2-ipflex-hth2-cube1.hilltop.systems | V41: A4:6C:2A:B4:73:81 A4:6C:2A:B4:73:82 A4:6C:2A:B4:73:80 | W41: Settings | X41: 0 | Y41: 0 | AB41: 0 | AC41: 0 | AG41: 2026-05-08T15:18:01.658Z | AH41: 2026-05-08T15:23:54.504Z | AI41: null | AJ41: 2026-05-08T15:23:54.504Z | AK41: 2026-05-08T15:23:54.504Z | AL41: template-80295fee-c9f5-bb4f-0422-3f46012f5e2bba99a3058425a248 | AM41: 95d933fc-434b-40df-8f34-1685e1133e37 | AN41: 2026-05-08T15:24:26.331Z | AO41: 2026-05-08T15:23:51Z | AQ41: TRUE | AR41: None | AS41: 0 | AT41: 0 | AU41: NONE | AV41: 41 | AW41: summary | AX41: 1.6 | AY41: ssh | AZ41: 2024-03-25T00:00:00Z | BA41: 2020-10-15T00:00:00Z | BB41: FALSE | BC41: FALSE | BD41: FALSE | BE41: FALSE | BF41: FALSE | BG41: FALSE | BH41: FALSE | BI41: FALSE | BJ41: FALSE | BK41: FALSE | BL41: FALSE | BM41: FALSE | BN41: FALSE
