Workbook

Sheet AUDIT COMPARE REPORT
A1: ===============================================================================
A2: IOS AUDIT COMPARE REPORT
A3: Generated : 2026-04-20 09:30:45
A4: Reference : OGNetIOS.audit
A5: New/combined: IOS_Combined.audit
A6: ===============================================================================
A8: Reference items : 49
A9: New items : 76
A10: Already in ref : 24 (deduped — active in New_Only)
A11: Genuinely new : 52
A12: Final total : 101
A14: --- Items already in reference (deduped) ---
... A139: 1.0076 - NETIOS - Set 'neighbor password

Sheet Current
A1: Plugin ID | B1: CVE | C1: CVSS | D1: Risk | E1: Host | F1: Protocol | G1: Port | H1: Name | I1: Synopsis | J1: Item | K1: Short Description | L1: Audit Name | M1: Status | N1: Description | O1: Solution | P1: See Also | Q1: Plugin Output | R1: Asset UUID | S1: Vulnerability State | T1: IP Address | U1: FQDN | V1: NetBios | W1: OS | X1: MAC Address | Y1: Plugin Family | Z1: CVSS Base Score | AA1: CVSS Temporal Score | AB1: CVSS Temporal Vector | AC1: CVSS Vector | AD1: CVSS3 Base Score | AE1: CVSS3 Temporal Score | AF1: CVSS3 Temporal Vector | AG1: CVSS3 Vector | AH1: System Type | AI1: Host Start | AJ1: Host End | AK1: Vulnerability Priority Rating (VPR) | AL1: First Found | AM1: Last Found | AN1: Host Scan Schedule ID | AO1: Host Scan ID | AP1: Indexed At | AQ1: Last Authenticated Results Date | AR1: Last Unauthenticated Results Date | AS1: Tracked | AT1: Risk Factor | AU1: Severity | AV1: Original Severity | AW1: Modification | AX1: Plugin Family ID | AY1: Plugin Type | AZ1: Plugin Version | BA1: Service | BB1: Plugin Modification Date | BC1: Plugin Publication Date | BD1: Checks for Malware | BE1: Exploit Available | BF1: Exploited by Malware | BG1: Exploited by Nessus | BH1: CANVAS | BI1: D2 Elliot | BJ1: Metasploit | BK1: Core Exploits | BL1: ExploitHub | BM1: Default Account | BN1: Patch Available | BO1: In The News | BP1: Unsupported By Vendor | BQ1: Last Fixed
A2: =MID($N2,FIND("1.",$N2),FIND("-",$N2)-FIND("1.",$N2)-1) -> 1.0001 | B2: =MID($N2,FIND("MSWRK - ",$N2)+8,FIND(":",$N2,40)-FIND("MSWRK - ",$N2)-8) -> #VALUE! | C2: =MID($N2,FIND("1.",$N2),FIND("[",$N2)-1-FIND("1.",$N2)-1) -> 1.0001 - NETIOS - Enable 'aaa new-model | D2: =MID($N2,FIND("[",$N2)+1,FIND("]",$N2)-FIND("[",$N2)-1) -> PASSED | E2: hth2-ipflex-hth2-cube1.hilltop.systems | F2: tcp | G2: 0 | H2: Cisco IOS Compliance Checks | I2: Compliance checks for Cisco IOS devices. | J2: =MID($N2,FIND("1.",$N2),FIND("-",$N2)-FIND("1.",$N2)-1) -> 1.0001 | K2: =MID($N2,FIND("NETIOS - ",$N2)+8,FIND(":",$N2,40)-FIND("NETIOS - ",$N2)-8) -> Enable 'aaa new-model | L2: =MID($N2,FIND("1.",$N2),FIND("[",$N2)-1-FIND("1.",$N2)-1) -> 1.0001 - NETIOS - Enable 'aaa new-model | M2: =MID($N2,FIND("[",$N2)+1,FIND("]",$N2)-FIND("[",$N2)-1) -> PASSED | N2: "1.0001 - NETIOS - Enable 'aaa new-model: [PASSED]" This command enables the AAA access control system. See Also: See HTH Policies and Standards Reference: NIST 800-53r5|AC-2(1) Policy Value: CONFIG_CHECK item: aaa new-model$ Actual Value: aaa new-model <---- | O2: N/A | R2: 549e7be8-1405-4274-a37c-56853449b396 | T2: 10.2.166.4 | U2: hth2-ipflex-hth2-cube1.hilltop.systems | X2: A4:6C:2A:B4:73:81 A4:6C:2A:B4:73:82 A4:6C:2A:B4:73:80 | Y2: Policy Compliance | Z2: 0 | AA2: 0 | AD2: 0 | AE2: 0 | AI2: 2026-04-20T14:59:05.184Z | AJ2: 2026-04-20T15:05:16.326Z | AK2: null | AN2: template-80295fee-c9f5-bb4f-0422-3f46012f5e2bba99a3058425a248 | AO2: c4785404-6646-486d-b008-461e60f4e791 | AP2: 2026-04-20T15:07:01.218Z | AQ2: 2026-04-20T15:05:04Z | AS2: TRUE | AT2: None | AU2: 0 | AV2: 0 | AX2: 39 | AY2: local | AZ2: $Revision: 1.887 $ | BB2: 2026-04-16T00:00:00Z | BC2: 2010-05-17T00:00:00Z | BD2: FALSE | BE2: FALSE | BF2: FALSE | BG2: FALSE | BH2: FALSE | BI2: FALSE | BJ2: FALSE | BK2: FALSE | BL2: FALSE | BM2: FALSE | BN2: FALSE | BO2: FALSE | BP2: FALSE
A3: 46689 | C3: 0 | D3: None | E3: wc-harwd-sa-3202-image | F3: tcp | G3: 0 | H3: Cisco IOS Compliance Checks | I3: Compliance checks for Cisco IOS devices. | J3: =MID($N3,FIND("1.",$N3),FIND("-",$N3)-FIND("1.",$N3)-1) -> 1.0001 | K3: =MID($N3,FIND("NETIOS - ",$N3)+8,FIND(":",$N3,40)-FIND("NETIOS - ",$N3)-8) -> Enable 'aaa new-model | L3: =MID($N3,FIND("1.",$N3),FIND("[",$N3)-1-FIND("1.",$N3)-1) -> 1.0001 - NETIOS - Enable 'aaa new-model | M3: =MID($N3,FIND("[",$N3)+1,FIND("]",$N3)-FIND("[",$N3)-1) -> PASSED | N3: "1.0001 - NETIOS - Enable 'aaa new-model: [PASSED]" This command enables the AAA access control system. See Also: See HTH Policies and Standards Reference: NIST 800-53r5|AC-2(1) Policy Value: CONFIG_CHECK item: aaa new-model$ Actual Value: aaa new-model <---- | O3: N/A | R3: ed63f2e6-8ee8-4077-bff4-4307d8534492 | T3: 10.132.172.254 | U3: wc-harwd-sa-3202-image | X3: 2C:F8:9B:C8:7E:09 2C:F8:9B:C8:7E:07 2C:F8:9B:C8:7E:08 2C:F8:9B:C8:7E:0E 2C:F8:9B:C8:7E:0F 2C:F8:9B:C8:7E:0C 2C:F8:9B:C8:7E:0D 2C:F8:9B:C8:7E:0A 2C:F8:9B:C8:7E:0B 2C:F8:9B:C8:7E:16 2C:F8:9B:C8:7E:17 2C:F8:9B:C8:7E:14 2C:F8:9B:C8:7E:15 2C:F8:9B:C8:7E:12 2C:F8:9B:C8:7E:13 2C:F8:9B:C8:7E:10 2C:F8:9B:C8:7E:11 2C:F8:9B:C8:7E:05 2C:F8:9B:C8:7E:06 2C:F8:9B:C8:7E:03 2C:F8:9B:C8:7E:47 2C:F8:9B:C8:7E:04 2C:F8:9B:C8:7E:01 2C:F8:9B:C8:7E:02 2C:F8:9B:C8:7E:00 2C:F8:9B:C8:7E:29 2C:F8:9B:C8:7E:2E 2C:F8:9B:C8:7E:2F 2C:F8:9B:C8:7E:2C 2C:F8:9B:C8:7E:2D 2C:F8:9B:C8:7E:2A 2C:F8:9B:C8:7E:2B 2C:F8:9B:C8:7E:30 2C:F8:9B:C8:7E:31 2C:F8:9B:C8:7E:73 2C:F8:9B:C8:7E:70 2C:F8:9B:C8:7E:34 2C:F8:9B:C8:7E:32 2C:F8:9B:C8:7E:33 2C:F8:9B:C8:7E:18 2C:F8:9B:C8:7E:19 2C:F8:9B:C8:7E:1F 2C:F8:9B:C8:7E:1D 2C:F8:9B:C8:7E:1E 2C:F8:9B:C8:7E:1B 2C:F8:9B:C8:7E:1C 2C:F8:9B:C8:7E:1A 2C:F8:9B:C8:7E:20 2C:F8:9B:C8:7E:27 2C:F8:9B:C8:7E:28 2C:F8:9B:C8:7E:25 2C:F8:9B:C8:7E:26 2C:F8:9B:C8:7E:23 2C:F8:9B:C8:7E:24 2C:F8:9B:C8:7E:21 2C:F8:9B:C8:7E:22 | Y3: Policy Compliance | Z3: 0 | AA3: 0 | AD3: 0 | AE3: 0 | AI3: 2026-04-20T14:59:05.184Z | AJ3: 2026-04-20T15:05:16.326Z | AK3: null | AN3: template-80295fee-c9f5-bb4f-0422-3f46012f5e2bba99a3058425a248 | AO3: c4785404-6646-486d-b008-461e60f4e791 | AP3: 2026-04-20T15:07:01.239Z | AQ3: 2026-04-20T15:02:50Z | AS3: TRUE | AT3: None | AU3: 0 | AV3: 0 | AX3: 39 | AY3: local | AZ3: $Revision: 1.887 $ | BB3: 2026-04-16T00:00:00Z | BC3: 2010-05-17T00:00:00Z | BD3: FALSE | BE3: FALSE | BF3: FALSE | BG3: FALSE | BH3: FALSE | BI3: FALSE | BJ3: FALSE | BK3: FALSE | BL3: FALSE | BM3: FALSE | BN3: FALSE | BO3: FALSE | BP3: FALSE
A4: 46689 | C4: 0 | D4: None | E4: hth2-ipflex-hth2-cube1.hilltop.systems | F4: tcp | G4: 0 | H4: Cisco IOS Compliance Checks | I4: Compliance checks for Cisco IOS devices. | J4: =MID($N4,FIND("1.",$N4),FIND("-",$N4)-FIND("1.",$N4)-1) -> 1.0002 | K4: =MID($N4,FIND("NETIOS - ",$N4)+8,FIND(":",$N4,40)-FIND("NETIOS - ",$N4)-8) -> Enable 'aaa authentication login | L4: =MID($N4,FIND("1.",$N4),FIND("[",$N4)-1-FIND("1.",$N4)-1) -> 1.0002 - NETIOS - Enable 'aaa authentication login | M4: =MID($N4,FIND("[",$N4)+1,FIND("]",$N4)-FIND("[",$N4)-1) -> PASSED | N4: "1.0002 - NETIOS - Enable 'aaa authentication login: [PASSED]" Sets authentication, authorization and accounting (AAA) authentication at login. See Also: See HTH Policies and Standards Reference: NIST 800-53r5|AC-2(1) Policy Value: CONFIG_CHECK item: aaa authentication login Actual Value: aaa authentication login CON-Access group ISE-TACACS local <---- aaa authentication login VTY-Access group ISE-TACACS local <---- | O4: N/A | R4: 549e7be8-1405-4274-a37c-56853449b396 | T4: 10.2.166.4 | U4: hth2-ipflex-hth2-cube1.hilltop.systems | X4: A4:6C:2A:B4:73:81 A4:6C:2A:B4:73:82 A4:6C:2A:B4:73:80 | Y4: Policy Compliance | Z4: 0 | AA4: 0 | AD4: 0 | AE4: 0 | AI4: 2026-04-20T14:59:05.184Z | AJ4: 2026-04-20T15:05:16.326Z | AK4: null | AN4: template-80295fee-c9f5-bb4f-0422-3f46012f5e2bba99a3058425a248 | AO4: c4785404-6646-486d-b008-461e60f4e791 | AP4: 2026-04-20T15:07:01.225Z | AQ4: 2026-04-20T15:05:04Z | AS4: TRUE | AT4: None | AU4: 0 | AV4: 0 | AX4: 39 | AY4: local | AZ4: $Revision: 1.887 $ | BB4: 2026-04-16T00:00:00Z | BC4: 2010-05-17T00:00:00Z | BD4: FALSE | BE4: FALSE | BF4: FALSE | BG4: FALSE | BH4: FALSE | BI4: FALSE | BJ4: FALSE | BK4: FALSE | BL4: FALSE | BM4: FALSE | BN4: FALSE | BO4: FALSE | BP4: FALSE
A5: 46689 | C5: 0 | D5: None | E5: wc-harwd-sa-3202-image | F5: tcp | G5: 0 | H5: Cisco IOS Compliance Checks | I5: Compliance checks for Cisco IOS devices. | J5: =MID($N5,FIND("1.",$N5),FIND("-",$N5)-FIND("1.",$N5)-1) -> 1.0002 | K5: =MID($N5,FIND("NETIOS - ",$N5)+8,FIND(":",$N5,40)-FIND("NETIOS - ",$N5)-8) -> Enable 'aaa authentication login | L5: =MID($N5,FIND("1.",$N5),FIND("[",$N5)-1-FIND("1.",$N5)-1) -> 1.0002 - NETIOS - Enable 'aaa authentication login | M5: =MID($N5,FIND("[",$N5)+1,FIND("]",$N5)-FIND("[",$N5)-1) -> PASSED | N5: "1.0002 - NETIOS - Enable 'aaa authentication login: [PASSED]" Sets authentication, authorization and accounting (AAA) authentication at login. See Also: See HTH Policies and Standards Reference: NIST 800-53r5|AC-2(1) Policy Value: CONFIG_CHECK item: aaa authentication login Actual Value: aaa authentication login default group HTH-ISE local-case <---- aaa authentication login HTH-ISE local-case <---- | O5: N/A | R5: ed63f2e6-8ee8-4077-bff4-4307d8534492 | T5: 10.132.172.254 | U5: wc-harwd-sa-3202-image | X5: 2C:F8:9B:C8:7E:09 2C:F8:9B:C8:7E:07 2C:F8:9B:C8:7E:08 2C:F8:9B:C8:7E:0E 2C:F8:9B:C8:7E:0F 2C:F8:9B:C8:7E:0C 2C:F8:9B:C8:7E:0D 2C:F8:9B:C8:7E:0A 2C:F8:9B:C8:7E:0B 2C:F8:9B:C8:7E:16 2C:F8:9B:C8:7E:17 2C:F8:9B:C8:7E:14 2C:F8:9B:C8:7E:15 2C:F8:9B:C8:7E:12 2C:F8:9B:C8:7E:13 2C:F8:9B:C8:7E:10 2C:F8:9B:C8:7E:11 2C:F8:9B:C8:7E:05 2C:F8:9B:C8:7E:06 2C:F8:9B:C8:7E:03 2C:F8:9B:C8:7E:47 2C:F8:9B:C8:7E:04 2C:F8:9B:C8:7E:01 2C:F8:9B:C8:7E:02 2C:F8:9B:C8:7E:00 2C:F8:9B:C8:7E:29 2C:F8:9B:C8:7E:2E 2C:F8:9B:C8:7E:2F 2C:F8:9B:C8:7E:2C 2C:F8:9B:C8:7E:2D 2C:F8:9B:C8:7E:2A 2C:F8:9B:C8:7E:2B 2C:F8:9B:C8:7E:30 2C:F8:9B:C8:7E:31 2C:F8:9B:C8:7E:73 2C:F8:9B:C8:7E:70 2C:F8:9B:C8:7E:34 2C:F8:9B:C8:7E:32 2C:F8:9B:C8:7E:33 2C:F8:9B:C8:7E:18 2C:F8:9B:C8:7E:19 2C:F8:9B:C8:7E:1F 2C:F8:9B:C8:7E:1D 2C:F8:9B:C8:7E:1E 2C:F8:9B:C8:7E:1B 2C:F8:9B:C8:7E:1C 2C:F8:9B:C8:7E:1A 2C:F8:9B:C8:7E:20 2C:F8:9B:C8:7E:27 2C:F8:9B:C8:7E:28 2C:F8:9B:C8:7E:25 2C:F8:9B:C8:7E:26 2C:F8:9B:C8:7E:23 2C:F8:9B:C8:7E:24 2C:F8:9B:C8:7E:21 2C:F8:9B:C8:7E:22 | Y5: Policy Compliance | Z5: 0 | AA5: 0 | AD5: 0 | AE5: 0 | AI5: 2026-04-20T14:59:05.184Z | AJ5: 2026-04-20T15:05:16.326Z | AK5: null | AN5: template-80295fee-c9f5-bb4f-0422-3f46012f5e2bba99a3058425a248 | AO5: c4785404-6646-486d-b008-461e60f4e791 | AP5: 2026-04-20T15:07:01.236Z | AQ5: 2026-04-20T15:02:50Z | AS5: TRUE | AT5: None | AU5: 0 | AV5: 0 | AX5: 39 | AY5: local | AZ5: $Revision: 1.887 $ | BB5: 2026-04-16T00:00:00Z | BC5: 2010-05-17T00:00:00Z | BD5: FALSE | BE5: FALSE | BF5: FALSE | BG5: FALSE | BH5: FALSE | BI5: FALSE | BJ5: FALSE | BK5: FALSE | BL5: FALSE | BM5: FALSE | BN5: FALSE | BO5: FALSE | BP5: FALSE
A6: 46689 | C6: 0 | D6: High | E6: wc-harwd-sa-3202-image | F6: tcp | G6: 0 | H6: Cisco IOS Compliance Checks | I6: Compliance checks for Cisco IOS devices. | J6: =MID($N6,FIND("1.",$N6),FIND("-",$N6)-FIND("1.",$N6)-1) -> 1.0003 | K6: =MID($N6,FIND("NETIOS - ",$N6)+8,FIND(":",$N6,40)-FIND("NETIOS - ",$N6)-8) -> Set 'login authentication for 'line vty | L6: =MID($N6,FIND("1.",$N6),FIND("[",$N6)-1-FIND("1.",$N6)-1) -> 1.0003 - NETIOS - Set 'login authentication for 'line vty | M6: =MID($N6,FIND("[",$N6)+1,FIND("]",$N6)-FIND("[",$N6)-1) -> FAILED | N6: "1.0003 - NETIOS - Set 'login authentication for 'line vty: [FAILED]" Authenticates users who access the router or switch remotely through the VTY port. See Also: See HTH Policies and Standards Reference: NIST 800-53r5|AC-2(1) Policy Value: CONFIG_CHECK item: login authentication .+ context: line vty .+ Actual Value: line vty 0 4 transport input ssh Expected configuration: login authentication .+ line vty 5 31 transport input ssh Expected configuration: login authentication .+ | O6: N/A | R6: ed63f2e6-8ee8-4077-bff4-4307d8534492 | T6: 10.132.172.254 | U6: wc-harwd-sa-3202-image | X6: 2C:F8:9B:C8:7E:09 2C:F8:9B:C8:7E:07 2C:F8:9B:C8:7E:08 2C:F8:9B:C8:7E:0E 2C:F8:9B:C8:7E:0F 2C:F8:9B:C8:7E:0C 2C:F8:9B:C8:7E:0D 2C:F8:9B:C8:7E:0A 2C:F8:9B:C8:7E:0B 2C:F8:9B:C8:7E:16 2C:F8:9B:C8:7E:17 2C:F8:9B:C8:7E:14 2C:F8:9B:C8:7E:15 2C:F8:9B:C8:7E:12 2C:F8:9B:C8:7E:13 2C:F8:9B:C8:7E:10 2C:F8:9B:C8:7E:11 2C:F8:9B:C8:7E:05 2C:F8:9B:C8:7E:06 2C:F8:9B:C8:7E:03 2C:F8:9B:C8:7E:47 2C:F8:9B:C8:7E:04 2C:F8:9B:C8:7E:01 2C:F8:9B:C8:7E:02 2C:F8:9B:C8:7E:00 2C:F8:9B:C8:7E:29 2C:F8:9B:C8:7E:2E 2C:F8:9B:C8:7E:2F 2C:F8:9B:C8:7E:2C 2C:F8:9B:C8:7E:2D 2C:F8:9B:C8:7E:2A 2C:F8:9B:C8:7E:2B 2C:F8:9B:C8:7E:30 2C:F8:9B:C8:7E:31 2C:F8:9B:C8:7E:73 2C:F8:9B:C8:7E:70 2C:F8:9B:C8:7E:34 2C:F8:9B:C8:7E:32 2C:F8:9B:C8:7E:33 2C:F8:9B:C8:7E:18 2C:F8:9B:C8:7E:19 2C:F8:9B:C8:7E:1F 2C:F8:9B:C8:7E:1D 2C:F8:9B:C8:7E:1E 2C:F8:9B:C8:7E:1B 2C:F8:9B:C8:7E:1C 2C:F8:9B:C8:7E:1A 2C:F8:9B:C8:7E:20 2C:F8:9B:C8:7E:27 2C:F8:9B:C8:7E:28 2C:F8:9B:C8:7E:25 2C:F8:9B:C8:7E:26 2C:F8:9B:C8:7E:23 2C:F8:9B:C8:7E:24 2C:F8:9B:C8:7E:21 2C:F8:9B:C8:7E:22 | Y6: Policy Compliance | Z6: 0 | AA6: 0 | AD6: 0 | AE6: 0 | AI6: 2026-04-20T14:59:05.184Z | AJ6: 2026-04-20T15:05:16.326Z | AK6: null | AN6: template-80295fee-c9f5-bb4f-0422-3f46012f5e2bba99a3058425a248 | AO6: c4785404-6646-486d-b008-461e60f4e791 | AP6: 2026-04-20T15:07:01.239Z | AQ6: 2026-04-20T15:02:50Z | AS6: TRUE | AT6: None | AU6: 0 | AV6: 0 | AX6: 39 | AY6: local | AZ6: $Revision: 1.887 $ | BB6: 2026-04-16T00:00:00Z | BC6: 2010-05-17T00:00:00Z | BD6: FALSE | BE6: FALSE | BF6: FALSE | BG6: FALSE | BH6: FALSE | BI6: FALSE | BJ6: FALSE | BK6: FALSE | BL6: FALSE | BM6: FALSE | BN6: FALSE | BO6: FALSE | BP6: FALSE
A7: 46689 | C7: 0 | D7: None | E7: hth2-ipflex-hth2-cube1.hilltop.systems | F7: tcp | G7: 0 | H7: Cisco IOS Compliance Checks | I7: Compliance checks for Cisco IOS devices. | J7: =MID($N7,FIND("1.",$N7),FIND("-",$N7)-FIND("1.",$N7)-1) -> 1.0003 | K7: =MID($N7,FIND("NETIOS - ",$N7)+8,FIND(":",$N7,40)-FIND("NETIOS - ",$N7)-8) -> Set 'login authentication for 'line vty | L7: =MID($N7,FIND("1.",$N7),FIND("[",$N7)-1-FIND("1.",$N7)-1) -> 1.0003 - NETIOS - Set 'login authentication for 'line vty | M7: =MID($N7,FIND("[",$N7)+1,FIND("]",$N7)-FIND("[",$N7)-1) -> PASSED | N7: "1.0003 - NETIOS - Set 'login authentication for 'line vty: [PASSED]" Authenticates users who access the router or switch remotely through the VTY port. See Also: See HTH Policies and Standards Reference: NIST 800-53r5|AC-2(1) Policy Value: CONFIG_CHECK item: login authentication .+ context: line vty .+ Actual Value: line vty 0 4 exec-timeout 15 0 privilege level 15 password 7 04681B07012A551F logging synchronous login authentication VTY-Access <---- length 0 transport input ssh transport output ssh | O7: N/A | R7: 549e7be8-1405-4274-a37c-56853449b396 | T7: 10.2.166.4 | U7: hth2-ipflex-hth2-cube1.hilltop.systems | X7: A4:6C:2A:B4:73:81 A4:6C:2A:B4:73:82 A4:6C:2A:B4:73:80 | Y7: Policy Compliance | Z7: 0 | AA7: 0 | AD7: 0 | AE7: 0 | AI7: 2026-04-20T14:59:05.184Z | AJ7: 2026-04-20T15:05:16.326Z | AK7: null | AN7: template-80295fee-c9f5-bb4f-0422-3f46012f5e2bba99a3058425a248 | AO7: c4785404-6646-486d-b008-461e60f4e791 | AP7: 2026-04-20T15:07:01.224Z | AQ7: 2026-04-20T15:05:04Z | AS7: TRUE | AT7: None | AU7: 0 | AV7: 0 | AX7: 39 | AY7: local | AZ7: $Revision: 1.887 $ | BB7: 2026-04-16T00:00:00Z | BC7: 2010-05-17T00:00:00Z | BD7: FALSE | BE7: FALSE | BF7: FALSE | BG7: FALSE | BH7: FALSE | BI7: FALSE | BJ7: FALSE | BK7: FALSE | BL7: FALSE | BM7: FALSE | BN7: FALSE | BO7: FALSE | BP7: FALSE
A8: 46689 | C8: 0 | D8: None | E8: hth2-ipflex-hth2-cube1.hilltop.systems | F8: tcp | G8: 0 | H8: Cisco IOS Compliance Checks | I8: Compliance checks for Cisco IOS devices. | J8: =MID($N8,FIND("1.",$N8),FIND("-",$N8)-FIND("1.",$N8)-1) -> 1.0004 | K8: =MID($N8,FIND("NETIOS - ",$N8)+8,FIND(":",$N8,40)-FIND("NETIOS - ",$N8)-8) -> Set 'transport input ssh' for 'line vty' connections | L8: =MID($N8,FIND("1.",$N8),FIND("[",$N8)-1-FIND("1.",$N8)-1) -> 1.0004 - NETIOS - Set 'transport input ssh' for 'line vty' connections | M8: =MID($N8,FIND("[",$N8)+1,FIND("]",$N8)-FIND("[",$N8)-1) -> PASSED | N8: "1.0004 - NETIOS - Set 'transport input ssh' for 'line vty' connections: [PASSED]" Selects the Secure Shell (SSH) protocol. See Also: See HTH Policies and Standards Reference: NIST 800-53r5|IA-2(1) Policy Value: CONFIG_CHECK item: transport input ssh$ context: line vty .+ Actual Value: line vty 0 4 exec-timeout 15 0 privilege level 15 password 7 04681B07012A551F logging synchronous login authentication VTY-Access length 0 transport input ssh <---- transport output ssh | O8: N/A | R8: 549e7be8-1405-4274-a37c-56853449b396 | T8: 10.2.166.4 | U8: hth2-ipflex-hth2-cube1.hilltop.systems | X8: A4:6C:2A:B4:73:81 A4:6C:2A:B4:73:82 A4:6C:2A:B4:73:80 | Y8: Policy Compliance | Z8: 0 | AA8: 0 | AD8: 0 | AE8: 0 | AI8: 2026-04-20T14:59:05.184Z | AJ8: 2026-04-20T15:05:16.326Z | AK8: null | AN8: template-80295fee-c9f5-bb4f-0422-3f46012f5e2bba99a3058425a248 | AO8: c4785404-6646-486d-b008-461e60f4e791 | AP8: 2026-04-20T15:07:01.224Z | AQ8: 2026-04-20T15:05:04Z | AS8: TRUE | AT8: None | AU8: 0 | AV8: 0 | AX8: 39 | AY8: local | AZ8: $Revision: 1.887 $ | BB8: 2026-04-16T00:00:00Z | BC8: 2010-05-17T00:00:00Z | BD8: FALSE | BE8: FALSE | BF8: FALSE | BG8: FALSE | BH8: FALSE | BI8: FALSE | BJ8: FALSE | BK8: FALSE | BL8: FALSE | BM8: FALSE | BN8: FALSE | BO8: FALSE | BP8: FALSE
A9: 46689 | C9: 0 | D9: None | E9: wc-harwd-sa-3202-image | F9: tcp | G9: 0 | H9: Cisco IOS Compliance Checks | I9: Compliance checks for Cisco IOS devices. | J9: =MID($N9,FIND("1.",$N9),FIND("-",$N9)-FIND("1.",$N9)-1) -> 1.0004 | K9: =MID($N9,FIND("NETIOS - ",$N9)+8,FIND(":",$N9,40)-FIND("NETIOS - ",$N9)-8) -> Set 'transport input ssh' for 'line vty' connections | L9: =MID($N9,FIND("1.",$N9),FIND("[",$N9)-1-FIND("1.",$N9)-1) -> 1.0004 - NETIOS - Set 'transport input ssh' for 'line vty' connections | M9: =MID($N9,FIND("[",$N9)+1,FIND("]",$N9)-FIND("[",$N9)-1) -> PASSED | N9: "1.0004 - NETIOS - Set 'transport input ssh' for 'line vty' connections: [PASSED]" Selects the Secure Shell (SSH) protocol. See Also: See HTH Policies and Standards Reference: NIST 800-53r5|IA-2(1) Policy Value: CONFIG_CHECK item: transport input ssh$ context: line vty .+ Actual Value: line vty 0 4 transport input ssh <---- line vty 5 31 transport input ssh <---- | O9: N/A | R9: ed63f2e6-8ee8-4077-bff4-4307d8534492 | T9: 10.132.172.254 | U9: wc-harwd-sa-3202-image | X9: 2C:F8:9B:C8:7E:09 2C:F8:9B:C8:7E:07 2C:F8:9B:C8:7E:08 2C:F8:9B:C8:7E:0E 2C:F8:9B:C8:7E:0F 2C:F8:9B:C8:7E:0C 2C:F8:9B:C8:7E:0D 2C:F8:9B:C8:7E:0A 2C:F8:9B:C8:7E:0B 2C:F8:9B:C8:7E:16 2C:F8:9B:C8:7E:17 2C:F8:9B:C8:7E:14 2C:F8:9B:C8:7E:15 2C:F8:9B:C8:7E:12 2C:F8:9B:C8:7E:13 2C:F8:9B:C8:7E:10 2C:F8:9B:C8:7E:11 2C:F8:9B:C8:7E:05 2C:F8:9B:C8:7E:06 2C:F8:9B:C8:7E:03 2C:F8:9B:C8:7E:47 2C:F8:9B:C8:7E:04 2C:F8:9B:C8:7E:01 2C:F8:9B:C8:7E:02 2C:F8:9B:C8:7E:00 2C:F8:9B:C8:7E:29 2C:F8:9B:C8:7E:2E 2C:F8:9B:C8:7E:2F 2C:F8:9B:C8:7E:2C 2C:F8:9B:C8:7E:2D 2C:F8:9B:C8:7E:2A 2C:F8:9B:C8:7E:2B 2C:F8:9B:C8:7E:30 2C:F8:9B:C8:7E:31 2C:F8:9B:C8:7E:73 2C:F8:9B:C8:7E:70 2C:F8:9B:C8:7E:34 2C:F8:9B:C8:7E:32 2C:F8:9B:C8:7E:33 2C:F8:9B:C8:7E:18 2C:F8:9B:C8:7E:19 2C:F8:9B:C8:7E:1F 2C:F8:9B:C8:7E:1D 2C:F8:9B:C8:7E:1E 2C:F8:9B:C8:7E:1B 2C:F8:9B:C8:7E:1C 2C:F8:9B:C8:7E:1A 2C:F8:9B:C8:7E:20 2C:F8:9B:C8:7E:27 2C:F8:9B:C8:7E:28 2C:F8:9B:C8:7E:25 2C:F8:9B:C8:7E:26 2C:F8:9B:C8:7E:23 2C:F8:9B:C8:7E:24 2C:F8:9B:C8:7E:21 2C:F8:9B:C8:7E:22 | Y9: Policy Compliance | Z9: 0 | AA9: 0 | AD9: 0 | AE9: 0 | AI9: 2026-04-20T14:59:05.184Z | AJ9: 2026-04-20T15:05:16.326Z | AK9: null | AN9: template-80295fee-c9f5-bb4f-0422-3f46012f5e2bba99a3058425a248 | AO9: c4785404-6646-486d-b008-461e60f4e791 | AP9: 2026-04-20T15:07:01.226Z | AQ9: 2026-04-20T15:02:50Z | AS9: TRUE | AT9: None | AU9: 0 | AV9: 0 | AX9: 39 | AY9: local | AZ9: $Revision: 1.887 $ | BB9: 2026-04-16T00:00:00Z | BC9: 2010-05-17T00:00:00Z | BD9: FALSE | BE9: FALSE | BF9: FALSE | BG9: FALSE | BH9: FALSE | BI9: FALSE | BJ9: FALSE | BK9: FALSE | BL9: FALSE | BM9: FALSE | BN9: FALSE | BO9: FALSE | BP9: FALSE
A10: 46689 | C10: 0 | D10: None | E10: hth2-ipflex-hth2-cube1.hilltop.systems | F10: tcp | G10: 0 | H10: Cisco IOS Compliance Checks | I10: Compliance checks for Cisco IOS devices. | J10: =MID($N10,FIND("1.",$N10),FIND("-",$N10)-FIND("1.",$N10)-1) -> 1.0005 | K10: =MID($N10,FIND("NETIOS - ",$N10)+8,FIND(":",$N10,40)-FIND("NETIOS - ",$N10)-8) -> Set 'password' for 'enable secret | L10: =MID($N10,FIND("1.",$N10),FIND("[",$N10)-1-FIND("1.",$N10)-1) -> 1.0005 - NETIOS - Set 'password' for 'enable secret | M10: =MID($N10,FIND("[",$N10)+1,FIND("]",$N10)-FIND("[",$N10)-1) -> PASSED | N10: "1.0005 - NETIOS - Set 'password' for 'enable secret: [PASSED]" Enable secret password type 5 and enable secret password type 5 must be migrated to the stronger password type 8 or 9. See Also: See HTH Policies and Standards Reference: NIST 800-53r5|AC-6(2) AC-6(5) Policy Value: CONFIG_CHECK item: enable secret [^ ]+ Actual Value: enable secret 5 $1$uhIg$.BzYCWKUy20Kl3.f78xEz/ <---- | O10: N/A | R10: 549e7be8-1405-4274-a37c-56853449b396 | T10: 10.2.166.4 | U10: hth2-ipflex-hth2-cube1.hilltop.systems | X10: A4:6C:2A:B4:73:81 A4:6C:2A:B4:73:82 A4:6C:2A:B4:73:80 | Y10: Policy Compliance | Z10: 0 | AA10: 0 | AD10: 0 | AE10: 0 | AI10: 2026-04-20T14:59:05.184Z | AJ10: 2026-04-20T15:05:16.326Z | AK10: null | AN10: template-80295fee-c9f5-bb4f-0422-3f46012f5e2bba99a3058425a248 | AO10: c4785404-6646-486d-b008-461e60f4e791 | AP10: 2026-04-20T15:07:01.218Z | AQ10: 2026-04-20T15:05:04Z | AS10: TRUE | AT10: None | AU10: 0 | AV10: 0 | AX10: 39 | AY10: local | AZ10: $Revision: 1.887 $ | BB10: 2026-04-16T00:00:00Z | BC10: 2010-05-17T00:00:00Z | BD10: FALSE | BE10: FALSE | BF10: FALSE | BG10: FALSE | BH10: FALSE | BI10: FALSE | BJ10: FALSE | BK10: FALSE | BL10: FALSE | BM10: FALSE | BN10: FALSE | BO10: FALSE | BP10: FALSE
A11: 46689 | C11: 0 | D11: None | E11: wc-harwd-sa-3202-image | F11: tcp | G11: 0 | H11: Cisco IOS Compliance Checks | I11: Compliance checks for Cisco IOS devices. | J11: =MID($N11,FIND("1.",$N11),FIND("-",$N11)-FIND("1.",$N11)-1) -> 1.0005 | K11: =MID($N11,FIND("NETIOS - ",$N11)+8,FIND(":",$N11,40)-FIND("NETIOS - ",$N11)-8) -> Set 'password' for 'enable secret | L11: =MID($N11,FIND("1.",$N11),FIND("[",$N11)-1-FIND("1.",$N11)-1) -> 1.0005 - NETIOS - Set 'password' for 'enable secret | M11: =MID($N11,FIND("[",$N11)+1,FIND("]",$N11)-FIND("[",$N11)-1) -> PASSED | N11: "1.0005 - NETIOS - Set 'password' for 'enable secret: [PASSED]" Enable secret password type 5 and enable secret password type 5 must be migrated to the stronger password type 8 or 9. See Also: See HTH Policies and Standards Reference: NIST 800-53r5|AC-6(2) AC-6(5) Policy Value: CONFIG_CHECK item: enable secret [^ ]+ Actual Value: enable secret 9 $14$Z1NL$53wlqErEEDCDlk$td5Z8TPaISnbZwCbf7oi51kS9Y0cQas2ClrSu4JqoiY <---- | O11: N/A | R11: ed63f2e6-8ee8-4077-bff4-4307d8534492 | T11: 10.132.172.254 | U11: wc-harwd-sa-3202-image | X11: 2C:F8:9B:C8:7E:09 2C:F8:9B:C8:7E:07 2C:F8:9B:C8:7E:08 2C:F8:9B:C8:7E:0E 2C:F8:9B:C8:7E:0F 2C:F8:9B:C8:7E:0C 2C:F8:9B:C8:7E:0D 2C:F8:9B:C8:7E:0A 2C:F8:9B:C8:7E:0B 2C:F8:9B:C8:7E:16 2C:F8:9B:C8:7E:17 2C:F8:9B:C8:7E:14 2C:F8:9B:C8:7E:15 2C:F8:9B:C8:7E:12 2C:F8:9B:C8:7E:13 2C:F8:9B:C8:7E:10 2C:F8:9B:C8:7E:11 2C:F8:9B:C8:7E:05 2C:F8:9B:C8:7E:06 2C:F8:9B:C8:7E:03 2C:F8:9B:C8:7E:47 2C:F8:9B:C8:7E:04 2C:F8:9B:C8:7E:01 2C:F8:9B:C8:7E:02 2C:F8:9B:C8:7E:00 2C:F8:9B:C8:7E:29 2C:F8:9B:C8:7E:2E 2C:F8:9B:C8:7E:2F 2C:F8:9B:C8:7E:2C 2C:F8:9B:C8:7E:2D 2C:F8:9B:C8:7E:2A 2C:F8:9B:C8:7E:2B 2C:F8:9B:C8:7E:30 2C:F8:9B:C8:7E:31 2C:F8:9B:C8:7E:73 2C:F8:9B:C8:7E:70 2C:F8:9B:C8:7E:34 2C:F8:9B:C8:7E:32 2C:F8:9B:C8:7E:33 2C:F8:9B:C8:7E:18 2C:F8:9B:C8:7E:19 2C:F8:9B:C8:7E:1F 2C:F8:9B:C8:7E:1D 2C:F8:9B:C8:7E:1E 2C:F8:9B:C8:7E:1B 2C:F8:9B:C8:7E:1C 2C:F8:9B:C8:7E:1A 2C:F8:9B:C8:7E:20 2C:F8:9B:C8:7E:27 2C:F8:9B:C8:7E:28 2C:F8:9B:C8:7E:25 2C:F8:9B:C8:7E:26 2C:F8:9B:C8:7E:23 2C:F8:9B:C8:7E:24 2C:F8:9B:C8:7E:21 2C:F8:9B:C8:7E:22 | Y11: Policy Compliance | Z11: 0 | AA11: 0 | AD11: 0 | AE11: 0 | AI11: 2026-04-20T14:59:05.184Z | AJ11: 2026-04-20T15:05:16.326Z | AK11: null | AN11: template-80295fee-c9f5-bb4f-0422-3f46012f5e2bba99a3058425a248 | AO11: c4785404-6646-486d-b008-461e60f4e791 | AP11: 2026-04-20T15:07:01.238Z | AQ11: 2026-04-20T15:02:50Z | AS11: TRUE | AT11: None | AU11: 0 | AV11: 0 | AX11: 39 | AY11: local | AZ11: $Revision: 1.887 $ | BB11: 2026-04-16T00:00:00Z | BC11: 2010-05-17T00:00:00Z | BD11: FALSE | BE11: FALSE | BF11: FALSE | BG11: FALSE | BH11: FALSE | BI11: FALSE | BJ11: FALSE | BK11: FALSE | BL11: FALSE | BM11: FALSE | BN11: FALSE | BO11: FALSE | BP11: FALSE
A12: 46689 | C12: 0 | D12: None | E12: hth2-ipflex-hth2-cube1.hilltop.systems | F12: tcp | G12: 0 | H12: Cisco IOS Compliance Checks | I12: Compliance checks for Cisco IOS devices. | J12: =MID($N12,FIND("1.",$N12),FIND("-",$N12)-FIND("1.",$N12)-1) -> 1.0006 | K12: =MID($N12,FIND("NETIOS - ",$N12)+8,FIND(":",$N12,40)-FIND("NETIOS - ",$N12)-8) -> Enable 'service password-encryption | L12: =MID($N12,FIND("1.",$N12),FIND("[",$N12)-1-FIND("1.",$N12)-1) -> 1.0006 - NETIOS - Enable 'service password-encryption | M12: =MID($N12,FIND("[",$N12)+1,FIND("]",$N12)-FIND("[",$N12)-1) -> PASSED | N12: "1.0006 - NETIOS - Enable 'service password-encryption: [PASSED]" When password encryption is enabled, the encrypted form of the passwords is displayed when a more system:running-config command is entered. See Also: See HTH Policies and Standards Reference: NIST 800-53r5|IA-5(1) SC-28 SC-28(1) Policy Value: CONFIG_CHECK item: service password-encryption Actual Value: service password-encryption <---- | O12: N/A | R12: 549e7be8-1405-4274-a37c-56853449b396 | T12: 10.2.166.4 | U12: hth2-ipflex-hth2-cube1.hilltop.systems | X12: A4:6C:2A:B4:73:81 A4:6C:2A:B4:73:82 A4:6C:2A:B4:73:80 | Y12: Policy Compliance | Z12: 0 | AA12: 0 | AD12: 0 | AE12: 0 | AI12: 2026-04-20T14:59:05.184Z | AJ12: 2026-04-20T15:05:16.326Z | AK12: null | AN12: template-80295fee-c9f5-bb4f-0422-3f46012f5e2bba99a3058425a248 | AO12: c4785404-6646-486d-b008-461e60f4e791 | AP12: 2026-04-20T15:07:01.213Z | AQ12: 2026-04-20T15:05:04Z | AS12: TRUE | AT12: None | AU12: 0 | AV12: 0 | AX12: 39 | AY12: local | AZ12: $Revision: 1.887 $ | BB12: 2026-04-16T00:00:00Z | BC12: 2010-05-17T00:00:00Z | BD12: FALSE | BE12: FALSE | BF12: FALSE | BG12: FALSE | BH12: FALSE | BI12: FALSE | BJ12: FALSE | BK12: FALSE | BL12: FALSE | BM12: FALSE | BN12: FALSE | BO12: FALSE | BP12: FALSE
A13: 46689 | C13: 0 | D13: None | E13: wc-harwd-sa-3202-image | F13: tcp | G13: 0 | H13: Cisco IOS Compliance Checks | I13: Compliance checks for Cisco IOS devices. | J13: =MID($N13,FIND("1.",$N13),FIND("-",$N13)-FIND("1.",$N13)-1) -> 1.0006 | K13: =MID($N13,FIND("NETIOS - ",$N13)+8,FIND(":",$N13,40)-FIND("NETIOS - ",$N13)-8) -> Enable 'service password-encryption | L13: =MID($N13,FIND("1.",$N13),FIND("[",$N13)-1-FIND("1.",$N13)-1) -> 1.0006 - NETIOS - Enable 'service password-encryption | M13: =MID($N13,FIND("[",$N13)+1,FIND("]",$N13)-FIND("[",$N13)-1) -> PASSED | N13: "1.0006 - NETIOS - Enable 'service password-encryption: [PASSED]" When password encryption is enabled, the encrypted form of the passwords is displayed when a more system:running-config command is entered. See Also: See HTH Policies and Standards Reference: NIST 800-53r5|IA-5(1) SC-28 SC-28(1) Policy Value: CONFIG_CHECK item: service password-encryption Actual Value: service password-encryption <---- | O13: N/A | R13: ed63f2e6-8ee8-4077-bff4-4307d8534492 | T13: 10.132.172.254 | U13: wc-harwd-sa-3202-image | X13: 2C:F8:9B:C8:7E:09 2C:F8:9B:C8:7E:07 2C:F8:9B:C8:7E:08 2C:F8:9B:C8:7E:0E 2C:F8:9B:C8:7E:0F 2C:F8:9B:C8:7E:0C 2C:F8:9B:C8:7E:0D 2C:F8:9B:C8:7E:0A 2C:F8:9B:C8:7E:0B 2C:F8:9B:C8:7E:16 2C:F8:9B:C8:7E:17 2C:F8:9B:C8:7E:14 2C:F8:9B:C8:7E:15 2C:F8:9B:C8:7E:12 2C:F8:9B:C8:7E:13 2C:F8:9B:C8:7E:10 2C:F8:9B:C8:7E:11 2C:F8:9B:C8:7E:05 2C:F8:9B:C8:7E:06 2C:F8:9B:C8:7E:03 2C:F8:9B:C8:7E:47 2C:F8:9B:C8:7E:04 2C:F8:9B:C8:7E:01 2C:F8:9B:C8:7E:02 2C:F8:9B:C8:7E:00 2C:F8:9B:C8:7E:29 2C:F8:9B:C8:7E:2E 2C:F8:9B:C8:7E:2F 2C:F8:9B:C8:7E:2C 2C:F8:9B:C8:7E:2D 2C:F8:9B:C8:7E:2A 2C:F8:9B:C8:7E:2B 2C:F8:9B:C8:7E:30 2C:F8:9B:C8:7E:31 2C:F8:9B:C8:7E:73 2C:F8:9B:C8:7E:70 2C:F8:9B:C8:7E:34 2C:F8:9B:C8:7E:32 2C:F8:9B:C8:7E:33 2C:F8:9B:C8:7E:18 2C:F8:9B:C8:7E:19 2C:F8:9B:C8:7E:1F 2C:F8:9B:C8:7E:1D 2C:F8:9B:C8:7E:1E 2C:F8:9B:C8:7E:1B 2C:F8:9B:C8:7E:1C 2C:F8:9B:C8:7E:1A 2C:F8:9B:C8:7E:20 2C:F8:9B:C8:7E:27 2C:F8:9B:C8:7E:28 2C:F8:9B:C8:7E:25 2C:F8:9B:C8:7E:26 2C:F8:9B:C8:7E:23 2C:F8:9B:C8:7E:24 2C:F8:9B:C8:7E:21 2C:F8:9B:C8:7E:22 | Y13: Policy Compliance | Z13: 0 | AA13: 0 | AD13: 0 | AE13: 0 | AI13: 2026-04-20T14:59:05.184Z | AJ13: 2026-04-20T15:05:16.326Z | AK13: null | AN13: template-80295fee-c9f5-bb4f-0422-3f46012f5e2bba99a3058425a248 | AO13: c4785404-6646-486d-b008-461e60f4e791 | AP13: 2026-04-20T15:07:01.232Z | AQ13: 2026-04-20T15:02:50Z | AS13: TRUE | AT13: None | AU13: 0 | AV13: 0 | AX13: 39 | AY13: local | AZ13: $Revision: 1.887 $ | BB13: 2026-04-16T00:00:00Z | BC13: 2010-05-17T00:00:00Z | BD13: FALSE | BE13: FALSE | BF13: FALSE | BG13: FALSE | BH13: FALSE | BI13: FALSE | BJ13: FALSE | BK13: FALSE | BL13: FALSE | BM13: FALSE | BN13: FALSE | BO13: FALSE | BP13: FALSE
A14: 46689 | C14: 0 | D14: None | E14: hth2-ipflex-hth2-cube1.hilltop.systems | F14: tcp | G14: 0 | H14: Cisco IOS Compliance Checks | I14: Compliance checks for Cisco IOS devices. | J14: =MID($N14,FIND("1.",$N14),FIND("-",$N14)-FIND("1.",$N14)-1) -> 1.0007 | K14: =MID($N14,FIND("NETIOS - ",$N14)+8,FIND(":",$N14,40)-FIND("NETIOS - ",$N14)-8) -> Set 'username secret' for all local users | L14: =MID($N14,FIND("1.",$N14),FIND("[",$N14)-1-FIND("1.",$N14)-1) -> 1.0007 - NETIOS - Set 'username secret' for all local users | M14: =MID($N14,FIND("[",$N14)+1,FIND("]",$N14)-FIND("[",$N14)-1) -> PASSED | N14: "1.0007 - NETIOS - Set 'username secret' for all local users: [PASSED]" Username secret password type 5 and enable secret password type 5 must be migrated to the stronger password type 8 or 9. See Also: See HTH Policies and Standards Reference: NIST 800-53r5|IA-5(1) SC-28 SC-28(1) Policy Value: CONFIG_CHECK item: username [^ ]+ regex: username .+ secret [^ ]+ Actual Value: username globaladmin privilege 15 secret 5 $1$iknv$WmqdYILsqNKDVIO.mBTZ80 <---- | O14: N/A | R14: 549e7be8-1405-4274-a37c-56853449b396 | T14: 10.2.166.4 | U14: hth2-ipflex-hth2-cube1.hilltop.systems | X14: A4:6C:2A:B4:73:81 A4:6C:2A:B4:73:82 A4:6C:2A:B4:73:80 | Y14: Policy Compliance | Z14: 0 | AA14: 0 | AD14: 0 | AE14: 0 | AI14: 2026-04-20T14:59:05.184Z | AJ14: 2026-04-20T15:05:16.326Z | AK14: null | AN14: template-80295fee-c9f5-bb4f-0422-3f46012f5e2bba99a3058425a248 | AO14: c4785404-6646-486d-b008-461e60f4e791 | AP14: 2026-04-20T15:07:01.213Z | AQ14: 2026-04-20T15:05:04Z | AS14: TRUE | AT14: None | AU14: 0 | AV14: 0 | AX14: 39 | AY14: local | AZ14: $Revision: 1.887 $ | BB14: 2026-04-16T00:00:00Z | BC14: 2010-05-17T00:00:00Z | BD14: FALSE | BE14: FALSE | BF14: FALSE | BG14: FALSE | BH14: FALSE | BI14: FALSE | BJ14: FALSE | BK14: FALSE | BL14: FALSE | BM14: FALSE | BN14: FALSE | BO14: FALSE | BP14: FALSE
... A49: 46689 | C49: 0 | D49: None | E49: wc-harwd-sa-3202-image | F49: tcp | G49: 0 | H49: Cisco IOS Compliance Checks | I49: Compliance checks for Cisco IOS devices. | J49: =MID($N49,FIND("1.",$N49),FIND("-",$N49)-FIND("1.",$N49)-1) -> 1.0024 | K49: =MID($N49,FIND("NETIOS - ",$N49)+8,FIND(":",$N49,40)-FIND("NETIOS - ",$N49)-8) -> Enable 'aaa new-model | L49: =MID($N49,FIND("1.",$N49),FIND("[",$N49)-1-FIND("1.",$N49)-1) -> 1.0024 - NETIOS - Enable 'aaa new-model | M49: =MID($N49,FIND("[",$N49)+1,FIND("]",$N49)-FIND("[",$N49)-1) -> PASSED | N49: "1.0024 - NETIOS - Enable 'aaa new-model: [PASSED]" This command enables the AAA access control system. See Also: See HTH Policies and Standards Reference: NIST 800-53r5|AC-2(1) Policy Value: CONFIG_CHECK item: aaa new-model[ ]*$ Actual Value: aaa new-model <---- | O49: N/A | R49: ed63f2e6-8ee8-4077-bff4-4307d8534492 | T49: 10.132.172.254 | U49: wc-harwd-sa-3202-image | X49: 2C:F8:9B:C8:7E:09 2C:F8:9B:C8:7E:07 2C:F8:9B:C8:7E:08 2C:F8:9B:C8:7E:0E 2C:F8:9B:C8:7E:0F 2C:F8:9B:C8:7E:0C 2C:F8:9B:C8:7E:0D 2C:F8:9B:C8:7E:0A 2C:F8:9B:C8:7E:0B 2C:F8:9B:C8:7E:16 2C:F8:9B:C8:7E:17 2C:F8:9B:C8:7E:14 2C:F8:9B:C8:7E:15 2C:F8:9B:C8:7E:12 2C:F8:9B:C8:7E:13 2C:F8:9B:C8:7E:10 2C:F8:9B:C8:7E:11 2C:F8:9B:C8:7E:05 2C:F8:9B:C8:7E:06 2C:F8:9B:C8:7E:03 2C:F8:9B:C8:7E:47 2C:F8:9B:C8:7E:04 2C:F8:9B:C8:7E:01 2C:F8:9B:C8:7E:02 2C:F8:9B:C8:7E:00 2C:F8:9B:C8:7E:29 2C:F8:9B:C8:7E:2E 2C:F8:9B:C8:7E:2F 2C:F8:9B:C8:7E:2C 2C:F8:9B:C8:7E:2D 2C:F8:9B:C8:7E:2A 2C:F8:9B:C8:7E:2B 2C:F8:9B:C8:7E:30 2C:F8:9B:C8:7E:31 2C:F8:9B:C8:7E:73 2C:F8:9B:C8:7E:70 2C:F8:9B:C8:7E:34 2C:F8:9B:C8:7E:32 2C:F8:9B:C8:7E:33 2C:F8:9B:C8:7E:18 2C:F8:9B:C8:7E:19 2C:F8:9B:C8:7E:1F 2C:F8:9B:C8:7E:1D 2C:F8:9B:C8:7E:1E 2C:F8:9B:C8:7E:1B 2C:F8:9B:C8:7E:1C 2C:F8:9B:C8:7E:1A 2C:F8:9B:C8:7E:20 2C:F8:9B:C8:7E:27 2C:F8:9B:C8:7E:28 2C:F8:9B:C8:7E:25 2C:F8:9B:C8:7E:26 2C:F8:9B:C8:7E:23 2C:F8:9B:C8:7E:24 2C:F8:9B:C8:7E:21 2C:F8:9B:C8:7E:22 | Y49: Policy Compliance | Z49: 0 | AA49: 0 | AD49: 0 | AE49: 0 | AI49: 2026-04-20T14:59:05.184Z | AJ49: 2026-04-20T15:05:16.326Z | AK49: null | AN49: template-80295fee-c9f5-bb4f-0422-3f46012f5e2bba99a3058425a248 | AO49: c4785404-6646-486d-b008-461e60f4e791 | AP49: 2026-04-20T15:07:01.246Z | AQ49: 2026-04-20T15:02:50Z | AS49: TRUE | AT49: None | AU49: 0 | AV49: 0 | AX49: 39 | AY49: local | AZ49: $Revision: 1.887 $ | BB49: 2026-04-16T00:00:00Z | BC49: 2010-05-17T00:00:00Z | BD49: FALSE | BE49: FALSE | BF49: FALSE | BG49: FALSE | BH49: FALSE | BI49: FALSE | BJ49: FALSE | BK49: FALSE | BL49: FALSE | BM49: FALSE | BN49: FALSE | BO49: FALSE | BP49: FALSE

Sheet Potential
A1: Plugin ID | B1: CVE | C1: CVSS | D1: Risk | E1: Host | F1: Protocol | G1: Port | H1: Name | I1: Synopsis | J1: Item | K1: Short Description | L1: Audit Name | M1: Status | N1: Description | O1: Solution | P1: See Also | Q1: Plugin Output | R1: Asset UUID | S1: Vulnerability State | T1: IP Address | U1: FQDN | V1: NetBios | W1: OS | X1: MAC Address | Y1: Plugin Family | Z1: CVSS Base Score | AA1: CVSS Temporal Score | AB1: CVSS Temporal Vector | AC1: CVSS Vector | AD1: CVSS3 Base Score | AE1: CVSS3 Temporal Score | AF1: CVSS3 Temporal Vector | AG1: CVSS3 Vector | AH1: System Type | AI1: Host Start | AJ1: Host End | AK1: Vulnerability Priority Rating (VPR) | AL1: First Found | AM1: Last Found | AN1: Host Scan Schedule ID | AO1: Host Scan ID | AP1: Indexed At | AQ1: Last Authenticated Results Date | AR1: Last Unauthenticated Results Date | AS1: Tracked | AT1: Risk Factor | AU1: Severity | AV1: Original Severity | AW1: Modification | AX1: Plugin Family ID | AY1: Plugin Type | AZ1: Plugin Version | BA1: Service | BB1: Plugin Modification Date | BC1: Plugin Publication Date | BD1: Checks for Malware | BE1: Exploit Available | BF1: Exploited by Malware | BG1: Exploited by Nessus | BH1: CANVAS | BI1: D2 Elliot | BJ1: Metasploit | BK1: Core Exploits | BL1: ExploitHub | BM1: Default Account | BN1: Patch Available | BO1: In The News | BP1: Unsupported By Vendor | BQ1: Last Fixed | BR1: Already Pass/Not Assessed
A2: 46689 | C2: 0 | D2: None | E2: hth2-ipflex-hth2-cube1.hilltop.systems | F2: tcp | G2: 0 | H2: Cisco IOS Compliance Checks | I2: Compliance checks for Cisco IOS devices. | J2: =MID($N2,FIND("1.",$N2),FIND("-",$N2)-FIND("1.",$N2)-1) -> 1.0025 | K2: =MID($N2,FIND("NETIOS - ",$N2)+8,FIND(":",$N2,40)-FIND("NETIOS - ",$N2)-8) -> Enable 'aaa authentication enable default | L2: =MID($N2,FIND("1.",$N2),FIND("[",$N2)-1-FIND("1.",$N2)-1) -> 1.0025 - NETIOS - Enable 'aaa authentication enable default | M2: =MID($N2,FIND("[",$N2)+1,FIND("]",$N2)-FIND("[",$N2)-1) -> PASSED | N2: "1.0025 - NETIOS - Enable 'aaa authentication enable default: [PASSED]" Authenticates users who access privileged EXEC mode when they use the enable command. See Also: See HTH Policies and Standards Reference: NIST 800-53r5|AC-2(1) Policy Value: CONFIG_CHECK item: aaa authentication enable default Actual Value: aaa authentication enable default group ISE-TACACS enable <---- | O2: N/A | R2: 549e7be8-1405-4274-a37c-56853449b396 | T2: 10.2.166.4 | U2: hth2-ipflex-hth2-cube1.hilltop.systems | X2: A4:6C:2A:B4:73:81 A4:6C:2A:B4:73:82 A4:6C:2A:B4:73:80 | Y2: Policy Compliance | Z2: 0 | AA2: 0 | AD2: 0 | AE2: 0 | AI2: 2026-04-20T14:36:10.744Z | AJ2: 2026-04-20T14:42:23.901Z | AK2: null | AN2: template-80295fee-c9f5-bb4f-0422-3f46012f5e2bba99a3058425a248 | AO2: dda80223-7230-4f84-93c3-cc2b0802dfe9 | AP2: 2026-04-20T14:45:52.581Z | AQ2: 2026-04-20T14:42:12Z | AS2: TRUE | AT2: None | AU2: 0 | AV2: 0 | AX2: 39 | AY2: local | AZ2: $Revision: 1.887 $ | BB2: 2026-04-16T00:00:00Z | BC2: 2010-05-17T00:00:00Z | BD2: FALSE | BE2: FALSE | BF2: FALSE | BG2: FALSE | BH2: FALSE | BI2: FALSE | BJ2: FALSE | BK2: FALSE | BL2: FALSE | BM2: FALSE | BN2: FALSE | BO2: FALSE | BP2: FALSE | BR2: =IFERROR(IF(M2="PASSED",VLOOKUP(J2,Current!J1:BR61,1,FALSE)),N2) -> "1.0025 - NETIOS - Enable 'aaa authentication enable default: [PASSED]" Authenticates users who access privileged EXEC mode when they use the enable command. See Also: See HTH Policies and Standards Reference: NIST 800-53r5|AC-2(1) Policy Value: CONFIG_CHECK item: aaa authentication enable default Actual Value: aaa authentication enable default group ISE-TACACS enable <----
A3: 46689 | C3: 0 | D3: High | E3: hth2-ipflex-hth2-cube1.hilltop.systems | F3: tcp | G3: 0 | H3: Cisco IOS Compliance Checks | I3: Compliance checks for Cisco IOS devices. | J3: =MID($N3,FIND("1.",$N3),FIND("-",$N3)-FIND("1.",$N3)-1) -> 1.0026 | K3: =MID($N3,FIND("NETIOS - ",$N3)+8,FIND(":",$N3,40)-FIND("NETIOS - ",$N3)-8) -> Set 'privilege 1' for local users | L3: =MID($N3,FIND("1.",$N3),FIND("[",$N3)-1-FIND("1.",$N3)-1) -> 1.0026 - NETIOS - Set 'privilege 1' for local users | M3: =MID($N3,FIND("[",$N3)+1,FIND("]",$N3)-FIND("[",$N3)-1) -> FAILED | N3: "1.0026 - NETIOS - Set 'privilege 1' for local users: [FAILED]" Sets the privilege level for the user. See Also: See HTH Policies and Standards Reference: NIST 800-53r5|IA-2(2) IA-5(1) Policy Value: CONFIG_CHECK_NOT item: username .+ privilege ([2-9]|1[0-5]) Actual Value: username globaladmin privilege 15 secret 5 $1$iknv$WmqdYILsqNKDVIO.mBTZ80 <---- | O3: N/A | R3: 549e7be8-1405-4274-a37c-56853449b396 | T3: 10.2.166.4 | U3: hth2-ipflex-hth2-cube1.hilltop.systems | X3: A4:6C:2A:B4:73:81 A4:6C:2A:B4:73:82 A4:6C:2A:B4:73:80 | Y3: Policy Compliance | Z3: 0 | AA3: 0 | AD3: 0 | AE3: 0 | AI3: 2026-04-20T14:36:10.744Z | AJ3: 2026-04-20T14:42:23.901Z | AK3: null | AN3: template-80295fee-c9f5-bb4f-0422-3f46012f5e2bba99a3058425a248 | AO3: dda80223-7230-4f84-93c3-cc2b0802dfe9 | AP3: 2026-04-20T14:45:52.591Z | AQ3: 2026-04-20T14:42:12Z | AS3: TRUE | AT3: None | AU3: 0 | AV3: 0 | AX3: 39 | AY3: local | AZ3: $Revision: 1.887 $ | BB3: 2026-04-16T00:00:00Z | BC3: 2010-05-17T00:00:00Z | BD3: FALSE | BE3: FALSE | BF3: FALSE | BG3: FALSE | BH3: FALSE | BI3: FALSE | BJ3: FALSE | BK3: FALSE | BL3: FALSE | BM3: FALSE | BN3: FALSE | BO3: FALSE | BP3: FALSE | BR3: =IFERROR(IF(M3="PASSED",VLOOKUP(J3,Current!J3:BR63,1,FALSE)),N3) -> FALSE
A4: 46689 | C4: 0 | D4: High | E4: hth2-ipflex-hth2-cube1.hilltop.systems | F4: tcp | G4: 0 | H4: Cisco IOS Compliance Checks | I4: Compliance checks for Cisco IOS devices. | J4: =MID($N4,FIND("1.",$N4),FIND("-",$N4)-FIND("1.",$N4)-1) -> 1.0027 | K4: =MID($N4,FIND("NETIOS - ",$N4)+8,FIND(":",$N4,40)-FIND("NETIOS - ",$N4)-8) -> Set 'http Secure-server' limit | L4: =MID($N4,FIND("1.",$N4),FIND("[",$N4)-1-FIND("1.",$N4)-1) -> 1.0027 - NETIOS - Set 'http Secure-server' limit | M4: =MID($N4,FIND("[",$N4)+1,FIND("]",$N4)-FIND("[",$N4)-1) -> FAILED | N4: "1.0027 - NETIOS - Set 'http Secure-server' limit: [FAILED]" Device management includes the ability to control the number of administrators and management sessions that manage a device. See Also: See HTH Policies and Standards Reference: NIST 800-53r5|AC-10 Policy Value: CONFIG_CHECK item: ip http max-connections 2 Actual Value: ip http max-connections 2 not found in the configuration file | O4: N/A | R4: 549e7be8-1405-4274-a37c-56853449b396 | T4: 10.2.166.4 | U4: hth2-ipflex-hth2-cube1.hilltop.systems | X4: A4:6C:2A:B4:73:81 A4:6C:2A:B4:73:82 A4:6C:2A:B4:73:80 | Y4: Policy Compliance | Z4: 0 | AA4: 0 | AD4: 0 | AE4: 0 | AI4: 2026-04-20T14:36:10.744Z | AJ4: 2026-04-20T14:42:23.901Z | AK4: null | AN4: template-80295fee-c9f5-bb4f-0422-3f46012f5e2bba99a3058425a248 | AO4: dda80223-7230-4f84-93c3-cc2b0802dfe9 | AP4: 2026-04-20T14:45:52.585Z | AQ4: 2026-04-20T14:42:12Z | AS4: TRUE | AT4: None | AU4: 0 | AV4: 0 | AX4: 39 | AY4: local | AZ4: $Revision: 1.887 $ | BB4: 2026-04-16T00:00:00Z | BC4: 2010-05-17T00:00:00Z | BD4: FALSE | BE4: FALSE | BF4: FALSE | BG4: FALSE | BH4: FALSE | BI4: FALSE | BJ4: FALSE | BK4: FALSE | BL4: FALSE | BM4: FALSE | BN4: FALSE | BO4: FALSE | BP4: FALSE | BR4: =IFERROR(IF(M4="PASSED",VLOOKUP(J4,Current!J5:BR65,1,FALSE)),N4) -> FALSE
A5: 46689 | C5: 0 | D5: High | E5: hth2-ipflex-hth2-cube1.hilltop.systems | F5: tcp | G5: 0 | H5: Cisco IOS Compliance Checks | I5: Compliance checks for Cisco IOS devices. | J5: =MID($N5,FIND("1.",$N5),FIND("-",$N5)-FIND("1.",$N5)-1) -> 1.0028 | K5: =MID($N5,FIND("NETIOS - ",$N5)+8,FIND(":",$N5,40)-FIND("NETIOS - ",$N5)-8) -> Set 'exec-timeout' to less than or equal to 10 min on 'ip http | L5: =MID($N5,FIND("1.",$N5),FIND("[",$N5)-1-FIND("1.",$N5)-1) -> 1.0028 - NETIOS - Set 'exec-timeout' to less than or equal to 10 min on 'ip http | M5: =MID($N5,FIND("[",$N5)+1,FIND("]",$N5)-FIND("[",$N5)-1) -> FAILED | N5: "1.0028 - NETIOS - Set 'exec-timeout' to less than or equal to 10 min on 'ip http: [FAILED]" If no input is detected during the interval, the EXEC facility resumes the current connection. See Also: See HTH Policies and Standards Reference: NIST 800-53r5|AC-2(5) AC-11 AC-11(1) AC-12 Policy Value: CONFIG_CHECK item: ip http timeout-policy idle ([1-9]|[1-9][0-9]|[1-5][0-9]{2}|600) life .+ requests .+ Actual Value: ip http timeout-policy idle ([1-9]|[1-9][0-9]|[1-5][0-9]{2}|600) life .+ requests .+ not found in the configuration file | O5: N/A | R5: 549e7be8-1405-4274-a37c-56853449b396 | T5: 10.2.166.4 | U5: hth2-ipflex-hth2-cube1.hilltop.systems | X5: A4:6C:2A:B4:73:81 A4:6C:2A:B4:73:82 A4:6C:2A:B4:73:80 | Y5: Policy Compliance | Z5: 0 | AA5: 0 | AD5: 0 | AE5: 0 | AI5: 2026-04-20T14:36:10.744Z | AJ5: 2026-04-20T14:42:23.901Z | AK5: null | AN5: template-80295fee-c9f5-bb4f-0422-3f46012f5e2bba99a3058425a248 | AO5: dda80223-7230-4f84-93c3-cc2b0802dfe9 | AP5: 2026-04-20T14:45:52.601Z | AQ5: 2026-04-20T14:42:12Z | AS5: TRUE | AT5: None | AU5: 0 | AV5: 0 | AX5: 39 | AY5: local | AZ5: $Revision: 1.887 $ | BB5: 2026-04-16T00:00:00Z | BC5: 2010-05-17T00:00:00Z | BD5: FALSE | BE5: FALSE | BF5: FALSE | BG5: FALSE | BH5: FALSE | BI5: FALSE | BJ5: FALSE | BK5: FALSE | BL5: FALSE | BM5: FALSE | BN5: FALSE | BO5: FALSE | BP5: FALSE | BR5: =IFERROR(IF(M5="PASSED",VLOOKUP(J5,Current!J7:BR67,1,FALSE)),N5) -> FALSE
A6: 46689 | C6: 0 | D6: High | E6: wc-harwd-sa-3202-image | F6: tcp | G6: 0 | H6: Cisco IOS Compliance Checks | I6: Compliance checks for Cisco IOS devices. | J6: =MID($N6,FIND("1.",$N6),FIND("-",$N6)-FIND("1.",$N6)-1) -> 1.0029 | K6: =MID($N6,FIND("NETIOS - ",$N6)+8,FIND(":",$N6,40)-FIND("NETIOS - ",$N6)-8) -> Set 'no exec' for 'line aux 0 | L6: =MID($N6,FIND("1.",$N6),FIND("[",$N6)-1-FIND("1.",$N6)-1) -> 1.0029 - NETIOS - Set 'no exec' for 'line aux 0 | M6: =MID($N6,FIND("[",$N6)+1,FIND("]",$N6)-FIND("[",$N6)-1) -> FAILED | N6: "1.0029 - NETIOS - Set 'no exec' for 'line aux 0: [FAILED]" The 'no exec' command restricts a line to outgoing connections only. See Also: See HTH Policies and Standards Reference: NIST 800-53r5|CM-7 Policy Value: CONFIG_CHECK item: no exec context: line aux .+ Actual Value: line aux 0 stopbits 1 Expected configuration: no exec | O6: N/A | R6: ed63f2e6-8ee8-4077-bff4-4307d8534492 | T6: 10.132.172.254 | U6: wc-harwd-sa-3202-image | X6: 2C:F8:9B:C8:7E:09 2C:F8:9B:C8:7E:07 2C:F8:9B:C8:7E:08 2C:F8:9B:C8:7E:0E 2C:F8:9B:C8:7E:0F 2C:F8:9B:C8:7E:0C 2C:F8:9B:C8:7E:0D 2C:F8:9B:C8:7E:0A 2C:F8:9B:C8:7E:0B 2C:F8:9B:C8:7E:16 2C:F8:9B:C8:7E:17 2C:F8:9B:C8:7E:14 2C:F8:9B:C8:7E:15 2C:F8:9B:C8:7E:12 2C:F8:9B:C8:7E:13 2C:F8:9B:C8:7E:10 2C:F8:9B:C8:7E:11 2C:F8:9B:C8:7E:05 2C:F8:9B:C8:7E:06 2C:F8:9B:C8:7E:03 2C:F8:9B:C8:7E:47 2C:F8:9B:C8:7E:04 2C:F8:9B:C8:7E:01 2C:F8:9B:C8:7E:02 2C:F8:9B:C8:7E:00 2C:F8:9B:C8:7E:29 2C:F8:9B:C8:7E:2E 2C:F8:9B:C8:7E:2F 2C:F8:9B:C8:7E:2C 2C:F8:9B:C8:7E:2D 2C:F8:9B:C8:7E:2A 2C:F8:9B:C8:7E:2B 2C:F8:9B:C8:7E:30 2C:F8:9B:C8:7E:31 2C:F8:9B:C8:7E:73 2C:F8:9B:C8:7E:70 2C:F8:9B:C8:7E:34 2C:F8:9B:C8:7E:32 2C:F8:9B:C8:7E:33 2C:F8:9B:C8:7E:18 2C:F8:9B:C8:7E:19 2C:F8:9B:C8:7E:1F 2C:F8:9B:C8:7E:1D 2C:F8:9B:C8:7E:1E 2C:F8:9B:C8:7E:1B 2C:F8:9B:C8:7E:1C 2C:F8:9B:C8:7E:1A 2C:F8:9B:C8:7E:20 2C:F8:9B:C8:7E:27 2C:F8:9B:C8:7E:28 2C:F8:9B:C8:7E:25 2C:F8:9B:C8:7E:26 2C:F8:9B:C8:7E:23 2C:F8:9B:C8:7E:24 2C:F8:9B:C8:7E:21 2C:F8:9B:C8:7E:22 | Y6: Policy Compliance | Z6: 0 | AA6: 0 | AD6: 0 | AE6: 0 | AI6: 2026-04-20T14:36:10.744Z | AJ6: 2026-04-20T14:42:23.901Z | AK6: null | AN6: template-80295fee-c9f5-bb4f-0422-3f46012f5e2bba99a3058425a248 | AO6: dda80223-7230-4f84-93c3-cc2b0802dfe9 | AP6: 2026-04-20T14:45:52.605Z | AQ6: 2026-04-20T14:40:07Z | AS6: TRUE | AT6: None | AU6: 0 | AV6: 0 | AX6: 39 | AY6: local | AZ6: $Revision: 1.887 $ | BB6: 2026-04-16T00:00:00Z | BC6: 2010-05-17T00:00:00Z | BD6: FALSE | BE6: FALSE | BF6: FALSE | BG6: FALSE | BH6: FALSE | BI6: FALSE | BJ6: FALSE | BK6: FALSE | BL6: FALSE | BM6: FALSE | BN6: FALSE | BO6: FALSE | BP6: FALSE | BR6: =IFERROR(IF(M6="PASSED",VLOOKUP(J6,Current!J9:BR69,1,FALSE)),N6) -> FALSE
A7: 46689 | C7: 0 | D7: None | E7: hth2-ipflex-hth2-cube1.hilltop.systems | F7: tcp | G7: 0 | H7: Cisco IOS Compliance Checks | I7: Compliance checks for Cisco IOS devices. | J7: =MID($N7,FIND("1.",$N7),FIND("-",$N7)-FIND("1.",$N7)-1) -> 1.0029 | K7: =MID($N7,FIND("NETIOS - ",$N7)+8,FIND(":",$N7,40)-FIND("NETIOS - ",$N7)-8) -> Set 'no exec' for 'line aux 0 | L7: =MID($N7,FIND("1.",$N7),FIND("[",$N7)-1-FIND("1.",$N7)-1) -> 1.0029 - NETIOS - Set 'no exec' for 'line aux 0 | M7: =MID($N7,FIND("[",$N7)+1,FIND("]",$N7)-FIND("[",$N7)-1) -> PASSED | N7: "1.0029 - NETIOS - Set 'no exec' for 'line aux 0: [PASSED]" The 'no exec' command restricts a line to outgoing connections only. See Also: See HTH Policies and Standards Reference: NIST 800-53r5|CM-7 Policy Value: CONFIG_CHECK item: no exec context: line aux .+ Actual Value: line aux 0 no exec <---- | O7: N/A | R7: 549e7be8-1405-4274-a37c-56853449b396 | T7: 10.2.166.4 | U7: hth2-ipflex-hth2-cube1.hilltop.systems | X7: A4:6C:2A:B4:73:81 A4:6C:2A:B4:73:82 A4:6C:2A:B4:73:80 | Y7: Policy Compliance | Z7: 0 | AA7: 0 | AD7: 0 | AE7: 0 | AI7: 2026-04-20T14:36:10.744Z | AJ7: 2026-04-20T14:42:23.901Z | AK7: null | AN7: template-80295fee-c9f5-bb4f-0422-3f46012f5e2bba99a3058425a248 | AO7: dda80223-7230-4f84-93c3-cc2b0802dfe9 | AP7: 2026-04-20T14:45:52.584Z | AQ7: 2026-04-20T14:42:12Z | AS7: TRUE | AT7: None | AU7: 0 | AV7: 0 | AX7: 39 | AY7: local | AZ7: $Revision: 1.887 $ | BB7: 2026-04-16T00:00:00Z | BC7: 2010-05-17T00:00:00Z | BD7: FALSE | BE7: FALSE | BF7: FALSE | BG7: FALSE | BH7: FALSE | BI7: FALSE | BJ7: FALSE | BK7: FALSE | BL7: FALSE | BM7: FALSE | BN7: FALSE | BO7: FALSE | BP7: FALSE | BR7: =IFERROR(IF(M7="PASSED",VLOOKUP(J7,Current!J10:BR70,1,FALSE)),N7) -> "1.0029 - NETIOS - Set 'no exec' for 'line aux 0: [PASSED]" The 'no exec' command restricts a line to outgoing connections only. See Also: See HTH Policies and Standards Reference: NIST 800-53r5|CM-7 Policy Value: CONFIG_CHECK item: no exec context: line aux .+ Actual Value: line aux 0 no exec <----
A8: 46689 | C8: 0 | D8: High | E8: hth2-ipflex-hth2-cube1.hilltop.systems | F8: tcp | G8: 0 | H8: Cisco IOS Compliance Checks | I8: Compliance checks for Cisco IOS devices. | J8: =MID($N8,FIND("1.",$N8),FIND("-",$N8)-FIND("1.",$N8)-1) -> 1.0030 | K8: =MID($N8,FIND("NETIOS - ",$N8)+8,FIND(":",$N8,40)-FIND("NETIOS - ",$N8)-8) -> Set 'access-class' for 'line vty | L8: =MID($N8,FIND("1.",$N8),FIND("[",$N8)-1-FIND("1.",$N8)-1) -> 1.0030 - NETIOS - Set 'access-class' for 'line vty | M8: =MID($N8,FIND("[",$N8)+1,FIND("]",$N8)-FIND("[",$N8)-1) -> FAILED | N8: "1.0030 - NETIOS - Set 'access-class' for 'line vty: [FAILED]" The 'access-class' setting restricts incoming and outgoing connections between a particular vty (into a Cisco device) and the networking devices associated with addresses in an access list. See Also: See HTH Policies and Standards Reference: NIST 800-53r5|AC-17(3) SI-7 Policy Value: CONFIG_CHECK item: access-class 100 in context: line vty .+ Actual Value: line vty 0 4 exec-timeout 15 0 privilege level 15 password 7 04681B07012A551F logging synchronous login authentication VTY-Access length 0 transport input ssh transport output ssh Expected configuration: access-class 100 in | O8: N/A | R8: 549e7be8-1405-4274-a37c-56853449b396 | T8: 10.2.166.4 | U8: hth2-ipflex-hth2-cube1.hilltop.systems | X8: A4:6C:2A:B4:73:81 A4:6C:2A:B4:73:82 A4:6C:2A:B4:73:80 | Y8: Policy Compliance | Z8: 0 | AA8: 0 | AD8: 0 | AE8: 0 | AI8: 2026-04-20T14:36:10.744Z | AJ8: 2026-04-20T14:42:23.901Z | AK8: null | AN8: template-80295fee-c9f5-bb4f-0422-3f46012f5e2bba99a3058425a248 | AO8: dda80223-7230-4f84-93c3-cc2b0802dfe9 | AP8: 2026-04-20T14:45:52.598Z | AQ8: 2026-04-20T14:42:12Z | AS8: TRUE | AT8: None | AU8: 0 | AV8: 0 | AX8: 39 | AY8: local | AZ8: $Revision: 1.887 $ | BB8: 2026-04-16T00:00:00Z | BC8: 2010-05-17T00:00:00Z | BD8: FALSE | BE8: FALSE | BF8: FALSE | BG8: FALSE | BH8: FALSE | BI8: FALSE | BJ8: FALSE | BK8: FALSE | BL8: FALSE | BM8: FALSE | BN8: FALSE | BO8: FALSE | BP8: FALSE | BR8: =IFERROR(IF(M8="PASSED",VLOOKUP(J8,Current!J11:BR71,1,FALSE)),N8) -> FALSE
A9: 46689 | C9: 0 | D9: None | E9: hth2-ipflex-hth2-cube1.hilltop.systems | F9: tcp | G9: 0 | H9: Cisco IOS Compliance Checks | I9: Compliance checks for Cisco IOS devices. | J9: =MID($N9,FIND("1.",$N9),FIND("-",$N9)-FIND("1.",$N9)-1) -> 1.0031 | K9: =MID($N9,FIND("NETIOS - ",$N9)+8,FIND(":",$N9,40)-FIND("NETIOS - ",$N9)-8) -> Set 'transport input none' for 'line aux 0 | L9: =MID($N9,FIND("1.",$N9),FIND("[",$N9)-1-FIND("1.",$N9)-1) -> 1.0031 - NETIOS - Set 'transport input none' for 'line aux 0 | M9: =MID($N9,FIND("[",$N9)+1,FIND("]",$N9)-FIND("[",$N9)-1) -> PASSED | N9: "1.0031 - NETIOS - Set 'transport input none' for 'line aux 0: [PASSED]" When you want to allow only an outgoing connection on a line, use the no exec command. See Also: See HTH Policies and Standards Reference: NIST 800-53r5|AC-2(5) AC-11 AC-11(1) AC-12 Policy Value: CONFIG_CHECK_NOT item: transport input (all|ssh|telnet)$ context: line aux .+ Actual Value: line aux 0 no exec Expected configuration: transport input (all|ssh|telnet)$ | O9: N/A | R9: 549e7be8-1405-4274-a37c-56853449b396 | T9: 10.2.166.4 | U9: hth2-ipflex-hth2-cube1.hilltop.systems | X9: A4:6C:2A:B4:73:81 A4:6C:2A:B4:73:82 A4:6C:2A:B4:73:80 | Y9: Policy Compliance | Z9: 0 | AA9: 0 | AD9: 0 | AE9: 0 | AI9: 2026-04-20T14:36:10.744Z | AJ9: 2026-04-20T14:42:23.901Z | AK9: null | AN9: template-80295fee-c9f5-bb4f-0422-3f46012f5e2bba99a3058425a248 | AO9: dda80223-7230-4f84-93c3-cc2b0802dfe9 | AP9: 2026-04-20T14:45:52.585Z | AQ9: 2026-04-20T14:42:12Z | AS9: TRUE | AT9: None | AU9: 0 | AV9: 0 | AX9: 39 | AY9: local | AZ9: $Revision: 1.887 $ | BB9: 2026-04-16T00:00:00Z | BC9: 2010-05-17T00:00:00Z | BD9: FALSE | BE9: FALSE | BF9: FALSE | BG9: FALSE | BH9: FALSE | BI9: FALSE | BJ9: FALSE | BK9: FALSE | BL9: FALSE | BM9: FALSE | BN9: FALSE | BO9: FALSE | BP9: FALSE | BR9: =IFERROR(IF(M9="PASSED",VLOOKUP(J9,Current!J13:BR73,1,FALSE)),N9) -> "1.0031 - NETIOS - Set 'transport input none' for 'line aux 0: [PASSED]" When you want to allow only an outgoing connection on a line, use the no exec command. See Also: See HTH Policies and Standards Reference: NIST 800-53r5|AC-2(5) AC-11 AC-11(1) AC-12 Policy Value: CONFIG_CHECK_NOT item: transport input (all|ssh|telnet)$ context: line aux .+ Actual Value: line aux 0 no exec Expected configuration: transport input (all|ssh|telnet)$
A10: 46689 | C10: 0 | D10: High | E10: hth2-ipflex-hth2-cube1.hilltop.systems | F10: tcp | G10: 0 | H10: Cisco IOS Compliance Checks | I10: Compliance checks for Cisco IOS devices. | J10: =MID($N10,FIND("1.",$N10),FIND("-",$N10)-FIND("1.",$N10)-1) -> 1.0032 | K10: =MID($N10,FIND("NETIOS - ",$N10)+8,FIND(":",$N10,40)-FIND("NETIOS - ",$N10)-8) -> Set the 'banner-text' for 'banner exec | L10: =MID($N10,FIND("1.",$N10),FIND("[",$N10)-1-FIND("1.",$N10)-1) -> 1.0032 - NETIOS - Set the 'banner-text' for 'banner exec | M10: =MID($N10,FIND("[",$N10)+1,FIND("]",$N10)-FIND("[",$N10)-1) -> FAILED | N10: "1.0032 - NETIOS - Set the 'banner-text' for 'banner exec: [FAILED]" This command specifies a message to be displayed when an EXEC process is created (a line is activated, or an incoming connection is made to a vty). See Also: See HTH Policies and Standards Reference: NIST 800-53r5|AT-1 AT-2 PM-13 Policy Value: BANNER_CHECK item: banner exec content: All unauthorized activity is monitored and logged. Actual Value: banner exec not found in the configuration file | O10: N/A | R10: 549e7be8-1405-4274-a37c-56853449b396 | T10: 10.2.166.4 | U10: hth2-ipflex-hth2-cube1.hilltop.systems | X10: A4:6C:2A:B4:73:81 A4:6C:2A:B4:73:82 A4:6C:2A:B4:73:80 | Y10: Policy Compliance | Z10: 0 | AA10: 0 | AD10: 0 | AE10: 0 | AI10: 2026-04-20T14:36:10.744Z | AJ10: 2026-04-20T14:42:23.901Z | AK10: null | AN10: template-80295fee-c9f5-bb4f-0422-3f46012f5e2bba99a3058425a248 | AO10: dda80223-7230-4f84-93c3-cc2b0802dfe9 | AP10: 2026-04-20T14:45:52.582Z | AQ10: 2026-04-20T14:42:12Z | AS10: TRUE | AT10: None | AU10: 0 | AV10: 0 | AX10: 39 | AY10: local | AZ10: $Revision: 1.887 $ | BB10: 2026-04-16T00:00:00Z | BC10: 2010-05-17T00:00:00Z | BD10: FALSE | BE10: FALSE | BF10: FALSE | BG10: FALSE | BH10: FALSE | BI10: FALSE | BJ10: FALSE | BK10: FALSE | BL10: FALSE | BM10: FALSE | BN10: FALSE | BO10: FALSE | BP10: FALSE | BR10: =IFERROR(IF(M10="PASSED",VLOOKUP(J10,Current!J15:BR75,1,FALSE)),N10) -> FALSE
A11: 46689 | C11: 0 | D11: High | E11: hth2-ipflex-hth2-cube1.hilltop.systems | F11: tcp | G11: 0 | H11: Cisco IOS Compliance Checks | I11: Compliance checks for Cisco IOS devices. | J11: =MID($N11,FIND("1.",$N11),FIND("-",$N11)-FIND("1.",$N11)-1) -> 1.0033 | K11: =MID($N11,FIND("NETIOS - ",$N11)+8,FIND(":",$N11,40)-FIND("NETIOS - ",$N11)-8) -> Set the 'banner-text' for 'banner login | L11: =MID($N11,FIND("1.",$N11),FIND("[",$N11)-1-FIND("1.",$N11)-1) -> 1.0033 - NETIOS - Set the 'banner-text' for 'banner login | M11: =MID($N11,FIND("[",$N11)+1,FIND("]",$N11)-FIND("[",$N11)-1) -> FAILED | N11: "1.0033 - NETIOS - Set the 'banner-text' for 'banner login: [FAILED]" Follow the banner login command with one or more blank spaces and a delimiting character of your choice. See Also: See HTH Policies and Standards Reference: NIST 800-53r5|AT-1 AT-2 PM-13 Policy Value: BANNER_CHECK item: banner login content: All unauthorized activity is monitored and logged. Actual Value: banner login not found in the configuration file | O11: N/A | R11: 549e7be8-1405-4274-a37c-56853449b396 | T11: 10.2.166.4 | U11: hth2-ipflex-hth2-cube1.hilltop.systems | X11: A4:6C:2A:B4:73:81 A4:6C:2A:B4:73:82 A4:6C:2A:B4:73:80 | Y11: Policy Compliance | Z11: 0 | AA11: 0 | AD11: 0 | AE11: 0 | AI11: 2026-04-20T14:36:10.744Z | AJ11: 2026-04-20T14:42:23.901Z | AK11: null | AN11: template-80295fee-c9f5-bb4f-0422-3f46012f5e2bba99a3058425a248 | AO11: dda80223-7230-4f84-93c3-cc2b0802dfe9 | AP11: 2026-04-20T14:45:52.591Z | AQ11: 2026-04-20T14:42:12Z | AS11: TRUE | AT11: None | AU11: 0 | AV11: 0 | AX11: 39 | AY11: local | AZ11: $Revision: 1.887 $ | BB11: 2026-04-16T00:00:00Z | BC11: 2010-05-17T00:00:00Z | BD11: FALSE | BE11: FALSE | BF11: FALSE | BG11: FALSE | BH11: FALSE | BI11: FALSE | BJ11: FALSE | BK11: FALSE | BL11: FALSE | BM11: FALSE | BN11: FALSE | BO11: FALSE | BP11: FALSE | BR11: =IFERROR(IF(M11="PASSED",VLOOKUP(J11,Current!J17:BR77,1,FALSE)),N11) -> FALSE
A12: 46689 | C12: 0 | D12: High | E12: hth2-ipflex-hth2-cube1.hilltop.systems | F12: tcp | G12: 0 | H12: Cisco IOS Compliance Checks | I12: Compliance checks for Cisco IOS devices. | J12: =MID($N12,FIND("1.",$N12),FIND("-",$N12)-FIND("1.",$N12)-1) -> 1.0034 | K12: =MID($N12,FIND("NETIOS - ",$N12)+8,FIND(":",$N12,40)-FIND("NETIOS - ",$N12)-8) -> Set the 'banner-text' for 'banner motd | L12: =MID($N12,FIND("1.",$N12),FIND("[",$N12)-1-FIND("1.",$N12)-1) -> 1.0034 - NETIOS - Set the 'banner-text' for 'banner motd | M12: =MID($N12,FIND("[",$N12)+1,FIND("]",$N12)-FIND("[",$N12)-1) -> FAILED | N12: "1.0034 - NETIOS - Set the 'banner-text' for 'banner motd: [FAILED]" This MOTD banner is displayed to all terminals connected and is useful for sending messages that affect all users (such as impending system shutdowns). See Also: See HTH Policies and Standards Reference: NIST 800-53r5|AT-1 AT-2 PM-13 Policy Value: BANNER_CHECK item: banner motd content: All unauthorized activity is monitored and logged. Actual Value: ___,,___ ,d8888888888b,_ _,d889' 8888b, _,d8888' 8888888b, _,d8889' 888888888888b,_ _,d8889' 888888889'688888, /b _,d8889' 88888889' `6888d 6,_ ,d88886' _d888889' ,8d b888b, d\ ,d889'888, d8889' 8d 9888888Y ) ,d889' `88, ,d88' d8 `,88aa88 9 d889' `88, ,88' `8b )88a88' d88' `88 ,88 88 `8b,_ d888888 d89 88, 88 d888b `88`_ 8888 88 88b 88 d888888 8: (6`) 88') 88 8888b, 88 d888aaa8888, ` 'Y' 88b ,888888888888 `d88aa `88888b ,d8 `88b ,88886 `88888888 d88a d8a88` `8/ `q8b ,88'`888 `888'"`88 d8b d8888,` 88/ 9)_6 88 ,88" `88 88p `88 d88888888888bd8( Z~/ 88b 8p 88 68' `88 88888888' `688889` `88 8 `8 8, `88 888 `8888, `qp' 8 8, `q 8b `88 88" `888b q8 8b "888 `8888' "888 `q88b "888' XXXXXXXXXXXXXXXXXXXXXXXXXXXXXXXXXXXXXXXXXXXXXXXXXXXXXXXXXXXXXXXXXXXXX XX !! WARNING !! XX XX Access to this system is restricted to authorized users. XX XX All users expressly consent to the monitoring and recording XX XX of all activity. System violations are subject to XX XX disciplinary action. Evidence of criminal activity may be XX XX reported to corporate security and local, state and federal XX XX law enforcement agencies. By using this system the user XX XX accepts these terms and conditions. XX XXXXXXXXXXXXXXXXXXXXXXXXXXXXXXXXXXXXXXXXXXXXXXXXXXXXXXXXXXXXXXXXXXXXX Expected configuration: banner motd First ERROR: ___,,___ ,d8888888888b,_ != All unauthorized | O12: N/A | R12: 549e7be8-1405-4274-a37c-56853449b396 | T12: 10.2.166.4 | U12: hth2-ipflex-hth2-cube1.hilltop.systems | X12: A4:6C:2A:B4:73:81 A4:6C:2A:B4:73:82 A4:6C:2A:B4:73:80 | Y12: Policy Compliance | Z12: 0 | AA12: 0 | AD12: 0 | AE12: 0 | AI12: 2026-04-20T14:36:10.744Z | AJ12: 2026-04-20T14:42:23.901Z | AK12: null | AN12: template-80295fee-c9f5-bb4f-0422-3f46012f5e2bba99a3058425a248 | AO12: dda80223-7230-4f84-93c3-cc2b0802dfe9 | AP12: 2026-04-20T14:45:52.579Z | AQ12: 2026-04-20T14:42:12Z | AS12: TRUE | AT12: None | AU12: 0 | AV12: 0 | AX12: 39 | AY12: local | AZ12: $Revision: 1.887 $ | BB12: 2026-04-16T00:00:00Z | BC12: 2010-05-17T00:00:00Z | BD12: FALSE | BE12: FALSE | BF12: FALSE | BG12: FALSE | BH12: FALSE | BI12: FALSE | BJ12: FALSE | BK12: FALSE | BL12: FALSE | BM12: FALSE | BN12: FALSE | BO12: FALSE | BP12: FALSE | BR12: =IFERROR(IF(M12="PASSED",VLOOKUP(J12,Current!J19:BR79,1,FALSE)),N12) -> FALSE
