Workbook

Sheet AUDIT FILE COMPARISON REPORT
A1: ===============================================================================
A2: AUDIT FILE COMPARISON REPORT
A3: Generated : 2026-04-20 13:54:41
A4: ===============================================================================
A6: SIMILAR ITEMS RELABELLED
A7: ===============================================================================
A10: 1.0181 - MSWRK - Ensure Allow Basic authentication is set to Disabled -> Added (Client)
A11: 1.0184 - MSWRK - Ensure Allow Basic authentication is set to Disabled -> Added (Service)
A13: 1.0182 - MSWRK - Ensure Allow unencrypted traffic is set to Disabled -> Added (Client)
A14: 1.0185 - MSWRK - Ensure Allow unencrypted traffic is set to Disabled -> Added (Service)
A16: 1.0206 - MSWRK - Ensure Configure SMB v1 client driver is set to Enabled: Disable driver (recommended) -> Added (Mrxsmb10)
A17: 1.0414 - MSWRK - Ensure Microsoft FTP Service (FTPSVC) is set to Disabled or Not Installed -> Added (Ftpsvc)
... A767: Key: None

Sheet Current
A1: Plugin ID | B1: CVE | C1: CVSS | D1: Risk | E1: Host | F1: Protocol | G1: Port | H1: Name | I1: Synopsis | J1: Item | K1: Short Description | L1: Audit Name | M1: Status | N1: Description | O1: Solution | P1: See Also | Q1: Plugin Output | R1: Asset UUID | S1: Vulnerability State | T1: IP Address | U1: FQDN | V1: NetBios | W1: OS | X1: MAC Address | Y1: Plugin Family | Z1: CVSS Base Score | AA1: CVSS Temporal Score | AB1: CVSS Temporal Vector | AC1: CVSS Vector | AD1: CVSS3 Base Score | AE1: CVSS3 Temporal Score | AF1: CVSS3 Temporal Vector | AG1: CVSS3 Vector | AH1: System Type | AI1: Host Start | AJ1: Host End | AK1: Vulnerability Priority Rating (VPR) | AL1: First Found | AM1: Last Found | AN1: Host Scan Schedule ID | AO1: Host Scan ID | AP1: Indexed At | AQ1: Last Authenticated Results Date | AR1: Last Unauthenticated Results Date | AS1: Tracked | AT1: Risk Factor | AU1: Severity | AV1: Original Severity | AW1: Modification | AX1: Plugin Family ID | AY1: Plugin Type | AZ1: Plugin Version | BA1: Service | BB1: Plugin Modification Date | BC1: Plugin Publication Date | BD1: Checks for Malware | BE1: Exploit Available | BF1: Exploited by Malware | BG1: Exploited by Nessus | BH1: CANVAS | BI1: D2 Elliot | BJ1: Metasploit | BK1: Core Exploits | BL1: ExploitHub | BM1: Default Account | BN1: Patch Available | BO1: In The News | BP1: Unsupported By Vendor | BQ1: Last Fixed
A2: 21156 | C2: 0 | D2: None | E2: hth4qvk6c4 | F2: tcp | G2: 0 | H2: Windows Compliance Checks | I2: Compliance checks for Windows systems. | J2: =MID($N2,FIND("1.",$N2),FIND("-",$N2)-FIND("1.",$N2)-1) -> 1.0001 | K2: =MID($N2,FIND("MSWRK - ",$N2)+8,FIND(":",$N2)-FIND("MSWRK - ",$N2)-8) -> Ensure Enforce password history is set to 24 or more password(s) | L2: =MID($N2,FIND("1.",$N2),FIND("[",$N2)-1-FIND("1.",$N2)-1) -> 1.0001 - MSWRK - Ensure Enforce password history is set to 24 or more password(s) | M2: =MID($N2,FIND("[",$N2)+1,FIND("]",$N2)-FIND("[",$N2)-1) -> PASSED | N2: "1.0001 - MSWRK - Ensure Enforce password history is set to 24 or more password(s): [PASSED]" This policy setting determines the number of renewed, unique passwords that have to be associated with a user account before you can reuse an old password. See Also: See HTH Policies and Standards Reference: NIST 800-53r5|IA-5(1) Policy Value: '24' Actual Value: '24' | O2: N/A | R2: 15f6a868-a423-46f6-9471-bbe28660b015 | T2: 10.9.228.37 | U2: hth4qvk6c4.hilltop.global | W2: Microsoft Windows 11 Enterprise Build 22631 | X2: AC:45:EF:8D:16:70 D4:A2:CD:F6:35:20 | Y2: Policy Compliance | Z2: 0 | AA2: 0 | AD2: 0 | AE2: 0 | AH2: general-purpose | AI2: 2026-04-19T01:36:07.747Z | AJ2: 2026-04-19T01:42:03.523Z | AK2: null | AN2: template-9cfb28cd-a1ba-2b6f-ef9e-f7691bc0a80b14766c032550e147 | AO2: e830cd7e-199f-49c4-bdd0-e3fe00351986 | AP2: 2026-04-19T01:44:05.106Z | AQ2: 2026-04-19T01:40:38Z | AS2: TRUE | AT2: None | AU2: 0 | AV2: 0 | AX2: 39 | AY2: local | AZ2: $Revision: 1.793 $ | BB2: 2026-04-15T00:00:00Z | BC2: 2007-11-21T00:00:00Z | BD2: FALSE | BE2: FALSE | BF2: FALSE | BG2: FALSE | BH2: FALSE | BI2: FALSE | BJ2: FALSE | BK2: FALSE | BL2: FALSE | BM2: FALSE | BN2: FALSE | BO2: FALSE | BP2: FALSE | BR2: =IF(M2="PASSED",VLOOKUP(J2,All_Potential!$J$1:$N$500,1,FALSE)) -> 1.0001
A3: 21156 | C3: 0 | D3: None | E3: hth4qvk6c4 | F3: tcp | G3: 0 | H3: Windows Compliance Checks | I3: Compliance checks for Windows systems. | J3: =MID($N3,FIND("1.",$N3),FIND("-",$N3)-FIND("1.",$N3)-1) -> 1.0002 | K3: =MID($N3,FIND("MSWRK - ",$N3)+8,FIND(":",$N3)-FIND("MSWRK - ",$N3)-8) -> Ensure Maximum password age is set to 365 or fewer days, but not 0 | L3: =MID($N3,FIND("1.",$N3),FIND("[",$N3)-1-FIND("1.",$N3)-1) -> 1.0002 - MSWRK - Ensure Maximum password age is set to 365 or fewer days, but not 0 | M3: =MID($N3,FIND("[",$N3)+1,FIND("]",$N3)-FIND("[",$N3)-1) -> PASSED | N3: "1.0002 - MSWRK - Ensure Maximum password age is set to 365 or fewer days, but not 0: [PASSED]" This policy setting defines how long a user can use their password before it expires. See Also: See HTH Policies and Standards Reference: NIST 800-53r5|IA-5(1) Policy Value: '60' Actual Value: '60' | O3: N/A | R3: 15f6a868-a423-46f6-9471-bbe28660b015 | T3: 10.9.228.37 | U3: hth4qvk6c4.hilltop.global | W3: Microsoft Windows 11 Enterprise Build 22631 | X3: AC:45:EF:8D:16:70 D4:A2:CD:F6:35:20 | Y3: Policy Compliance | Z3: 0 | AA3: 0 | AD3: 0 | AE3: 0 | AH3: general-purpose | AI3: 2026-04-19T01:36:07.747Z | AJ3: 2026-04-19T01:42:03.523Z | AK3: null | AN3: template-9cfb28cd-a1ba-2b6f-ef9e-f7691bc0a80b14766c032550e147 | AO3: e830cd7e-199f-49c4-bdd0-e3fe00351986 | AP3: 2026-04-19T01:44:05.136Z | AQ3: 2026-04-19T01:40:38Z | AS3: TRUE | AT3: None | AU3: 0 | AV3: 0 | AX3: 39 | AY3: local | AZ3: $Revision: 1.793 $ | BB3: 2026-04-15T00:00:00Z | BC3: 2007-11-21T00:00:00Z | BD3: FALSE | BE3: FALSE | BF3: FALSE | BG3: FALSE | BH3: FALSE | BI3: FALSE | BJ3: FALSE | BK3: FALSE | BL3: FALSE | BM3: FALSE | BN3: FALSE | BO3: FALSE | BP3: FALSE | BR3: =IF(M3="PASSED",VLOOKUP(J3,All_Potential!$J$1:$N$500,1,FALSE)) -> 1.0002
A4: 21156 | C4: 0 | D4: None | E4: hth4qvk6c4 | F4: tcp | G4: 0 | H4: Windows Compliance Checks | I4: Compliance checks for Windows systems. | J4: =MID($N4,FIND("1.",$N4),FIND("-",$N4)-FIND("1.",$N4)-1) -> 1.0003 | K4: =MID($N4,FIND("MSWRK - ",$N4)+8,FIND(":",$N4)-FIND("MSWRK - ",$N4)-8) -> Ensure Minimum password age is set to 1 or more day(s) | L4: =MID($N4,FIND("1.",$N4),FIND("[",$N4)-1-FIND("1.",$N4)-1) -> 1.0003 - MSWRK - Ensure Minimum password age is set to 1 or more day(s) | M4: =MID($N4,FIND("[",$N4)+1,FIND("]",$N4)-FIND("[",$N4)-1) -> PASSED | N4: "1.0003 - MSWRK - Ensure Minimum password age is set to 1 or more day(s): [PASSED]" This policy setting determines the number of days that you must use a password before you can change it. See Also: See HTH Policies and Standards Reference: NIST 800-53r5|IA-5(1) Policy Value: '1' Actual Value: '1' | O4: N/A | R4: 15f6a868-a423-46f6-9471-bbe28660b015 | T4: 10.9.228.37 | U4: hth4qvk6c4.hilltop.global | W4: Microsoft Windows 11 Enterprise Build 22631 | X4: AC:45:EF:8D:16:70 D4:A2:CD:F6:35:20 | Y4: Policy Compliance | Z4: 0 | AA4: 0 | AD4: 0 | AE4: 0 | AH4: general-purpose | AI4: 2026-04-19T01:36:07.747Z | AJ4: 2026-04-19T01:42:03.523Z | AK4: null | AN4: template-9cfb28cd-a1ba-2b6f-ef9e-f7691bc0a80b14766c032550e147 | AO4: e830cd7e-199f-49c4-bdd0-e3fe00351986 | AP4: 2026-04-19T01:44:05.080Z | AQ4: 2026-04-19T01:40:38Z | AS4: TRUE | AT4: None | AU4: 0 | AV4: 0 | AX4: 39 | AY4: local | AZ4: $Revision: 1.793 $ | BB4: 2026-04-15T00:00:00Z | BC4: 2007-11-21T00:00:00Z | BD4: FALSE | BE4: FALSE | BF4: FALSE | BG4: FALSE | BH4: FALSE | BI4: FALSE | BJ4: FALSE | BK4: FALSE | BL4: FALSE | BM4: FALSE | BN4: FALSE | BO4: FALSE | BP4: FALSE | BR4: =IF(M4="PASSED",VLOOKUP(J4,All_Potential!$J$1:$N$500,1,FALSE)) -> 1.0003
A5: 21156 | C5: 0 | D5: None | E5: hth4qvk6c4 | F5: tcp | G5: 0 | H5: Windows Compliance Checks | I5: Compliance checks for Windows systems. | J5: =MID($N5,FIND("1.",$N5),FIND("-",$N5)-FIND("1.",$N5)-1) -> 1.0004 | K5: =MID($N5,FIND("MSWRK - ",$N5)+8,FIND(":",$N5)-FIND("MSWRK - ",$N5)-8) -> Ensure Minimum password length is set to 14 or more character(s) | L5: =MID($N5,FIND("1.",$N5),FIND("[",$N5)-1-FIND("1.",$N5)-1) -> 1.0004 - MSWRK - Ensure Minimum password length is set to 14 or more character(s) | M5: =MID($N5,FIND("[",$N5)+1,FIND("]",$N5)-FIND("[",$N5)-1) -> PASSED | N5: "1.0004 - MSWRK - Ensure Minimum password length is set to 14 or more character(s): [PASSED]" This policy setting determines the least number of characters that make up a password for a user account. See Also: See HTH Policies and Standards Reference: NIST 800-53r5|IA-5(1) Policy Value: '^(8|9|10|11|12|13|14|15|16|17|18|19|20)$' Actual Value: '8' | O5: N/A | R5: 15f6a868-a423-46f6-9471-bbe28660b015 | T5: 10.9.228.37 | U5: hth4qvk6c4.hilltop.global | W5: Microsoft Windows 11 Enterprise Build 22631 | X5: AC:45:EF:8D:16:70 D4:A2:CD:F6:35:20 | Y5: Policy Compliance | Z5: 0 | AA5: 0 | AD5: 0 | AE5: 0 | AH5: general-purpose | AI5: 2026-04-19T01:36:07.747Z | AJ5: 2026-04-19T01:42:03.523Z | AK5: null | AN5: template-9cfb28cd-a1ba-2b6f-ef9e-f7691bc0a80b14766c032550e147 | AO5: e830cd7e-199f-49c4-bdd0-e3fe00351986 | AP5: 2026-04-19T01:44:05.106Z | AQ5: 2026-04-19T01:40:38Z | AS5: TRUE | AT5: None | AU5: 0 | AV5: 0 | AX5: 39 | AY5: local | AZ5: $Revision: 1.793 $ | BB5: 2026-04-15T00:00:00Z | BC5: 2007-11-21T00:00:00Z | BD5: FALSE | BE5: FALSE | BF5: FALSE | BG5: FALSE | BH5: FALSE | BI5: FALSE | BJ5: FALSE | BK5: FALSE | BL5: FALSE | BM5: FALSE | BN5: FALSE | BO5: FALSE | BP5: FALSE | BR5: =IF(M5="PASSED",VLOOKUP(J5,All_Potential!$J$1:$N$500,1,FALSE)) -> 1.0004
A6: 21156 | C6: 0 | D6: None | E6: hth4qvk6c4 | F6: tcp | G6: 0 | H6: Windows Compliance Checks | I6: Compliance checks for Windows systems. | J6: =MID($N6,FIND("1.",$N6),FIND("-",$N6)-FIND("1.",$N6)-1) -> 1.0005 | K6: =MID($N6,FIND("MSWRK - ",$N6)+8,FIND(":",$N6)-FIND("MSWRK - ",$N6)-8) -> Ensure Password must meet complexity requirements is set to Enabled | L6: =MID($N6,FIND("1.",$N6),FIND("[",$N6)-1-FIND("1.",$N6)-1) -> 1.0005 - MSWRK - Ensure Password must meet complexity requirements is set to Enabled | M6: =MID($N6,FIND("[",$N6)+1,FIND("]",$N6)-FIND("[",$N6)-1) -> PASSED | N6: "1.0005 - MSWRK - Ensure Password must meet complexity requirements is set to Enabled: [PASSED]" This policy setting checks all new passwords to ensure that they meet basic requirements for strong passwords. See Also: See HTH Policies and Standards Reference: NIST 800-53r5|IA-5(1) Policy Value: 'Enabled' Actual Value: 'Enabled' | O6: N/A | R6: 15f6a868-a423-46f6-9471-bbe28660b015 | T6: 10.9.228.37 | U6: hth4qvk6c4.hilltop.global | W6: Microsoft Windows 11 Enterprise Build 22631 | X6: AC:45:EF:8D:16:70 D4:A2:CD:F6:35:20 | Y6: Policy Compliance | Z6: 0 | AA6: 0 | AD6: 0 | AE6: 0 | AH6: general-purpose | AI6: 2026-04-19T01:36:07.747Z | AJ6: 2026-04-19T01:42:03.523Z | AK6: null | AN6: template-9cfb28cd-a1ba-2b6f-ef9e-f7691bc0a80b14766c032550e147 | AO6: e830cd7e-199f-49c4-bdd0-e3fe00351986 | AP6: 2026-04-19T01:44:05.117Z | AQ6: 2026-04-19T01:40:38Z | AS6: TRUE | AT6: None | AU6: 0 | AV6: 0 | AX6: 39 | AY6: local | AZ6: $Revision: 1.793 $ | BB6: 2026-04-15T00:00:00Z | BC6: 2007-11-21T00:00:00Z | BD6: FALSE | BE6: FALSE | BF6: FALSE | BG6: FALSE | BH6: FALSE | BI6: FALSE | BJ6: FALSE | BK6: FALSE | BL6: FALSE | BM6: FALSE | BN6: FALSE | BO6: FALSE | BP6: FALSE | BR6: =IF(M6="PASSED",VLOOKUP(J6,All_Potential!$J$1:$N$500,1,FALSE)) -> 1.0005
A7: 21156 | C7: 0 | D7: None | E7: hth4qvk6c4 | F7: tcp | G7: 0 | H7: Windows Compliance Checks | I7: Compliance checks for Windows systems. | J7: =MID($N7,FIND("1.",$N7),FIND("-",$N7)-FIND("1.",$N7)-1) -> 1.0007 | K7: =MID($N7,FIND("MSWRK - ",$N7)+8,FIND(":",$N7)-FIND("MSWRK - ",$N7)-8) -> Ensure Store passwords using reversible encryption is set to Disabled | L7: =MID($N7,FIND("1.",$N7),FIND("[",$N7)-1-FIND("1.",$N7)-1) -> 1.0007 - MSWRK - Ensure Store passwords using reversible encryption is set to Disabled | M7: =MID($N7,FIND("[",$N7)+1,FIND("]",$N7)-FIND("[",$N7)-1) -> PASSED | N7: "1.0007 - MSWRK - Ensure Store passwords using reversible encryption is set to Disabled: [PASSED]" This policy setting determines whether the operating system stores passwords in a way that uses reversible encryption, which provides support for application protocols that require knowledge of the user's password for authentication purposes. See Also: See HTH Policies and Standards Reference: NIST 800-53r5|IA-5(1) SC-28 SC-28(1) Policy Value: 'Disabled' Actual Value: 'Disabled' | O7: N/A | R7: 15f6a868-a423-46f6-9471-bbe28660b015 | T7: 10.9.228.37 | U7: hth4qvk6c4.hilltop.global | W7: Microsoft Windows 11 Enterprise Build 22631 | X7: AC:45:EF:8D:16:70 D4:A2:CD:F6:35:20 | Y7: Policy Compliance | Z7: 0 | AA7: 0 | AD7: 0 | AE7: 0 | AH7: general-purpose | AI7: 2026-04-19T01:36:07.747Z | AJ7: 2026-04-19T01:42:03.523Z | AK7: null | AN7: template-9cfb28cd-a1ba-2b6f-ef9e-f7691bc0a80b14766c032550e147 | AO7: e830cd7e-199f-49c4-bdd0-e3fe00351986 | AP7: 2026-04-19T01:44:05.126Z | AQ7: 2026-04-19T01:40:38Z | AS7: TRUE | AT7: None | AU7: 0 | AV7: 0 | AX7: 39 | AY7: local | AZ7: $Revision: 1.793 $ | BB7: 2026-04-15T00:00:00Z | BC7: 2007-11-21T00:00:00Z | BD7: FALSE | BE7: FALSE | BF7: FALSE | BG7: FALSE | BH7: FALSE | BI7: FALSE | BJ7: FALSE | BK7: FALSE | BL7: FALSE | BM7: FALSE | BN7: FALSE | BO7: FALSE | BP7: FALSE | BR7: =IF(M7="PASSED",VLOOKUP(J7,All_Potential!$J$1:$N$500,1,FALSE)) -> 1.0007
A8: 21156 | C8: 0 | D8: None | E8: hth4qvk6c4 | F8: tcp | G8: 0 | H8: Windows Compliance Checks | I8: Compliance checks for Windows systems. | J8: =MID($N8,FIND("1.",$N8),FIND("-",$N8)-FIND("1.",$N8)-1) -> 1.0008 | K8: =MID($N8,FIND("MSWRK - ",$N8)+8,FIND(":",$N8)-FIND("MSWRK - ",$N8)-8) -> Ensure Account lockout duration is set to 15 or more minute(s) | L8: =MID($N8,FIND("1.",$N8),FIND("[",$N8)-1-FIND("1.",$N8)-1) -> 1.0008 - MSWRK - Ensure Account lockout duration is set to 15 or more minute(s) | M8: =MID($N8,FIND("[",$N8)+1,FIND("]",$N8)-FIND("[",$N8)-1) -> PASSED | N8: "1.0008 - MSWRK - Ensure Account lockout duration is set to 15 or more minute(s): [PASSED]" This policy setting determines the length of time that must pass before a locked account is unlocked and a user can try to log on again. See Also: See HTH Policies and Standards Reference: NIST 800-53r5|AC-7 AC-19 Policy Value: '^([1-9][0-9]{2,}|[2-9][0-9]{1}|1[5-9])$' Actual Value: '60' | O8: N/A | R8: 15f6a868-a423-46f6-9471-bbe28660b015 | T8: 10.9.228.37 | U8: hth4qvk6c4.hilltop.global | W8: Microsoft Windows 11 Enterprise Build 22631 | X8: AC:45:EF:8D:16:70 D4:A2:CD:F6:35:20 | Y8: Policy Compliance | Z8: 0 | AA8: 0 | AD8: 0 | AE8: 0 | AH8: general-purpose | AI8: 2026-04-19T01:36:07.747Z | AJ8: 2026-04-19T01:42:03.523Z | AK8: null | AN8: template-9cfb28cd-a1ba-2b6f-ef9e-f7691bc0a80b14766c032550e147 | AO8: e830cd7e-199f-49c4-bdd0-e3fe00351986 | AP8: 2026-04-19T01:44:05.119Z | AQ8: 2026-04-19T01:40:38Z | AS8: TRUE | AT8: None | AU8: 0 | AV8: 0 | AX8: 39 | AY8: local | AZ8: $Revision: 1.793 $ | BB8: 2026-04-15T00:00:00Z | BC8: 2007-11-21T00:00:00Z | BD8: FALSE | BE8: FALSE | BF8: FALSE | BG8: FALSE | BH8: FALSE | BI8: FALSE | BJ8: FALSE | BK8: FALSE | BL8: FALSE | BM8: FALSE | BN8: FALSE | BO8: FALSE | BP8: FALSE | BR8: =IF(M8="PASSED",VLOOKUP(J8,All_Potential!$J$1:$N$500,1,FALSE)) -> 1.0008
A9: 21156 | C9: 0 | D9: None | E9: hth4qvk6c4 | F9: tcp | G9: 0 | H9: Windows Compliance Checks | I9: Compliance checks for Windows systems. | J9: =MID($N9,FIND("1.",$N9),FIND("-",$N9)-FIND("1.",$N9)-1) -> 1.0009 | K9: =MID($N9,FIND("MSWRK - ",$N9)+8,FIND(":",$N9)-FIND("MSWRK - ",$N9)-8) -> Ensure Account lockout threshold is set to 5 or fewer invalid logon attempt(s), but not 0 | L9: =MID($N9,FIND("1.",$N9),FIND("[",$N9)-1-FIND("1.",$N9)-1) -> 1.0009 - MSWRK - Ensure Account lockout threshold is set to 5 or fewer invalid logon attempt(s), but not 0 | M9: =MID($N9,FIND("[",$N9)+1,FIND("]",$N9)-FIND("[",$N9)-1) -> PASSED | N9: "1.0009 - MSWRK - Ensure Account lockout threshold is set to 5 or fewer invalid logon attempt(s), but not 0: [PASSED]" This policy setting determines the number of failed logon attempts before the account is locked. See Also: See HTH Policies and Standards Reference: NIST 800-53r5|AC-7 AC-19 Policy Value: '^(1|2|3|4|5)$' Actual Value: '5' | O9: N/A | R9: 15f6a868-a423-46f6-9471-bbe28660b015 | T9: 10.9.228.37 | U9: hth4qvk6c4.hilltop.global | W9: Microsoft Windows 11 Enterprise Build 22631 | X9: AC:45:EF:8D:16:70 D4:A2:CD:F6:35:20 | Y9: Policy Compliance | Z9: 0 | AA9: 0 | AD9: 0 | AE9: 0 | AH9: general-purpose | AI9: 2026-04-19T01:36:07.747Z | AJ9: 2026-04-19T01:42:03.523Z | AK9: null | AN9: template-9cfb28cd-a1ba-2b6f-ef9e-f7691bc0a80b14766c032550e147 | AO9: e830cd7e-199f-49c4-bdd0-e3fe00351986 | AP9: 2026-04-19T01:44:05.116Z | AQ9: 2026-04-19T01:40:38Z | AS9: TRUE | AT9: None | AU9: 0 | AV9: 0 | AX9: 39 | AY9: local | AZ9: $Revision: 1.793 $ | BB9: 2026-04-15T00:00:00Z | BC9: 2007-11-21T00:00:00Z | BD9: FALSE | BE9: FALSE | BF9: FALSE | BG9: FALSE | BH9: FALSE | BI9: FALSE | BJ9: FALSE | BK9: FALSE | BL9: FALSE | BM9: FALSE | BN9: FALSE | BO9: FALSE | BP9: FALSE | BR9: =IF(M9="PASSED",VLOOKUP(J9,All_Potential!$J$1:$N$500,1,FALSE)) -> 1.0009
A10: 21156 | C10: 0 | D10: None | E10: hth4qvk6c4 | F10: tcp | G10: 0 | H10: Windows Compliance Checks | I10: Compliance checks for Windows systems. | J10: =MID($N10,FIND("1.",$N10),FIND("-",$N10)-FIND("1.",$N10)-1) -> 1.0010 | K10: =MID($N10,FIND("MSWRK - ",$N10)+8,FIND(":",$N10)-FIND("MSWRK - ",$N10)-8) -> Ensure Allow Administrator account lockout is set to Enabled | L10: =MID($N10,FIND("1.",$N10),FIND("[",$N10)-1-FIND("1.",$N10)-1) -> 1.0010 - MSWRK - Ensure Allow Administrator account lockout is set to Enabled | M10: =MID($N10,FIND("[",$N10)+1,FIND("]",$N10)-FIND("[",$N10)-1) -> PASSED | N10: "1.0010 - MSWRK - Ensure Allow Administrator account lockout is set to Enabled: [PASSED]" This policy setting determines whether the built-in Administrator account is subject to the following Account Lockout Policy settings: Account lockout duration, Account lockout threshold, and Reset account lockout counter. See Also: See HTH Policies and Standards Reference: NIST 800-53r5|AC-7 AC-19 Policy Value: 'Enabled' Actual Value: 'Enabled' | O10: N/A | R10: 15f6a868-a423-46f6-9471-bbe28660b015 | T10: 10.9.228.37 | U10: hth4qvk6c4.hilltop.global | W10: Microsoft Windows 11 Enterprise Build 22631 | X10: AC:45:EF:8D:16:70 D4:A2:CD:F6:35:20 | Y10: Policy Compliance | Z10: 0 | AA10: 0 | AD10: 0 | AE10: 0 | AH10: general-purpose | AI10: 2026-04-19T01:36:07.747Z | AJ10: 2026-04-19T01:42:03.523Z | AK10: null | AN10: template-9cfb28cd-a1ba-2b6f-ef9e-f7691bc0a80b14766c032550e147 | AO10: e830cd7e-199f-49c4-bdd0-e3fe00351986 | AP10: 2026-04-19T01:44:05.076Z | AQ10: 2026-04-19T01:40:38Z | AS10: TRUE | AT10: None | AU10: 0 | AV10: 0 | AX10: 39 | AY10: local | AZ10: $Revision: 1.793 $ | BB10: 2026-04-15T00:00:00Z | BC10: 2007-11-21T00:00:00Z | BD10: FALSE | BE10: FALSE | BF10: FALSE | BG10: FALSE | BH10: FALSE | BI10: FALSE | BJ10: FALSE | BK10: FALSE | BL10: FALSE | BM10: FALSE | BN10: FALSE | BO10: FALSE | BP10: FALSE | BR10: =IF(M10="PASSED",VLOOKUP(J10,All_Potential!$J$1:$N$500,1,FALSE)) -> 1.0010
A11: 21156 | C11: 0 | D11: None | E11: hth4qvk6c4 | F11: tcp | G11: 0 | H11: Windows Compliance Checks | I11: Compliance checks for Windows systems. | J11: =MID($N11,FIND("1.",$N11),FIND("-",$N11)-FIND("1.",$N11)-1) -> 1.0011 | K11: =MID($N11,FIND("MSWRK - ",$N11)+8,FIND(":",$N11)-FIND("MSWRK - ",$N11)-8) -> Ensure Reset account lockout counter after is set to 15 or more minute(s) | L11: =MID($N11,FIND("1.",$N11),FIND("[",$N11)-1-FIND("1.",$N11)-1) -> 1.0011 - MSWRK - Ensure Reset account lockout counter after is set to 15 or more minute(s) | M11: =MID($N11,FIND("[",$N11)+1,FIND("]",$N11)-FIND("[",$N11)-1) -> PASSED | N11: "1.0011 - MSWRK - Ensure Reset account lockout counter after is set to 15 or more minute(s): [PASSED]" This policy setting determines the length of time before the Account lockout threshold resets to zero. See Also: See HTH Policies and Standards Reference: NIST 800-53r5|AC-7 AC-19 Policy Value: '^([1-9][0-9]{2,}|[2-9][0-9]{1}|1[5-9])$' Actual Value: '60' | O11: N/A | R11: 15f6a868-a423-46f6-9471-bbe28660b015 | T11: 10.9.228.37 | U11: hth4qvk6c4.hilltop.global | W11: Microsoft Windows 11 Enterprise Build 22631 | X11: AC:45:EF:8D:16:70 D4:A2:CD:F6:35:20 | Y11: Policy Compliance | Z11: 0 | AA11: 0 | AD11: 0 | AE11: 0 | AH11: general-purpose | AI11: 2026-04-19T01:36:07.747Z | AJ11: 2026-04-19T01:42:03.523Z | AK11: null | AN11: template-9cfb28cd-a1ba-2b6f-ef9e-f7691bc0a80b14766c032550e147 | AO11: e830cd7e-199f-49c4-bdd0-e3fe00351986 | AP11: 2026-04-19T01:44:05.089Z | AQ11: 2026-04-19T01:40:38Z | AS11: TRUE | AT11: None | AU11: 0 | AV11: 0 | AX11: 39 | AY11: local | AZ11: $Revision: 1.793 $ | BB11: 2026-04-15T00:00:00Z | BC11: 2007-11-21T00:00:00Z | BD11: FALSE | BE11: FALSE | BF11: FALSE | BG11: FALSE | BH11: FALSE | BI11: FALSE | BJ11: FALSE | BK11: FALSE | BL11: FALSE | BM11: FALSE | BN11: FALSE | BO11: FALSE | BP11: FALSE | BR11: =IF(M11="PASSED",VLOOKUP(J11,All_Potential!$J$1:$N$500,1,FALSE)) -> 1.0011
A12: 21156 | C12: 0 | D12: None | E12: hth4qvk6c4 | F12: tcp | G12: 0 | H12: Windows Compliance Checks | I12: Compliance checks for Windows systems. | J12: =MID($N12,FIND("1.",$N12),FIND("-",$N12)-FIND("1.",$N12)-1) -> 1.0018 | K12: =MID($N12,FIND("MSWRK - ",$N12)+8,FIND(":",$N12)-FIND("MSWRK - ",$N12)-8) -> Ensure Audit Account Lockout is set to include Failure | L12: =MID($N12,FIND("1.",$N12),FIND("[",$N12)-1-FIND("1.",$N12)-1) -> 1.0018 - MSWRK - Ensure Audit Account Lockout is set to include Failure | M12: =MID($N12,FIND("[",$N12)+1,FIND("]",$N12)-FIND("[",$N12)-1) -> PASSED | N12: "1.0018 - MSWRK - Ensure Audit Account Lockout is set to include Failure: [PASSED]" This subcategory reports when a user's account is locked out as a result of too many failed logon attempts. See Also: See HTH Policies and Standards Reference: NIST 800-53r5|AU-3 AU-3(1) AU-7 AU-12 Policy Value: '^(Failure|Success\ and\ Failure)$' Actual Value: 'Success and Failure' | O12: N/A | R12: 15f6a868-a423-46f6-9471-bbe28660b015 | T12: 10.9.228.37 | U12: hth4qvk6c4.hilltop.global | W12: Microsoft Windows 11 Enterprise Build 22631 | X12: AC:45:EF:8D:16:70 D4:A2:CD:F6:35:20 | Y12: Policy Compliance | Z12: 0 | AA12: 0 | AD12: 0 | AE12: 0 | AH12: general-purpose | AI12: 2026-04-19T01:36:07.747Z | AJ12: 2026-04-19T01:42:03.523Z | AK12: null | AN12: template-9cfb28cd-a1ba-2b6f-ef9e-f7691bc0a80b14766c032550e147 | AO12: e830cd7e-199f-49c4-bdd0-e3fe00351986 | AP12: 2026-04-19T01:44:05.095Z | AQ12: 2026-04-19T01:40:38Z | AS12: TRUE | AT12: None | AU12: 0 | AV12: 0 | AX12: 39 | AY12: local | AZ12: $Revision: 1.793 $ | BB12: 2026-04-15T00:00:00Z | BC12: 2007-11-21T00:00:00Z | BD12: FALSE | BE12: FALSE | BF12: FALSE | BG12: FALSE | BH12: FALSE | BI12: FALSE | BJ12: FALSE | BK12: FALSE | BL12: FALSE | BM12: FALSE | BN12: FALSE | BO12: FALSE | BP12: FALSE | BR12: =IF(M12="PASSED",VLOOKUP(J12,All_Potential!$J$1:$N$500,1,FALSE)) -> 1.0018
A13: 21156 | C13: 0 | D13: None | E13: hth4qvk6c4 | F13: tcp | G13: 0 | H13: Windows Compliance Checks | I13: Compliance checks for Windows systems. | J13: =MID($N13,FIND("1.",$N13),FIND("-",$N13)-FIND("1.",$N13)-1) -> 1.0020 | K13: =MID($N13,FIND("MSWRK - ",$N13)+8,FIND(":",$N13)-FIND("MSWRK - ",$N13)-8) -> Ensure Audit Logoff is set to include Success | L13: =MID($N13,FIND("1.",$N13),FIND("[",$N13)-1-FIND("1.",$N13)-1) -> 1.0020 - MSWRK - Ensure Audit Logoff is set to include Success | M13: =MID($N13,FIND("[",$N13)+1,FIND("]",$N13)-FIND("[",$N13)-1) -> PASSED | N13: "1.0020 - MSWRK - Ensure Audit Logoff is set to include Success: [PASSED]" This subcategory reports when a user logs off from the system. See Also: See HTH Policies and Standards Reference: NIST 800-53r5|AU-3 AU-3(1) AU-7 AU-12 Policy Value: '^(Success|Success\ and\ Failure)$' Actual Value: 'Success' | O13: N/A | R13: 15f6a868-a423-46f6-9471-bbe28660b015 | T13: 10.9.228.37 | U13: hth4qvk6c4.hilltop.global | W13: Microsoft Windows 11 Enterprise Build 22631 | X13: AC:45:EF:8D:16:70 D4:A2:CD:F6:35:20 | Y13: Policy Compliance | Z13: 0 | AA13: 0 | AD13: 0 | AE13: 0 | AH13: general-purpose | AI13: 2026-04-19T01:36:07.747Z | AJ13: 2026-04-19T01:42:03.523Z | AK13: null | AN13: template-9cfb28cd-a1ba-2b6f-ef9e-f7691bc0a80b14766c032550e147 | AO13: e830cd7e-199f-49c4-bdd0-e3fe00351986 | AP13: 2026-04-19T01:44:05.099Z | AQ13: 2026-04-19T01:40:38Z | AS13: TRUE | AT13: None | AU13: 0 | AV13: 0 | AX13: 39 | AY13: local | AZ13: $Revision: 1.793 $ | BB13: 2026-04-15T00:00:00Z | BC13: 2007-11-21T00:00:00Z | BD13: FALSE | BE13: FALSE | BF13: FALSE | BG13: FALSE | BH13: FALSE | BI13: FALSE | BJ13: FALSE | BK13: FALSE | BL13: FALSE | BM13: FALSE | BN13: FALSE | BO13: FALSE | BP13: FALSE | BR13: =IF(M13="PASSED",VLOOKUP(J13,All_Potential!$J$1:$N$500,1,FALSE)) -> 1.0020
... A174: 21156 | C174: 0 | D174: High | E174: hth4qvk6c4 | F174: tcp | G174: 0 | H174: Windows Compliance Checks | I174: Compliance checks for Windows systems. | J174: =MID($N174,FIND("1.",$N174),FIND("-",$N174)-FIND("1.",$N174)-1) -> 1.0494 | K174: =MID($N174,FIND("MSWRK - ",$N174)+8,FIND(":",$N174)-FIND("MSWRK - ",$N174)-8) -> SMB v1 server is set to Disabled | L174: =MID($N174,FIND("1.",$N174),FIND("[",$N174)-1-FIND("1.",$N174)-1) -> 1.0494 - MSWRK - SMB v1 server is set to Disabled | M174: =MID($N174,FIND("[",$N174)+1,FIND("]",$N174)-FIND("[",$N174)-1) -> FAILED | N174: "1.0494 - MSWRK - SMB v1 server is set to Disabled: [FAILED]" This setting configures the server-side processing of the Server Message Block version 1 (SMBv1) protocol. See Also: See corresponding HTH Policy or Standard Reference: NIST 800-53r5|CM-6 CM-7 Policy Value: 'Disabled' Actual Value: 'RunspaceId Value _x000D_ ---------- ----- _x000D_ 9eb2b27c-6d6a-45f5-bbb9-05860a4eede8 Disabled' | O174: N/A | R174: 15f6a868-a423-46f6-9471-bbe28660b015 | T174: 10.9.228.37 | U174: hth4qvk6c4.hilltop.global | W174: Microsoft Windows 11 Enterprise Build 22631 | X174: AC:45:EF:8D:16:70 D4:A2:CD:F6:35:20 | Y174: Policy Compliance | Z174: 0 | AA174: 0 | AD174: 0 | AE174: 0 | AH174: general-purpose | AI174: 2026-04-19T01:36:07.747Z | AJ174: 2026-04-19T01:42:03.523Z | AK174: null | AN174: template-9cfb28cd-a1ba-2b6f-ef9e-f7691bc0a80b14766c032550e147 | AO174: e830cd7e-199f-49c4-bdd0-e3fe00351986 | AP174: 2026-04-19T01:44:05.108Z | AQ174: 2026-04-19T01:40:38Z | AS174: TRUE | AT174: None | AU174: 0 | AV174: 0 | AX174: 39 | AY174: local | AZ174: $Revision: 1.793 $ | BB174: 2026-04-15T00:00:00Z | BC174: 2007-11-21T00:00:00Z | BD174: FALSE | BE174: FALSE | BF174: FALSE | BG174: FALSE | BH174: FALSE | BI174: FALSE | BJ174: FALSE | BK174: FALSE | BL174: FALSE | BM174: FALSE | BN174: FALSE | BO174: FALSE | BP174: FALSE | BR174: =IF(M174="PASSED",VLOOKUP(J174,All_Potential!$J$1:$N$500,1,FALSE)) -> FALSE

Sheet All_Potential
A1: Plugin ID | B1: CVE | C1: CVSS | D1: Risk | E1: Host | F1: Protocol | G1: Port | H1: Name | I1: Synopsis | J1: Item | K1: Short Description | L1: Audit Name | M1: Status | N1: Description | O1: Solution | P1: See Also | Q1: Plugin Output | R1: Asset UUID | S1: Vulnerability State | T1: IP Address | U1: FQDN | V1: NetBios | W1: OS | X1: MAC Address | Y1: Plugin Family | Z1: CVSS Base Score | AA1: CVSS Temporal Score | AB1: CVSS Temporal Vector | AC1: CVSS Vector | AD1: CVSS3 Base Score | AE1: CVSS3 Temporal Score | AF1: CVSS3 Temporal Vector | AG1: CVSS3 Vector | AH1: System Type | AI1: Host Start | AJ1: Host End | AK1: Vulnerability Priority Rating (VPR) | AL1: First Found | AM1: Last Found | AN1: Host Scan Schedule ID | AO1: Host Scan ID | AP1: Indexed At | AQ1: Last Authenticated Results Date | AR1: Last Unauthenticated Results Date | AS1: Tracked | AT1: Risk Factor | AU1: Severity | AV1: Original Severity | AW1: Modification | AX1: Plugin Family ID | AY1: Plugin Type | AZ1: Plugin Version | BA1: Service | BB1: Plugin Modification Date | BC1: Plugin Publication Date | BD1: Checks for Malware | BE1: Exploit Available | BF1: Exploited by Malware | BG1: Exploited by Nessus | BH1: CANVAS | BI1: D2 Elliot | BJ1: Metasploit | BK1: Core Exploits | BL1: ExploitHub | BM1: Default Account | BN1: Patch Available | BO1: In The News | BP1: Unsupported By Vendor | BQ1: Last Fixed | BR1: Already Pass/Not Assessed
A2: 21156 | C2: 0 | D2: None | E2: hth4qvk6c4 | F2: tcp | G2: 0 | H2: Windows Compliance Checks | I2: Compliance checks for Windows systems. | J2: =MID($N2,FIND("1.",$N2),FIND("-",$N2)-FIND("1.",$N2)-1) -> 1.0001 | K2: =MID($N2,FIND("MSWRK - ",$N2)+8,FIND(":",$N2,40)-FIND("MSWRK - ",$N2)-8) -> Ensure Enforce password history is set to 24 or more password(s) | L2: =MID($N2,FIND("1.",$N2),FIND("[",$N2)-1-FIND("1.",$N2)-1) -> 1.0001 - MSWRK - Ensure Enforce password history is set to 24 or more password(s) | M2: =MID($N2,FIND("[",$N2)+1,FIND("]",$N2)-FIND("[",$N2)-1) -> PASSED | N2: "1.0001 - MSWRK - Ensure Enforce password history is set to 24 or more password(s): [PASSED]" This policy setting determines the number of renewed, unique passwords that have to be associated with a user account before you can reuse an old password. See Also: See HTH Policies and Standards Reference: NIST 800-53r5|IA-5(1) Policy Value: '24' Actual Value: '24' | O2: N/A | R2: 15f6a868-a423-46f6-9471-bbe28660b015 | T2: 10.9.228.37 | U2: hth4qvk6c4.hilltop.global | W2: Microsoft Windows 11 Enterprise Build 22631 | X2: AC:45:EF:8D:16:70 D4:A2:CD:F6:35:20 | Y2: Policy Compliance | Z2: 0 | AA2: 0 | AD2: 0 | AE2: 0 | AH2: general-purpose | AI2: 2026-04-19T01:21:54.036Z | AJ2: 2026-04-19T01:31:31.017Z | AK2: null | AN2: template-9cfb28cd-a1ba-2b6f-ef9e-f7691bc0a80b14766c032550e147 | AO2: c67919cb-fdfd-4f24-a332-e05d4b135763 | AP2: 2026-04-19T01:33:04.964Z | AQ2: 2026-04-19T01:30:12Z | AS2: TRUE | AT2: None | AU2: 0 | AV2: 0 | AX2: 39 | AY2: local | AZ2: $Revision: 1.793 $ | BB2: 2026-04-15T00:00:00Z | BC2: 2007-11-21T00:00:00Z | BD2: FALSE | BE2: FALSE | BF2: FALSE | BG2: FALSE | BH2: FALSE | BI2: FALSE | BJ2: FALSE | BK2: FALSE | BL2: FALSE | BM2: FALSE | BN2: FALSE | BO2: FALSE | BP2: FALSE | BR2: =IF(M2="PASSED",VLOOKUP(J2,Current!$J$1:$N$500,1,FALSE)) -> 1.0001
A3: 21156 | C3: 0 | D3: None | E3: hth4qvk6c4 | F3: tcp | G3: 0 | H3: Windows Compliance Checks | I3: Compliance checks for Windows systems. | J3: =MID($N3,FIND("1.",$N3),FIND("-",$N3)-FIND("1.",$N3)-1) -> 1.0002 | K3: =MID($N3,FIND("MSWRK - ",$N3)+8,FIND(":",$N3,40)-FIND("MSWRK - ",$N3)-8) -> Ensure Maximum password age is set to 365 or fewer days, but not 0 | L3: =MID($N3,FIND("1.",$N3),FIND("[",$N3)-1-FIND("1.",$N3)-1) -> 1.0002 - MSWRK - Ensure Maximum password age is set to 365 or fewer days, but not 0 | M3: =MID($N3,FIND("[",$N3)+1,FIND("]",$N3)-FIND("[",$N3)-1) -> PASSED | N3: "1.0002 - MSWRK - Ensure Maximum password age is set to 365 or fewer days, but not 0: [PASSED]" This policy setting defines how long a user can use their password before it expires. See Also: See HTH Policies and Standards Reference: NIST 800-53r5|IA-5(1) Policy Value: '60' Actual Value: '60' | O3: N/A | R3: 15f6a868-a423-46f6-9471-bbe28660b015 | T3: 10.9.228.37 | U3: hth4qvk6c4.hilltop.global | W3: Microsoft Windows 11 Enterprise Build 22631 | X3: AC:45:EF:8D:16:70 D4:A2:CD:F6:35:20 | Y3: Policy Compliance | Z3: 0 | AA3: 0 | AD3: 0 | AE3: 0 | AH3: general-purpose | AI3: 2026-04-19T01:21:54.036Z | AJ3: 2026-04-19T01:31:31.017Z | AK3: null | AN3: template-9cfb28cd-a1ba-2b6f-ef9e-f7691bc0a80b14766c032550e147 | AO3: c67919cb-fdfd-4f24-a332-e05d4b135763 | AP3: 2026-04-19T01:33:04.910Z | AQ3: 2026-04-19T01:30:12Z | AS3: TRUE | AT3: None | AU3: 0 | AV3: 0 | AX3: 39 | AY3: local | AZ3: $Revision: 1.793 $ | BB3: 2026-04-15T00:00:00Z | BC3: 2007-11-21T00:00:00Z | BD3: FALSE | BE3: FALSE | BF3: FALSE | BG3: FALSE | BH3: FALSE | BI3: FALSE | BJ3: FALSE | BK3: FALSE | BL3: FALSE | BM3: FALSE | BN3: FALSE | BO3: FALSE | BP3: FALSE | BR3: =IF(M3="PASSED",VLOOKUP(J3,Current!$J$1:$N$500,1,FALSE)) -> 1.0002
A4: 21156 | C4: 0 | D4: None | E4: hth4qvk6c4 | F4: tcp | G4: 0 | H4: Windows Compliance Checks | I4: Compliance checks for Windows systems. | J4: =MID($N4,FIND("1.",$N4),FIND("-",$N4)-FIND("1.",$N4)-1) -> 1.0003 | K4: =MID($N4,FIND("MSWRK - ",$N4)+8,FIND(":",$N4,40)-FIND("MSWRK - ",$N4)-8) -> Ensure Minimum password age is set to 1 or more day(s) | L4: =MID($N4,FIND("1.",$N4),FIND("[",$N4)-1-FIND("1.",$N4)-1) -> 1.0003 - MSWRK - Ensure Minimum password age is set to 1 or more day(s) | M4: =MID($N4,FIND("[",$N4)+1,FIND("]",$N4)-FIND("[",$N4)-1) -> PASSED | N4: "1.0003 - MSWRK - Ensure Minimum password age is set to 1 or more day(s): [PASSED]" This policy setting determines the number of days that you must use a password before you can change it. See Also: See HTH Policies and Standards Reference: NIST 800-53r5|IA-5(1) Policy Value: '1' Actual Value: '1' | O4: N/A | R4: 15f6a868-a423-46f6-9471-bbe28660b015 | T4: 10.9.228.37 | U4: hth4qvk6c4.hilltop.global | W4: Microsoft Windows 11 Enterprise Build 22631 | X4: AC:45:EF:8D:16:70 D4:A2:CD:F6:35:20 | Y4: Policy Compliance | Z4: 0 | AA4: 0 | AD4: 0 | AE4: 0 | AH4: general-purpose | AI4: 2026-04-19T01:21:54.036Z | AJ4: 2026-04-19T01:31:31.017Z | AK4: null | AN4: template-9cfb28cd-a1ba-2b6f-ef9e-f7691bc0a80b14766c032550e147 | AO4: c67919cb-fdfd-4f24-a332-e05d4b135763 | AP4: 2026-04-19T01:33:04.926Z | AQ4: 2026-04-19T01:30:12Z | AS4: TRUE | AT4: None | AU4: 0 | AV4: 0 | AX4: 39 | AY4: local | AZ4: $Revision: 1.793 $ | BB4: 2026-04-15T00:00:00Z | BC4: 2007-11-21T00:00:00Z | BD4: FALSE | BE4: FALSE | BF4: FALSE | BG4: FALSE | BH4: FALSE | BI4: FALSE | BJ4: FALSE | BK4: FALSE | BL4: FALSE | BM4: FALSE | BN4: FALSE | BO4: FALSE | BP4: FALSE | BR4: =IF(M4="PASSED",VLOOKUP(J4,Current!$J$1:$N$500,1,FALSE)) -> 1.0003
A5: 21156 | C5: 0 | D5: None | E5: hth4qvk6c4 | F5: tcp | G5: 0 | H5: Windows Compliance Checks | I5: Compliance checks for Windows systems. | J5: =MID($N5,FIND("1.",$N5),FIND("-",$N5)-FIND("1.",$N5)-1) -> 1.0004 | K5: =MID($N5,FIND("MSWRK - ",$N5)+8,FIND(":",$N5,40)-FIND("MSWRK - ",$N5)-8) -> Ensure Minimum password length is set to 14 or more character(s) | L5: =MID($N5,FIND("1.",$N5),FIND("[",$N5)-1-FIND("1.",$N5)-1) -> 1.0004 - MSWRK - Ensure Minimum password length is set to 14 or more character(s) | M5: =MID($N5,FIND("[",$N5)+1,FIND("]",$N5)-FIND("[",$N5)-1) -> PASSED | N5: "1.0004 - MSWRK - Ensure Minimum password length is set to 14 or more character(s): [PASSED]" This policy setting determines the least number of characters that make up a password for a user account. See Also: See HTH Policies and Standards Reference: NIST 800-53r5|IA-5(1) Policy Value: '^(8|9|10|11|12|13|14|15|16|17|18|19|20)$' Actual Value: '8' | O5: N/A | R5: 15f6a868-a423-46f6-9471-bbe28660b015 | T5: 10.9.228.37 | U5: hth4qvk6c4.hilltop.global | W5: Microsoft Windows 11 Enterprise Build 22631 | X5: AC:45:EF:8D:16:70 D4:A2:CD:F6:35:20 | Y5: Policy Compliance | Z5: 0 | AA5: 0 | AD5: 0 | AE5: 0 | AH5: general-purpose | AI5: 2026-04-19T01:21:54.036Z | AJ5: 2026-04-19T01:31:31.017Z | AK5: null | AN5: template-9cfb28cd-a1ba-2b6f-ef9e-f7691bc0a80b14766c032550e147 | AO5: c67919cb-fdfd-4f24-a332-e05d4b135763 | AP5: 2026-04-19T01:33:04.752Z | AQ5: 2026-04-19T01:30:12Z | AS5: TRUE | AT5: None | AU5: 0 | AV5: 0 | AX5: 39 | AY5: local | AZ5: $Revision: 1.793 $ | BB5: 2026-04-15T00:00:00Z | BC5: 2007-11-21T00:00:00Z | BD5: FALSE | BE5: FALSE | BF5: FALSE | BG5: FALSE | BH5: FALSE | BI5: FALSE | BJ5: FALSE | BK5: FALSE | BL5: FALSE | BM5: FALSE | BN5: FALSE | BO5: FALSE | BP5: FALSE | BR5: =IF(M5="PASSED",VLOOKUP(J5,Current!$J$1:$N$500,1,FALSE)) -> 1.0004
A6: 21156 | C6: 0 | D6: None | E6: hth4qvk6c4 | F6: tcp | G6: 0 | H6: Windows Compliance Checks | I6: Compliance checks for Windows systems. | J6: =MID($N6,FIND("1.",$N6),FIND("-",$N6)-FIND("1.",$N6)-1) -> 1.0005 | K6: =MID($N6,FIND("MSWRK - ",$N6)+8,FIND(":",$N6,40)-FIND("MSWRK - ",$N6)-8) -> Ensure Password must meet complexity requirements is set to Enabled | L6: =MID($N6,FIND("1.",$N6),FIND("[",$N6)-1-FIND("1.",$N6)-1) -> 1.0005 - MSWRK - Ensure Password must meet complexity requirements is set to Enabled | M6: =MID($N6,FIND("[",$N6)+1,FIND("]",$N6)-FIND("[",$N6)-1) -> PASSED | N6: "1.0005 - MSWRK - Ensure Password must meet complexity requirements is set to Enabled: [PASSED]" This policy setting checks all new passwords to ensure that they meet basic requirements for strong passwords. See Also: See HTH Policies and Standards Reference: NIST 800-53r5|IA-5(1) Policy Value: 'Enabled' Actual Value: 'Enabled' | O6: N/A | R6: 15f6a868-a423-46f6-9471-bbe28660b015 | T6: 10.9.228.37 | U6: hth4qvk6c4.hilltop.global | W6: Microsoft Windows 11 Enterprise Build 22631 | X6: AC:45:EF:8D:16:70 D4:A2:CD:F6:35:20 | Y6: Policy Compliance | Z6: 0 | AA6: 0 | AD6: 0 | AE6: 0 | AH6: general-purpose | AI6: 2026-04-19T01:21:54.036Z | AJ6: 2026-04-19T01:31:31.017Z | AK6: null | AN6: template-9cfb28cd-a1ba-2b6f-ef9e-f7691bc0a80b14766c032550e147 | AO6: c67919cb-fdfd-4f24-a332-e05d4b135763 | AP6: 2026-04-19T01:33:04.954Z | AQ6: 2026-04-19T01:30:12Z | AS6: TRUE | AT6: None | AU6: 0 | AV6: 0 | AX6: 39 | AY6: local | AZ6: $Revision: 1.793 $ | BB6: 2026-04-15T00:00:00Z | BC6: 2007-11-21T00:00:00Z | BD6: FALSE | BE6: FALSE | BF6: FALSE | BG6: FALSE | BH6: FALSE | BI6: FALSE | BJ6: FALSE | BK6: FALSE | BL6: FALSE | BM6: FALSE | BN6: FALSE | BO6: FALSE | BP6: FALSE | BR6: =IF(M6="PASSED",VLOOKUP(J6,Current!$J$1:$N$500,1,FALSE)) -> 1.0005
A7: 21156 | C7: 0 | D7: High | E7: hth4qvk6c4 | F7: tcp | G7: 0 | H7: Windows Compliance Checks | I7: Compliance checks for Windows systems. | J7: =MID($N7,FIND("1.",$N7),FIND("-",$N7)-FIND("1.",$N7)-1) -> 1.0006 | K7: =MID($N7,FIND("MSWRK - ",$N7)+8,FIND(":",$N7,40)-FIND("MSWRK - ",$N7)-8) -> Ensure Relax minimum password length limits is set to Enabled | L7: =MID($N7,FIND("1.",$N7),FIND("[",$N7)-1-FIND("1.",$N7)-1) -> 1.0006 - MSWRK - Ensure Relax minimum password length limits is set to Enabled | M7: =MID($N7,FIND("[",$N7)+1,FIND("]",$N7)-FIND("[",$N7)-1) -> FAILED | N7: "1.0006 - MSWRK - Ensure Relax minimum password length limits is set to Enabled: [FAILED]" This policy setting determines whether the minimum password length setting can be increased beyond the legacy limit of 14 characters. See Also: See HTH Policies and Standards Reference: NIST 800-53r5|IA-5(1) Policy Value: '1' Actual Value: '0' | O7: N/A | R7: 15f6a868-a423-46f6-9471-bbe28660b015 | T7: 10.9.228.37 | U7: hth4qvk6c4.hilltop.global | W7: Microsoft Windows 11 Enterprise Build 22631 | X7: AC:45:EF:8D:16:70 D4:A2:CD:F6:35:20 | Y7: Policy Compliance | Z7: 0 | AA7: 0 | AD7: 0 | AE7: 0 | AH7: general-purpose | AI7: 2026-04-19T01:21:54.036Z | AJ7: 2026-04-19T01:31:31.017Z | AK7: null | AN7: template-9cfb28cd-a1ba-2b6f-ef9e-f7691bc0a80b14766c032550e147 | AO7: c67919cb-fdfd-4f24-a332-e05d4b135763 | AP7: 2026-04-19T01:33:04.931Z | AQ7: 2026-04-19T01:30:12Z | AS7: TRUE | AT7: None | AU7: 0 | AV7: 0 | AX7: 39 | AY7: local | AZ7: $Revision: 1.793 $ | BB7: 2026-04-15T00:00:00Z | BC7: 2007-11-21T00:00:00Z | BD7: FALSE | BE7: FALSE | BF7: FALSE | BG7: FALSE | BH7: FALSE | BI7: FALSE | BJ7: FALSE | BK7: FALSE | BL7: FALSE | BM7: FALSE | BN7: FALSE | BO7: FALSE | BP7: FALSE | BR7: =IF(M7="PASSED",VLOOKUP(J7,Current!$J$1:$N$500,1,FALSE)) -> FALSE
A8: 21156 | C8: 0 | D8: None | E8: hth4qvk6c4 | F8: tcp | G8: 0 | H8: Windows Compliance Checks | I8: Compliance checks for Windows systems. | J8: =MID($N8,FIND("1.",$N8),FIND("-",$N8)-FIND("1.",$N8)-1) -> 1.0007 | K8: =MID($N8,FIND("MSWRK - ",$N8)+8,FIND(":",$N8,40)-FIND("MSWRK - ",$N8)-8) -> Ensure Store passwords using reversible encryption is set to Disabled | L8: =MID($N8,FIND("1.",$N8),FIND("[",$N8)-1-FIND("1.",$N8)-1) -> 1.0007 - MSWRK - Ensure Store passwords using reversible encryption is set to Disabled | M8: =MID($N8,FIND("[",$N8)+1,FIND("]",$N8)-FIND("[",$N8)-1) -> PASSED | N8: "1.0007 - MSWRK - Ensure Store passwords using reversible encryption is set to Disabled: [PASSED]" This policy setting determines whether the operating system stores passwords in a way that uses reversible encryption, which provides support for application protocols that require knowledge of the user's password for authentication purposes. See Also: See HTH Policies and Standards Reference: NIST 800-53r5|IA-5(1) SC-28 SC-28(1) Policy Value: 'Disabled' Actual Value: 'Disabled' | O8: N/A | R8: 15f6a868-a423-46f6-9471-bbe28660b015 | T8: 10.9.228.37 | U8: hth4qvk6c4.hilltop.global | W8: Microsoft Windows 11 Enterprise Build 22631 | X8: AC:45:EF:8D:16:70 D4:A2:CD:F6:35:20 | Y8: Policy Compliance | Z8: 0 | AA8: 0 | AD8: 0 | AE8: 0 | AH8: general-purpose | AI8: 2026-04-19T01:21:54.036Z | AJ8: 2026-04-19T01:31:31.017Z | AK8: null | AN8: template-9cfb28cd-a1ba-2b6f-ef9e-f7691bc0a80b14766c032550e147 | AO8: c67919cb-fdfd-4f24-a332-e05d4b135763 | AP8: 2026-04-19T01:33:04.692Z | AQ8: 2026-04-19T01:30:12Z | AS8: TRUE | AT8: None | AU8: 0 | AV8: 0 | AX8: 39 | AY8: local | AZ8: $Revision: 1.793 $ | BB8: 2026-04-15T00:00:00Z | BC8: 2007-11-21T00:00:00Z | BD8: FALSE | BE8: FALSE | BF8: FALSE | BG8: FALSE | BH8: FALSE | BI8: FALSE | BJ8: FALSE | BK8: FALSE | BL8: FALSE | BM8: FALSE | BN8: FALSE | BO8: FALSE | BP8: FALSE | BR8: =IFERROR(IF(M8="PASSED",VLOOKUP(J8,Current!$J$1:$N$500,1,FALSE)),N8) -> 1.0007
A9: 21156 | C9: 0 | D9: None | E9: hth4qvk6c4 | F9: tcp | G9: 0 | H9: Windows Compliance Checks | I9: Compliance checks for Windows systems. | J9: =MID($N9,FIND("1.",$N9),FIND("-",$N9)-FIND("1.",$N9)-1) -> 1.0008 | K9: =MID($N9,FIND("MSWRK - ",$N9)+8,FIND(":",$N9,40)-FIND("MSWRK - ",$N9)-8) -> Ensure Account lockout duration is set to 15 or more minute(s) | L9: =MID($N9,FIND("1.",$N9),FIND("[",$N9)-1-FIND("1.",$N9)-1) -> 1.0008 - MSWRK - Ensure Account lockout duration is set to 15 or more minute(s) | M9: =MID($N9,FIND("[",$N9)+1,FIND("]",$N9)-FIND("[",$N9)-1) -> PASSED | N9: "1.0008 - MSWRK - Ensure Account lockout duration is set to 15 or more minute(s): [PASSED]" This policy setting determines the length of time that must pass before a locked account is unlocked and a user can try to log on again. See Also: See HTH Policies and Standards Reference: NIST 800-53r5|AC-7 AC-19 Policy Value: '^([1-9][0-9]{2,}|[2-9][0-9]{1}|1[5-9])$' Actual Value: '60' | O9: N/A | R9: 15f6a868-a423-46f6-9471-bbe28660b015 | T9: 10.9.228.37 | U9: hth4qvk6c4.hilltop.global | W9: Microsoft Windows 11 Enterprise Build 22631 | X9: AC:45:EF:8D:16:70 D4:A2:CD:F6:35:20 | Y9: Policy Compliance | Z9: 0 | AA9: 0 | AD9: 0 | AE9: 0 | AH9: general-purpose | AI9: 2026-04-19T01:21:54.036Z | AJ9: 2026-04-19T01:31:31.017Z | AK9: null | AN9: template-9cfb28cd-a1ba-2b6f-ef9e-f7691bc0a80b14766c032550e147 | AO9: c67919cb-fdfd-4f24-a332-e05d4b135763 | AP9: 2026-04-19T01:33:04.681Z | AQ9: 2026-04-19T01:30:12Z | AS9: TRUE | AT9: None | AU9: 0 | AV9: 0 | AX9: 39 | AY9: local | AZ9: $Revision: 1.793 $ | BB9: 2026-04-15T00:00:00Z | BC9: 2007-11-21T00:00:00Z | BD9: FALSE | BE9: FALSE | BF9: FALSE | BG9: FALSE | BH9: FALSE | BI9: FALSE | BJ9: FALSE | BK9: FALSE | BL9: FALSE | BM9: FALSE | BN9: FALSE | BO9: FALSE | BP9: FALSE | BR9: =IFERROR(IF(M9="PASSED",VLOOKUP(J9,Current!$J$1:$N$500,1,FALSE)),N9) -> 1.0008
A10: 21156 | C10: 0 | D10: None | E10: hth4qvk6c4 | F10: tcp | G10: 0 | H10: Windows Compliance Checks | I10: Compliance checks for Windows systems. | J10: =MID($N10,FIND("1.",$N10),FIND("-",$N10)-FIND("1.",$N10)-1) -> 1.0009 | K10: =MID($N10,FIND("MSWRK - ",$N10)+8,FIND(":",$N10,40)-FIND("MSWRK - ",$N10)-8) -> Ensure Account lockout threshold is set to 5 or fewer invalid logon attempt(s), but not 0 | L10: =MID($N10,FIND("1.",$N10),FIND("[",$N10)-1-FIND("1.",$N10)-1) -> 1.0009 - MSWRK - Ensure Account lockout threshold is set to 5 or fewer invalid logon attempt(s), but not 0 | M10: =MID($N10,FIND("[",$N10)+1,FIND("]",$N10)-FIND("[",$N10)-1) -> PASSED | N10: "1.0009 - MSWRK - Ensure Account lockout threshold is set to 5 or fewer invalid logon attempt(s), but not 0: [PASSED]" This policy setting determines the number of failed logon attempts before the account is locked. See Also: See HTH Policies and Standards Reference: NIST 800-53r5|AC-7 AC-19 Policy Value: '^(1|2|3|4|5)$' Actual Value: '5' | O10: N/A | R10: 15f6a868-a423-46f6-9471-bbe28660b015 | T10: 10.9.228.37 | U10: hth4qvk6c4.hilltop.global | W10: Microsoft Windows 11 Enterprise Build 22631 | X10: AC:45:EF:8D:16:70 D4:A2:CD:F6:35:20 | Y10: Policy Compliance | Z10: 0 | AA10: 0 | AD10: 0 | AE10: 0 | AH10: general-purpose | AI10: 2026-04-19T01:21:54.036Z | AJ10: 2026-04-19T01:31:31.017Z | AK10: null | AN10: template-9cfb28cd-a1ba-2b6f-ef9e-f7691bc0a80b14766c032550e147 | AO10: c67919cb-fdfd-4f24-a332-e05d4b135763 | AP10: 2026-04-19T01:33:04.914Z | AQ10: 2026-04-19T01:30:12Z | AS10: TRUE | AT10: None | AU10: 0 | AV10: 0 | AX10: 39 | AY10: local | AZ10: $Revision: 1.793 $ | BB10: 2026-04-15T00:00:00Z | BC10: 2007-11-21T00:00:00Z | BD10: FALSE | BE10: FALSE | BF10: FALSE | BG10: FALSE | BH10: FALSE | BI10: FALSE | BJ10: FALSE | BK10: FALSE | BL10: FALSE | BM10: FALSE | BN10: FALSE | BO10: FALSE | BP10: FALSE | BR10: =IFERROR(IF(M10="PASSED",VLOOKUP(J10,Current!$J$1:$N$500,1,FALSE)),N10) -> 1.0009
A11: 21156 | C11: 0 | D11: None | E11: hth4qvk6c4 | F11: tcp | G11: 0 | H11: Windows Compliance Checks | I11: Compliance checks for Windows systems. | J11: =MID($N11,FIND("1.",$N11),FIND("-",$N11)-FIND("1.",$N11)-1) -> 1.0010 | K11: =MID($N11,FIND("MSWRK - ",$N11)+8,FIND(":",$N11,40)-FIND("MSWRK - ",$N11)-8) -> Ensure Allow Administrator account lockout is set to Enabled | L11: =MID($N11,FIND("1.",$N11),FIND("[",$N11)-1-FIND("1.",$N11)-1) -> 1.0010 - MSWRK - Ensure Allow Administrator account lockout is set to Enabled | M11: =MID($N11,FIND("[",$N11)+1,FIND("]",$N11)-FIND("[",$N11)-1) -> PASSED | N11: "1.0010 - MSWRK - Ensure Allow Administrator account lockout is set to Enabled: [PASSED]" This policy setting determines whether the built-in Administrator account is subject to the following Account Lockout Policy settings: Account lockout duration, Account lockout threshold, and Reset account lockout counter. See Also: See HTH Policies and Standards Reference: NIST 800-53r5|AC-7 AC-19 Policy Value: 'Enabled' Actual Value: 'Enabled' | O11: N/A | R11: 15f6a868-a423-46f6-9471-bbe28660b015 | T11: 10.9.228.37 | U11: hth4qvk6c4.hilltop.global | W11: Microsoft Windows 11 Enterprise Build 22631 | X11: AC:45:EF:8D:16:70 D4:A2:CD:F6:35:20 | Y11: Policy Compliance | Z11: 0 | AA11: 0 | AD11: 0 | AE11: 0 | AH11: general-purpose | AI11: 2026-04-19T01:21:54.036Z | AJ11: 2026-04-19T01:31:31.017Z | AK11: null | AN11: template-9cfb28cd-a1ba-2b6f-ef9e-f7691bc0a80b14766c032550e147 | AO11: c67919cb-fdfd-4f24-a332-e05d4b135763 | AP11: 2026-04-19T01:33:04.950Z | AQ11: 2026-04-19T01:30:12Z | AS11: TRUE | AT11: None | AU11: 0 | AV11: 0 | AX11: 39 | AY11: local | AZ11: $Revision: 1.793 $ | BB11: 2026-04-15T00:00:00Z | BC11: 2007-11-21T00:00:00Z | BD11: FALSE | BE11: FALSE | BF11: FALSE | BG11: FALSE | BH11: FALSE | BI11: FALSE | BJ11: FALSE | BK11: FALSE | BL11: FALSE | BM11: FALSE | BN11: FALSE | BO11: FALSE | BP11: FALSE | BR11: =IFERROR(IF(M11="PASSED",VLOOKUP(J11,Current!$J$1:$N$500,1,FALSE)),N11) -> 1.0010
A12: 21156 | C12: 0 | D12: None | E12: hth4qvk6c4 | F12: tcp | G12: 0 | H12: Windows Compliance Checks | I12: Compliance checks for Windows systems. | J12: =MID($N12,FIND("1.",$N12),FIND("-",$N12)-FIND("1.",$N12)-1) -> 1.0011 | K12: =MID($N12,FIND("MSWRK - ",$N12)+8,FIND(":",$N12,40)-FIND("MSWRK - ",$N12)-8) -> Ensure Reset account lockout counter after is set to 15 or more minute(s) | L12: =MID($N12,FIND("1.",$N12),FIND("[",$N12)-1-FIND("1.",$N12)-1) -> 1.0011 - MSWRK - Ensure Reset account lockout counter after is set to 15 or more minute(s) | M12: =MID($N12,FIND("[",$N12)+1,FIND("]",$N12)-FIND("[",$N12)-1) -> PASSED | N12: "1.0011 - MSWRK - Ensure Reset account lockout counter after is set to 15 or more minute(s): [PASSED]" This policy setting determines the length of time before the Account lockout threshold resets to zero. See Also: See HTH Policies and Standards Reference: NIST 800-53r5|AC-7 AC-19 Policy Value: '^([1-9][0-9]{2,}|[2-9][0-9]{1}|1[5-9])$' Actual Value: '60' | O12: N/A | R12: 15f6a868-a423-46f6-9471-bbe28660b015 | T12: 10.9.228.37 | U12: hth4qvk6c4.hilltop.global | W12: Microsoft Windows 11 Enterprise Build 22631 | X12: AC:45:EF:8D:16:70 D4:A2:CD:F6:35:20 | Y12: Policy Compliance | Z12: 0 | AA12: 0 | AD12: 0 | AE12: 0 | AH12: general-purpose | AI12: 2026-04-19T01:21:54.036Z | AJ12: 2026-04-19T01:31:31.017Z | AK12: null | AN12: template-9cfb28cd-a1ba-2b6f-ef9e-f7691bc0a80b14766c032550e147 | AO12: c67919cb-fdfd-4f24-a332-e05d4b135763 | AP12: 2026-04-19T01:33:04.954Z | AQ12: 2026-04-19T01:30:12Z | AS12: TRUE | AT12: None | AU12: 0 | AV12: 0 | AX12: 39 | AY12: local | AZ12: $Revision: 1.793 $ | BB12: 2026-04-15T00:00:00Z | BC12: 2007-11-21T00:00:00Z | BD12: FALSE | BE12: FALSE | BF12: FALSE | BG12: FALSE | BH12: FALSE | BI12: FALSE | BJ12: FALSE | BK12: FALSE | BL12: FALSE | BM12: FALSE | BN12: FALSE | BO12: FALSE | BP12: FALSE | BR12: =IFERROR(IF(M12="PASSED",VLOOKUP(J12,Current!$J$1:$N$500,1,FALSE)),N12) -> 1.0011
A13: 21156 | C13: 0 | D13: None | E13: hth4qvk6c4 | F13: tcp | G13: 0 | H13: Windows Compliance Checks | I13: Compliance checks for Windows systems. | J13: =MID($N13,FIND("1.",$N13),FIND("-",$N13)-FIND("1.",$N13)-1) -> 1.0012 | K13: =MID($N13,FIND("MSWRK - ",$N13)+8,FIND(":",$N13,40)-FIND("MSWRK - ",$N13)-8) -> Ensure Audit Credential Validation is set to Success and Failure | L13: =MID($N13,FIND("1.",$N13),FIND("[",$N13)-1-FIND("1.",$N13)-1) -> 1.0012 - MSWRK - Ensure Audit Credential Validation is set to Success and Failure | M13: =MID($N13,FIND("[",$N13)+1,FIND("]",$N13)-FIND("[",$N13)-1) -> PASSED | N13: "1.0012 - MSWRK - Ensure Audit Credential Validation is set to Success and Failure: [PASSED]" This subcategory reports the results of validation tests on credentials submitted for a user account logon request. See Also: See HTH Policies and Standards Reference: NIST 800-53r5|AU-3 AU-3(1) AU-7 AU-12 Policy Value: 'Success and Failure' Actual Value: 'Success and Failure' | O13: N/A | R13: 15f6a868-a423-46f6-9471-bbe28660b015 | T13: 10.9.228.37 | U13: hth4qvk6c4.hilltop.global | W13: Microsoft Windows 11 Enterprise Build 22631 | X13: AC:45:EF:8D:16:70 D4:A2:CD:F6:35:20 | Y13: Policy Compliance | Z13: 0 | AA13: 0 | AD13: 0 | AE13: 0 | AH13: general-purpose | AI13: 2026-04-19T01:21:54.036Z | AJ13: 2026-04-19T01:31:31.017Z | AK13: null | AN13: template-9cfb28cd-a1ba-2b6f-ef9e-f7691bc0a80b14766c032550e147 | AO13: c67919cb-fdfd-4f24-a332-e05d4b135763 | AP13: 2026-04-19T01:33:04.922Z | AQ13: 2026-04-19T01:30:12Z | AS13: TRUE | AT13: None | AU13: 0 | AV13: 0 | AX13: 39 | AY13: local | AZ13: $Revision: 1.793 $ | BB13: 2026-04-15T00:00:00Z | BC13: 2007-11-21T00:00:00Z | BD13: FALSE | BE13: FALSE | BF13: FALSE | BG13: FALSE | BH13: FALSE | BI13: FALSE | BJ13: FALSE | BK13: FALSE | BL13: FALSE | BM13: FALSE | BN13: FALSE | BO13: FALSE | BP13: FALSE | BR13: =IFERROR(IF(M13="PASSED",VLOOKUP(J13,Current!$J$1:$N$500,1,FALSE)),N13) -> "1.0012 - MSWRK - Ensure Audit Credential Validation is set to Success and Failure: [PASSED]" This subcategory reports the results of validation tests on credentials submitted for a user account logon request. See Also: See HTH Policies and Standards Reference: NIST 800-53r5|AU-3 AU-3(1) AU-7 AU-12 Policy Value: 'Success and Failure' Actual Value: 'Success and Failure'
A14: 21156 | C14: 0 | D14: None | E14: hth4qvk6c4 | F14: tcp | G14: 0 | H14: Windows Compliance Checks | I14: Compliance checks for Windows systems. | J14: =MID($N14,FIND("1.",$N14),FIND("-",$N14)-FIND("1.",$N14)-1) -> 1.0013 | K14: =MID($N14,FIND("MSWRK - ",$N14)+8,FIND(":",$N14,40)-FIND("MSWRK - ",$N14)-8) -> Ensure Audit Application Group Management is set to Success and Failure | L14: =MID($N14,FIND("1.",$N14),FIND("[",$N14)-1-FIND("1.",$N14)-1) -> 1.0013 - MSWRK - Ensure Audit Application Group Management is set to Success and Failure | M14: =MID($N14,FIND("[",$N14)+1,FIND("]",$N14)-FIND("[",$N14)-1) -> PASSED | N14: "1.0013 - MSWRK - Ensure Audit Application Group Management is set to Success and Failure: [PASSED]" This policy setting allows you to audit events generated by changes to application groups such as the following: - Application group is created, changed, or deleted. See Also: See HTH Policies and Standards Reference: NIST 800-53r5|AU-3 AU-3(1) AU-7 AU-12 Policy Value: 'Success and Failure' Actual Value: 'Success and Failure' | O14: N/A | R14: 15f6a868-a423-46f6-9471-bbe28660b015 | T14: 10.9.228.37 | U14: hth4qvk6c4.hilltop.global | W14: Microsoft Windows 11 Enterprise Build 22631 | X14: AC:45:EF:8D:16:70 D4:A2:CD:F6:35:20 | Y14: Policy Compliance | Z14: 0 | AA14: 0 | AD14: 0 | AE14: 0 | AH14: general-purpose | AI14: 2026-04-19T01:21:54.036Z | AJ14: 2026-04-19T01:31:31.017Z | AK14: null | AN14: template-9cfb28cd-a1ba-2b6f-ef9e-f7691bc0a80b14766c032550e147 | AO14: c67919cb-fdfd-4f24-a332-e05d4b135763 | AP14: 2026-04-19T01:33:04.689Z | AQ14: 2026-04-19T01:30:12Z | AS14: TRUE | AT14: None | AU14: 0 | AV14: 0 | AX14: 39 | AY14: local | AZ14: $Revision: 1.793 $ | BB14: 2026-04-15T00:00:00Z | BC14: 2007-11-21T00:00:00Z | BD14: FALSE | BE14: FALSE | BF14: FALSE | BG14: FALSE | BH14: FALSE | BI14: FALSE | BJ14: FALSE | BK14: FALSE | BL14: FALSE | BM14: FALSE | BN14: FALSE | BO14: FALSE | BP14: FALSE | BR14: =IFERROR(IF(M14="PASSED",VLOOKUP(J14,Current!$J$1:$N$500,1,FALSE)),N14) -> "1.0013 - MSWRK - Ensure Audit Application Group Management is set to Success and Failure: [PASSED]" This policy setting allows you to audit events generated by changes to application groups such as the following: - Application group is created, changed, or deleted. See Also: See HTH Policies and Standards Reference: NIST 800-53r5|AU-3 AU-3(1) AU-7 AU-12 Policy Value: 'Success and Failure' Actual Value: 'Success and Failure'
A15: 21156 | C15: 0 | D15: None | E15: hth4qvk6c4 | F15: tcp | G15: 0 | H15: Windows Compliance Checks | I15: Compliance checks for Windows systems. | J15: =MID($N15,FIND("1.",$N15),FIND("-",$N15)-FIND("1.",$N15)-1) -> 1.0014 | K15: =MID($N15,FIND("MSWRK - ",$N15)+8,FIND(":",$N15,40)-FIND("MSWRK - ",$N15)-8) -> Ensure Audit Security Group Management is set to include Success | L15: =MID($N15,FIND("1.",$N15),FIND("[",$N15)-1-FIND("1.",$N15)-1) -> 1.0014 - MSWRK - Ensure Audit Security Group Management is set to include Success | M15: =MID($N15,FIND("[",$N15)+1,FIND("]",$N15)-FIND("[",$N15)-1) -> PASSED | N15: "1.0014 - MSWRK - Ensure Audit Security Group Management is set to include Success: [PASSED]" This subcategory reports each event of security group management, such as when a security group is created, changed, or deleted or when a member is added to or removed from a security group. See Also: See HTH Policies and Standards Reference: NIST 800-53r5|AU-3 AU-3(1) AU-7 AU-12 Policy Value: '^(Success|Success\ and\ Failure)$' Actual Value: 'Success' | O15: N/A | R15: 15f6a868-a423-46f6-9471-bbe28660b015 | T15: 10.9.228.37 | U15: hth4qvk6c4.hilltop.global | W15: Microsoft Windows 11 Enterprise Build 22631 | X15: AC:45:EF:8D:16:70 D4:A2:CD:F6:35:20 | Y15: Policy Compliance | Z15: 0 | AA15: 0 | AD15: 0 | AE15: 0 | AH15: general-purpose | AI15: 2026-04-19T01:21:54.036Z | AJ15: 2026-04-19T01:31:31.017Z | AK15: null | AN15: template-9cfb28cd-a1ba-2b6f-ef9e-f7691bc0a80b14766c032550e147 | AO15: c67919cb-fdfd-4f24-a332-e05d4b135763 | AP15: 2026-04-19T01:33:04.924Z | AQ15: 2026-04-19T01:30:12Z | AS15: TRUE | AT15: None | AU15: 0 | AV15: 0 | AX15: 39 | AY15: local | AZ15: $Revision: 1.793 $ | BB15: 2026-04-15T00:00:00Z | BC15: 2007-11-21T00:00:00Z | BD15: FALSE | BE15: FALSE | BF15: FALSE | BG15: FALSE | BH15: FALSE | BI15: FALSE | BJ15: FALSE | BK15: FALSE | BL15: FALSE | BM15: FALSE | BN15: FALSE | BO15: FALSE | BP15: FALSE | BR15: =IFERROR(IF(M15="PASSED",VLOOKUP(J15,Current!$J$1:$N$500,1,FALSE)),N15) -> "1.0014 - MSWRK - Ensure Audit Security Group Management is set to include Success: [PASSED]" This subcategory reports each event of security group management, such as when a security group is created, changed, or deleted or when a member is added to or removed from a security group. See Also: See HTH Policies and Standards Reference: NIST 800-53r5|AU-3 AU-3(1) AU-7 AU-12 Policy Value: '^(Success|Success\ and\ Failure)$' Actual Value: 'Success'
A16: 21156 | C16: 0 | D16: None | E16: hth4qvk6c4 | F16: tcp | G16: 0 | H16: Windows Compliance Checks | I16: Compliance checks for Windows systems. | J16: =MID($N16,FIND("1.",$N16),FIND("-",$N16)-FIND("1.",$N16)-1) -> 1.0015 | K16: =MID($N16,FIND("MSWRK - ",$N16)+8,FIND(":",$N16,40)-FIND("MSWRK - ",$N16)-8) -> Ensure Audit User Account Management is set to Success and Failure | L16: =MID($N16,FIND("1.",$N16),FIND("[",$N16)-1-FIND("1.",$N16)-1) -> 1.0015 - MSWRK - Ensure Audit User Account Management is set to Success and Failure | M16: =MID($N16,FIND("[",$N16)+1,FIND("]",$N16)-FIND("[",$N16)-1) -> PASSED | N16: "1.0015 - MSWRK - Ensure Audit User Account Management is set to Success and Failure: [PASSED]" This subcategory reports each event of user account management, such as when a user account is created, changed, or deleted; a user account is renamed, disabled, or enabled; or a password is set or changed. See Also: See HTH Policies and Standards Reference: NIST 800-53r5|AU-3 AU-3(1) AU-7 AU-12 Policy Value: 'Success and Failure' Actual Value: 'Success and Failure' | O16: N/A | R16: 15f6a868-a423-46f6-9471-bbe28660b015 | T16: 10.9.228.37 | U16: hth4qvk6c4.hilltop.global | W16: Microsoft Windows 11 Enterprise Build 22631 | X16: AC:45:EF:8D:16:70 D4:A2:CD:F6:35:20 | Y16: Policy Compliance | Z16: 0 | AA16: 0 | AD16: 0 | AE16: 0 | AH16: general-purpose | AI16: 2026-04-19T01:21:54.036Z | AJ16: 2026-04-19T01:31:31.017Z | AK16: null | AN16: template-9cfb28cd-a1ba-2b6f-ef9e-f7691bc0a80b14766c032550e147 | AO16: c67919cb-fdfd-4f24-a332-e05d4b135763 | AP16: 2026-04-19T01:33:04.922Z | AQ16: 2026-04-19T01:30:12Z | AS16: TRUE | AT16: None | AU16: 0 | AV16: 0 | AX16: 39 | AY16: local | AZ16: $Revision: 1.793 $ | BB16: 2026-04-15T00:00:00Z | BC16: 2007-11-21T00:00:00Z | BD16: FALSE | BE16: FALSE | BF16: FALSE | BG16: FALSE | BH16: FALSE | BI16: FALSE | BJ16: FALSE | BK16: FALSE | BL16: FALSE | BM16: FALSE | BN16: FALSE | BO16: FALSE | BP16: FALSE | BR16: =IFERROR(IF(M16="PASSED",VLOOKUP(J16,Current!$J$1:$N$500,1,FALSE)),N16) -> "1.0015 - MSWRK - Ensure Audit User Account Management is set to Success and Failure: [PASSED]" This subcategory reports each event of user account management, such as when a user account is created, changed, or deleted; a user account is renamed, disabled, or enabled; or a password is set or changed. See Also: See HTH Policies and Standards Reference: NIST 800-53r5|AU-3 AU-3(1) AU-7 AU-12 Policy Value: 'Success and Failure' Actual Value: 'Success and Failure'
